Workbook

Sheet 1
B3: MOVIMIENTO DE AERONAVES
B4: ESTADISTICA DIARIA
C6: DEPENDENCIA: | D6: TORRE MORON | H6: FECHA: | I6: 46235
B8: FRANJA HORARIA UTC | C8: COMERCIAL | D8: OFICIAL | E8: OTROS | F8: LOCAL | G8: SOBREVUELO | H8: TOTAL MOVIMIENTOS | I8: IFR | J8: PISTA | R8: CONDICION METEOROLOGICA DEL AERODROMO (SADM)
J9: 2 | K9: 20 | R9: CONDICION | S9: VIS (m) | T9: TECHO (ft) | U9: SPECI | V9: METAR OBSERVADO
B10: 00 a 01 | H10: =SUM(C10:G10) | R10: =IFERROR(VLOOKUP(INT($I$6)*100+0,METEO_SADM!$A$1:$L$505,5,FALSE),"s/d") | S10: =IFERROR(VLOOKUP(INT($I$6)*100+0,METEO_SADM!$A$1:$L$505,6,FALSE),"s/d") | T10: =IFERROR(VLOOKUP(INT($I$6)*100+0,METEO_SADM!$A$1:$L$505,7,FALSE),"s/d") | U10: =IFERROR(VLOOKUP(INT($I$6)*100+0,METEO_SADM!$A$1:$L$505,8,FALSE),"s/d") | V10: =IFERROR(VLOOKUP(INT($I$6)*100+0,METEO_SADM!$A$1:$L$505,9,FALSE),"s/d")
B11: 01 a 02 | H11: =SUM(C11:G11) | R11: =IFERROR(VLOOKUP(INT($I$6)*100+1,METEO_SADM!$A$1:$L$505,5,FALSE),"s/d") | S11: =IFERROR(VLOOKUP(INT($I$6)*100+1,METEO_SADM!$A$1:$L$505,6,FALSE),"s/d") | T11: =IFERROR(VLOOKUP(INT($I$6)*100+1,METEO_SADM!$A$1:$L$505,7,FALSE),"s/d") | U11: =IFERROR(VLOOKUP(INT($I$6)*100+1,METEO_SADM!$A$1:$L$505,8,FALSE),"s/d") | V11: =IFERROR(VLOOKUP(INT($I$6)*100+1,METEO_SADM!$A$1:$L$505,9,FALSE),"s/d")
B12: 02 a 03 | H12: =SUM(C12:G12) | R12: =IFERROR(VLOOKUP(INT($I$6)*100+2,METEO_SADM!$A$1:$L$505,5,FALSE),"s/d") | S12: =IFERROR(VLOOKUP(INT($I$6)*100+2,METEO_SADM!$A$1:$L$505,6,FALSE),"s/d") | T12: =IFERROR(VLOOKUP(INT($I$6)*100+2,METEO_SADM!$A$1:$L$505,7,FALSE),"s/d") | U12: =IFERROR(VLOOKUP(INT($I$6)*100+2,METEO_SADM!$A$1:$L$505,8,FALSE),"s/d") | V12: =IFERROR(VLOOKUP(INT($I$6)*100+2,METEO_SADM!$A$1:$L$505,9,FALSE),"s/d")
B13: 03 a 04 | H13: =SUM(C13:G13) | R13: =IFERROR(VLOOKUP(INT($I$6)*100+3,METEO_SADM!$A$1:$L$505,5,FALSE),"s/d") | S13: =IFERROR(VLOOKUP(INT($I$6)*100+3,METEO_SADM!$A$1:$L$505,6,FALSE),"s/d") | T13: =IFERROR(VLOOKUP(INT($I$6)*100+3,METEO_SADM!$A$1:$L$505,7,FALSE),"s/d") | U13: =IFERROR(VLOOKUP(INT($I$6)*100+3,METEO_SADM!$A$1:$L$505,8,FALSE),"s/d") | V13: =IFERROR(VLOOKUP(INT($I$6)*100+3,METEO_SADM!$A$1:$L$505,9,FALSE),"s/d")
B14: 04 a 05 | H14: =SUM(C14:G14) | R14: =IFERROR(VLOOKUP(INT($I$6)*100+4,METEO_SADM!$A$1:$L$505,5,FALSE),"s/d") | S14: =IFERROR(VLOOKUP(INT($I$6)*100+4,METEO_SADM!$A$1:$L$505,6,FALSE),"s/d") | T14: =IFERROR(VLOOKUP(INT($I$6)*100+4,METEO_SADM!$A$1:$L$505,7,FALSE),"s/d") | U14: =IFERROR(VLOOKUP(INT($I$6)*100+4,METEO_SADM!$A$1:$L$505,8,FALSE),"s/d") | V14: =IFERROR(VLOOKUP(INT($I$6)*100+4,METEO_SADM!$A$1:$L$505,9,FALSE),"s/d")
B15: 05 a 06 | H15: =SUM(C15:G15) | R15: =IFERROR(VLOOKUP(INT($I$6)*100+5,METEO_SADM!$A$1:$L$505,5,FALSE),"s/d") | S15: =IFERROR(VLOOKUP(INT($I$6)*100+5,METEO_SADM!$A$1:$L$505,6,FALSE),"s/d") | T15: =IFERROR(VLOOKUP(INT($I$6)*100+5,METEO_SADM!$A$1:$L$505,7,FALSE),"s/d") | U15: =IFERROR(VLOOKUP(INT($I$6)*100+5,METEO_SADM!$A$1:$L$505,8,FALSE),"s/d") | V15: =IFERROR(VLOOKUP(INT($I$6)*100+5,METEO_SADM!$A$1:$L$505,9,FALSE),"s/d")
B16: 06 a 07 | H16: =SUM(C16:G16) | R16: =IFERROR(VLOOKUP(INT($I$6)*100+6,METEO_SADM!$A$1:$L$505,5,FALSE),"s/d") | S16: =IFERROR(VLOOKUP(INT($I$6)*100+6,METEO_SADM!$A$1:$L$505,6,FALSE),"s/d") | T16: =IFERROR(VLOOKUP(INT($I$6)*100+6,METEO_SADM!$A$1:$L$505,7,FALSE),"s/d") | U16: =IFERROR(VLOOKUP(INT($I$6)*100+6,METEO_SADM!$A$1:$L$505,8,FALSE),"s/d") | V16: =IFERROR(VLOOKUP(INT($I$6)*100+6,METEO_SADM!$A$1:$L$505,9,FALSE),"s/d")
B17: 07 a 08 | H17: =SUM(C17:G17) | R17: =IFERROR(VLOOKUP(INT($I$6)*100+7,METEO_SADM!$A$1:$L$505,5,FALSE),"s/d") | S17: =IFERROR(VLOOKUP(INT($I$6)*100+7,METEO_SADM!$A$1:$L$505,6,FALSE),"s/d") | T17: =IFERROR(VLOOKUP(INT($I$6)*100+7,METEO_SADM!$A$1:$L$505,7,FALSE),"s/d") | U17: =IFERROR(VLOOKUP(INT($I$6)*100+7,METEO_SADM!$A$1:$L$505,8,FALSE),"s/d") | V17: =IFERROR(VLOOKUP(INT($I$6)*100+7,METEO_SADM!$A$1:$L$505,9,FALSE),"s/d")
B18: 08 a 09 | H18: =SUM(C18:G18) | R18: =IFERROR(VLOOKUP(INT($I$6)*100+8,METEO_SADM!$A$1:$L$505,5,FALSE),"s/d") | S18: =IFERROR(VLOOKUP(INT($I$6)*100+8,METEO_SADM!$A$1:$L$505,6,FALSE),"s/d") | T18: =IFERROR(VLOOKUP(INT($I$6)*100+8,METEO_SADM!$A$1:$L$505,7,FALSE),"s/d") | U18: =IFERROR(VLOOKUP(INT($I$6)*100+8,METEO_SADM!$A$1:$L$505,8,FALSE),"s/d") | V18: =IFERROR(VLOOKUP(INT($I$6)*100+8,METEO_SADM!$A$1:$L$505,9,FALSE),"s/d")
B19: 09 a 10 | H19: =SUM(C19:G19) | R19: =IFERROR(VLOOKUP(INT($I$6)*100+9,METEO_SADM!$A$1:$L$505,5,FALSE),"s/d") | S19: =IFERROR(VLOOKUP(INT($I$6)*100+9,METEO_SADM!$A$1:$L$505,6,FALSE),"s/d") | T19: =IFERROR(VLOOKUP(INT($I$6)*100+9,METEO_SADM!$A$1:$L$505,7,FALSE),"s/d") | U19: =IFERROR(VLOOKUP(INT($I$6)*100+9,METEO_SADM!$A$1:$L$505,8,FALSE),"s/d") | V19: =IFERROR(VLOOKUP(INT($I$6)*100+9,METEO_SADM!$A$1:$L$505,9,FALSE),"s/d")
B20: 10 a 11 | H20: =SUM(C20:G20) | R20: =IFERROR(VLOOKUP(INT($I$6)*100+10,METEO_SADM!$A$1:$L$505,5,FALSE),"s/d") | S20: =IFERROR(VLOOKUP(INT($I$6)*100+10,METEO_SADM!$A$1:$L$505,6,FALSE),"s/d") | T20: =IFERROR(VLOOKUP(INT($I$6)*100+10,METEO_SADM!$A$1:$L$505,7,FALSE),"s/d") | U20: =IFERROR(VLOOKUP(INT($I$6)*100+10,METEO_SADM!$A$1:$L$505,8,FALSE),"s/d") | V20: =IFERROR(VLOOKUP(INT($I$6)*100+10,METEO_SADM!$A$1:$L$505,9,FALSE),"s/d")
B21: 11 a 12 | E21: 2 | H21: =SUM(C21:G21) | I21: 1 | K21: 1 | R21: =IFERROR(VLOOKUP(INT($I$6)*100+11,METEO_SADM!$A$1:$L$505,5,FALSE),"s/d") | S21: =IFERROR(VLOOKUP(INT($I$6)*100+11,METEO_SADM!$A$1:$L$505,6,FALSE),"s/d") | T21: =IFERROR(VLOOKUP(INT($I$6)*100+11,METEO_SADM!$A$1:$L$505,7,FALSE),"s/d") | U21: =IFERROR(VLOOKUP(INT($I$6)*100+11,METEO_SADM!$A$1:$L$505,8,FALSE),"s/d") | V21: =IFERROR(VLOOKUP(INT($I$6)*100+11,METEO_SADM!$A$1:$L$505,9,FALSE),"s/d")
B22: 12 a 13 | E22: 7 | H22: =SUM(C22:G22) | I22: 1 | K22: 1 | R22: =IFERROR(VLOOKUP(INT($I$6)*100+12,METEO_SADM!$A$1:$L$505,5,FALSE),"s/d") | S22: =IFERROR(VLOOKUP(INT($I$6)*100+12,METEO_SADM!$A$1:$L$505,6,FALSE),"s/d") | T22: =IFERROR(VLOOKUP(INT($I$6)*100+12,METEO_SADM!$A$1:$L$505,7,FALSE),"s/d") | U22: =IFERROR(VLOOKUP(INT($I$6)*100+12,METEO_SADM!$A$1:$L$505,8,FALSE),"s/d") | V22: =IFERROR(VLOOKUP(INT($I$6)*100+12,METEO_SADM!$A$1:$L$505,9,FALSE),"s/d")
B23: 13 a 14 | E23: 15 | F23: 14 | H23: =SUM(C23:G23) | K23: 1 | R23: =IFERROR(VLOOKUP(INT($I$6)*100+13,METEO_SADM!$A$1:$L$505,5,FALSE),"s/d") | S23: =IFERROR(VLOOKUP(INT($I$6)*100+13,METEO_SADM!$A$1:$L$505,6,FALSE),"s/d") | T23: =IFERROR(VLOOKUP(INT($I$6)*100+13,METEO_SADM!$A$1:$L$505,7,FALSE),"s/d") | U23: =IFERROR(VLOOKUP(INT($I$6)*100+13,METEO_SADM!$A$1:$L$505,8,FALSE),"s/d") | V23: =IFERROR(VLOOKUP(INT($I$6)*100+13,METEO_SADM!$A$1:$L$505,9,FALSE),"s/d")
B24: 14 a 15 | E24: 2 | G24: 1 | H24: =SUM(C24:G24) | K24: 1 | R24: =IFERROR(VLOOKUP(INT($I$6)*100+14,METEO_SADM!$A$1:$L$505,5,FALSE),"s/d") | S24: =IFERROR(VLOOKUP(INT($I$6)*100+14,METEO_SADM!$A$1:$L$505,6,FALSE),"s/d") | T24: =IFERROR(VLOOKUP(INT($I$6)*100+14,METEO_SADM!$A$1:$L$505,7,FALSE),"s/d") | U24: =IFERROR(VLOOKUP(INT($I$6)*100+14,METEO_SADM!$A$1:$L$505,8,FALSE),"s/d") | V24: =IFERROR(VLOOKUP(INT($I$6)*100+14,METEO_SADM!$A$1:$L$505,9,FALSE),"s/d")
B25: 15 a 16 | E25: 20 | F25: 8 | H25: =SUM(C25:G25) | K25: 1 | R25: =IFERROR(VLOOKUP(INT($I$6)*100+15,METEO_SADM!$A$1:$L$505,5,FALSE),"s/d") | S25: =IFERROR(VLOOKUP(INT($I$6)*100+15,METEO_SADM!$A$1:$L$505,6,FALSE),"s/d") | T25: =IFERROR(VLOOKUP(INT($I$6)*100+15,METEO_SADM!$A$1:$L$505,7,FALSE),"s/d") | U25: =IFERROR(VLOOKUP(INT($I$6)*100+15,METEO_SADM!$A$1:$L$505,8,FALSE),"s/d") | V25: =IFERROR(VLOOKUP(INT($I$6)*100+15,METEO_SADM!$A$1:$L$505,9,FALSE),"s/d")
B26: 16 a 17 | E26: 19 | F26: 16 | H26: =SUM(C26:G26) | K26: 1 | R26: =IFERROR(VLOOKUP(INT($I$6)*100+16,METEO_SADM!$A$1:$L$505,5,FALSE),"s/d") | S26: =IFERROR(VLOOKUP(INT($I$6)*100+16,METEO_SADM!$A$1:$L$505,6,FALSE),"s/d") | T26: =IFERROR(VLOOKUP(INT($I$6)*100+16,METEO_SADM!$A$1:$L$505,7,FALSE),"s/d") | U26: =IFERROR(VLOOKUP(INT($I$6)*100+16,METEO_SADM!$A$1:$L$505,8,FALSE),"s/d") | V26: =IFERROR(VLOOKUP(INT($I$6)*100+16,METEO_SADM!$A$1:$L$505,9,FALSE),"s/d")
B27: 17 a 18 | E27: 26 | F27: 12 | H27: =SUM(C27:G27) | K27: 1 | R27: =IFERROR(VLOOKUP(INT($I$6)*100+17,METEO_SADM!$A$1:$L$505,5,FALSE),"s/d") | S27: =IFERROR(VLOOKUP(INT($I$6)*100+17,METEO_SADM!$A$1:$L$505,6,FALSE),"s/d") | T27: =IFERROR(VLOOKUP(INT($I$6)*100+17,METEO_SADM!$A$1:$L$505,7,FALSE),"s/d") | U27: =IFERROR(VLOOKUP(INT($I$6)*100+17,METEO_SADM!$A$1:$L$505,8,FALSE),"s/d") | V27: =IFERROR(VLOOKUP(INT($I$6)*100+17,METEO_SADM!$A$1:$L$505,9,FALSE),"s/d")
B28: 18 a 19 | E28: 27 | F28: 8 | H28: =SUM(C28:G28) | K28: 1 | R28: =IFERROR(VLOOKUP(INT($I$6)*100+18,METEO_SADM!$A$1:$L$505,5,FALSE),"s/d") | S28: =IFERROR(VLOOKUP(INT($I$6)*100+18,METEO_SADM!$A$1:$L$505,6,FALSE),"s/d") | T28: =IFERROR(VLOOKUP(INT($I$6)*100+18,METEO_SADM!$A$1:$L$505,7,FALSE),"s/d") | U28: =IFERROR(VLOOKUP(INT($I$6)*100+18,METEO_SADM!$A$1:$L$505,8,FALSE),"s/d") | V28: =IFERROR(VLOOKUP(INT($I$6)*100+18,METEO_SADM!$A$1:$L$505,9,FALSE),"s/d")
B29: 19 a 20 | E29: 25 | H29: =SUM(C29:G29) | K29: 1 | R29: =IFERROR(VLOOKUP(INT($I$6)*100+19,METEO_SADM!$A$1:$L$505,5,FALSE),"s/d") | S29: =IFERROR(VLOOKUP(INT($I$6)*100+19,METEO_SADM!$A$1:$L$505,6,FALSE),"s/d") | T29: =IFERROR(VLOOKUP(INT($I$6)*100+19,METEO_SADM!$A$1:$L$505,7,FALSE),"s/d") | U29: =IFERROR(VLOOKUP(INT($I$6)*100+19,METEO_SADM!$A$1:$L$505,8,FALSE),"s/d") | V29: =IFERROR(VLOOKUP(INT($I$6)*100+19,METEO_SADM!$A$1:$L$505,9,FALSE),"s/d")
B30: 20 a 21 | E30: 24 | F30: 10 | H30: =SUM(C30:G30) | K30: 1 | R30: =IFERROR(VLOOKUP(INT($I$6)*100+20,METEO_SADM!$A$1:$L$505,5,FALSE),"s/d") | S30: =IFERROR(VLOOKUP(INT($I$6)*100+20,METEO_SADM!$A$1:$L$505,6,FALSE),"s/d") | T30: =IFERROR(VLOOKUP(INT($I$6)*100+20,METEO_SADM!$A$1:$L$505,7,FALSE),"s/d") | U30: =IFERROR(VLOOKUP(INT($I$6)*100+20,METEO_SADM!$A$1:$L$505,8,FALSE),"s/d") | V30: =IFERROR(VLOOKUP(INT($I$6)*100+20,METEO_SADM!$A$1:$L$505,9,FALSE),"s/d")
B31: 21 a 22 | E31: 5 | F31: 6 | H31: =SUM(C31:G31) | K31: 1 | R31: =IFERROR(VLOOKUP(INT($I$6)*100+21,METEO_SADM!$A$1:$L$505,5,FALSE),"s/d") | S31: =IFERROR(VLOOKUP(INT($I$6)*100+21,METEO_SADM!$A$1:$L$505,6,FALSE),"s/d") | T31: =IFERROR(VLOOKUP(INT($I$6)*100+21,METEO_SADM!$A$1:$L$505,7,FALSE),"s/d") | U31: =IFERROR(VLOOKUP(INT($I$6)*100+21,METEO_SADM!$A$1:$L$505,8,FALSE),"s/d") | V31: =IFERROR(VLOOKUP(INT($I$6)*100+21,METEO_SADM!$A$1:$L$505,9,FALSE),"s/d")
B32: 22 a 23 | H32: =SUM(C32:G32) | R32: =IFERROR(VLOOKUP(INT($I$6)*100+22,METEO_SADM!$A$1:$L$505,5,FALSE),"s/d") | S32: =IFERROR(VLOOKUP(INT($I$6)*100+22,METEO_SADM!$A$1:$L$505,6,FALSE),"s/d") | T32: =IFERROR(VLOOKUP(INT($I$6)*100+22,METEO_SADM!$A$1:$L$505,7,FALSE),"s/d") | U32: =IFERROR(VLOOKUP(INT($I$6)*100+22,METEO_SADM!$A$1:$L$505,8,FALSE),"s/d") | V32: =IFERROR(VLOOKUP(INT($I$6)*100+22,METEO_SADM!$A$1:$L$505,9,FALSE),"s/d")
B33: 23 a 00 | H33: =SUM(C33:G33) | P33: pista | R33: =IFERROR(VLOOKUP(INT($I$6)*100+23,METEO_SADM!$A$1:$L$505,5,FALSE),"s/d") | S33: =IFERROR(VLOOKUP(INT($I$6)*100+23,METEO_SADM!$A$1:$L$505,6,FALSE),"s/d") | T33: =IFERROR(VLOOKUP(INT($I$6)*100+23,METEO_SADM!$A$1:$L$505,7,FALSE),"s/d") | U33: =IFERROR(VLOOKUP(INT($I$6)*100+23,METEO_SADM!$A$1:$L$505,8,FALSE),"s/d") | V33: =IFERROR(VLOOKUP(INT($I$6)*100+23,METEO_SADM!$A$1:$L$505,9,FALSE),"s/d")
B34: TOTAL DIARIO | C34: COMERCIAL | D34: OFICIAL | E34: OTROS | F34: LOCAL | G34: SOBREVUELO | H34: TOTAL MOVIMIENTOS | I34: IFR | J34: PISTA | P34: suma total
J35: =J9 | K35: =K9 | L35: =L9 | M35: =M9 | P35: =SUM(J36:M36)
C36: =SUM(C10:C33) | D36: =SUM(D10:D33) | E36: =SUM(E10:E33) | F36: =SUM(F10:F33) | G36: =SUM(G10:G33) | H36: =SUM(H10:H33) | I36: =SUM(I10:I33) | J36: =SUM(J10:J33) | ... M36: =SUM(M10:M33)
C37: =((C36*100)/$H$36)/100 | D37: =((D36*100)/$H$36)/100 | E37: =((E36*100)/$H$36)/100 | F37: =((F36*100)/$H$36)/100 | G37: =((G36*100)/$H$36)/100 | H37: =((H36*100)/$H$36)/100 | I37: =((I36*100)/$H$36)/100 | J37: =((J36*100)/$P$35)/100 | K37: =((K36*100)/$P$35)/100 | L37: =((L36*100)/$P$35)/100 | M37: =((M36*100)/$P$35)/100
F44: Firma y aclaración del responsable

Sheet 2
B3: MOVIMIENTO DE AERONAVES
B4: ESTADISTICA DIARIA
C6: DEPENDENCIA: | D6: TORRE MORON | H6: FECHA: | I6: 46236
B8: FRANJA HORARIA UTC | C8: COMERCIAL | D8: OFICIAL | E8: OTROS | F8: LOCAL | G8: SOBREVUELO | H8: TOTAL MOVIMIENTOS | I8: IFR | J8: PISTA | R8: CONDICION METEOROLOGICA DEL AERODROMO (SADM)
J9: 2 | K9: 20 | R9: CONDICION | S9: VIS (m) | T9: TECHO (ft) | U9: SPECI | V9: METAR OBSERVADO
B10: 00 a 01 | H10: =SUM(C10:G10) | R10: =IFERROR(VLOOKUP(INT($I$6)*100+0,METEO_SADM!$A$1:$L$505,5,FALSE),"s/d") | S10: =IFERROR(VLOOKUP(INT($I$6)*100+0,METEO_SADM!$A$1:$L$505,6,FALSE),"s/d") | T10: =IFERROR(VLOOKUP(INT($I$6)*100+0,METEO_SADM!$A$1:$L$505,7,FALSE),"s/d") | U10: =IFERROR(VLOOKUP(INT($I$6)*100+0,METEO_SADM!$A$1:$L$505,8,FALSE),"s/d") | V10: =IFERROR(VLOOKUP(INT($I$6)*100+0,METEO_SADM!$A$1:$L$505,9,FALSE),"s/d")
B11: 01 a 02 | H11: =SUM(C11:G11) | R11: =IFERROR(VLOOKUP(INT($I$6)*100+1,METEO_SADM!$A$1:$L$505,5,FALSE),"s/d") | S11: =IFERROR(VLOOKUP(INT($I$6)*100+1,METEO_SADM!$A$1:$L$505,6,FALSE),"s/d") | T11: =IFERROR(VLOOKUP(INT($I$6)*100+1,METEO_SADM!$A$1:$L$505,7,FALSE),"s/d") | U11: =IFERROR(VLOOKUP(INT($I$6)*100+1,METEO_SADM!$A$1:$L$505,8,FALSE),"s/d") | V11: =IFERROR(VLOOKUP(INT($I$6)*100+1,METEO_SADM!$A$1:$L$505,9,FALSE),"s/d")
B12: 02 a 03 | H12: =SUM(C12:G12) | R12: =IFERROR(VLOOKUP(INT($I$6)*100+2,METEO_SADM!$A$1:$L$505,5,FALSE),"s/d") | S12: =IFERROR(VLOOKUP(INT($I$6)*100+2,METEO_SADM!$A$1:$L$505,6,FALSE),"s/d") | T12: =IFERROR(VLOOKUP(INT($I$6)*100+2,METEO_SADM!$A$1:$L$505,7,FALSE),"s/d") | U12: =IFERROR(VLOOKUP(INT($I$6)*100+2,METEO_SADM!$A$1:$L$505,8,FALSE),"s/d") | V12: =IFERROR(VLOOKUP(INT($I$6)*100+2,METEO_SADM!$A$1:$L$505,9,FALSE),"s/d")
B13: 03 a 04 | H13: =SUM(C13:G13) | R13: =IFERROR(VLOOKUP(INT($I$6)*100+3,METEO_SADM!$A$1:$L$505,5,FALSE),"s/d") | S13: =IFERROR(VLOOKUP(INT($I$6)*100+3,METEO_SADM!$A$1:$L$505,6,FALSE),"s/d") | T13: =IFERROR(VLOOKUP(INT($I$6)*100+3,METEO_SADM!$A$1:$L$505,7,FALSE),"s/d") | U13: =IFERROR(VLOOKUP(INT($I$6)*100+3,METEO_SADM!$A$1:$L$505,8,FALSE),"s/d") | V13: =IFERROR(VLOOKUP(INT($I$6)*100+3,METEO_SADM!$A$1:$L$505,9,FALSE),"s/d")
B14: 04 a 05 | H14: =SUM(C14:G14) | R14: =IFERROR(VLOOKUP(INT($I$6)*100+4,METEO_SADM!$A$1:$L$505,5,FALSE),"s/d") | S14: =IFERROR(VLOOKUP(INT($I$6)*100+4,METEO_SADM!$A$1:$L$505,6,FALSE),"s/d") | T14: =IFERROR(VLOOKUP(INT($I$6)*100+4,METEO_SADM!$A$1:$L$505,7,FALSE),"s/d") | U14: =IFERROR(VLOOKUP(INT($I$6)*100+4,METEO_SADM!$A$1:$L$505,8,FALSE),"s/d") | V14: =IFERROR(VLOOKUP(INT($I$6)*100+4,METEO_SADM!$A$1:$L$505,9,FALSE),"s/d")
B15: 05 a 06 | H15: =SUM(C15:G15) | R15: =IFERROR(VLOOKUP(INT($I$6)*100+5,METEO_SADM!$A$1:$L$505,5,FALSE),"s/d") | S15: =IFERROR(VLOOKUP(INT($I$6)*100+5,METEO_SADM!$A$1:$L$505,6,FALSE),"s/d") | T15: =IFERROR(VLOOKUP(INT($I$6)*100+5,METEO_SADM!$A$1:$L$505,7,FALSE),"s/d") | U15: =IFERROR(VLOOKUP(INT($I$6)*100+5,METEO_SADM!$A$1:$L$505,8,FALSE),"s/d") | V15: =IFERROR(VLOOKUP(INT($I$6)*100+5,METEO_SADM!$A$1:$L$505,9,FALSE),"s/d")
B16: 06 a 07 | H16: =SUM(C16:G16) | R16: =IFERROR(VLOOKUP(INT($I$6)*100+6,METEO_SADM!$A$1:$L$505,5,FALSE),"s/d") | S16: =IFERROR(VLOOKUP(INT($I$6)*100+6,METEO_SADM!$A$1:$L$505,6,FALSE),"s/d") | T16: =IFERROR(VLOOKUP(INT($I$6)*100+6,METEO_SADM!$A$1:$L$505,7,FALSE),"s/d") | U16: =IFERROR(VLOOKUP(INT($I$6)*100+6,METEO_SADM!$A$1:$L$505,8,FALSE),"s/d") | V16: =IFERROR(VLOOKUP(INT($I$6)*100+6,METEO_SADM!$A$1:$L$505,9,FALSE),"s/d")
B17: 07 a 08 | H17: =SUM(C17:G17) | R17: =IFERROR(VLOOKUP(INT($I$6)*100+7,METEO_SADM!$A$1:$L$505,5,FALSE),"s/d") | S17: =IFERROR(VLOOKUP(INT($I$6)*100+7,METEO_SADM!$A$1:$L$505,6,FALSE),"s/d") | T17: =IFERROR(VLOOKUP(INT($I$6)*100+7,METEO_SADM!$A$1:$L$505,7,FALSE),"s/d") | U17: =IFERROR(VLOOKUP(INT($I$6)*100+7,METEO_SADM!$A$1:$L$505,8,FALSE),"s/d") | V17: =IFERROR(VLOOKUP(INT($I$6)*100+7,METEO_SADM!$A$1:$L$505,9,FALSE),"s/d")
B18: 08 a 09 | H18: =SUM(C18:G18) | R18: =IFERROR(VLOOKUP(INT($I$6)*100+8,METEO_SADM!$A$1:$L$505,5,FALSE),"s/d") | S18: =IFERROR(VLOOKUP(INT($I$6)*100+8,METEO_SADM!$A$1:$L$505,6,FALSE),"s/d") | T18: =IFERROR(VLOOKUP(INT($I$6)*100+8,METEO_SADM!$A$1:$L$505,7,FALSE),"s/d") | U18: =IFERROR(VLOOKUP(INT($I$6)*100+8,METEO_SADM!$A$1:$L$505,8,FALSE),"s/d") | V18: =IFERROR(VLOOKUP(INT($I$6)*100+8,METEO_SADM!$A$1:$L$505,9,FALSE),"s/d")
B19: 09 a 10 | H19: =SUM(C19:G19) | R19: =IFERROR(VLOOKUP(INT($I$6)*100+9,METEO_SADM!$A$1:$L$505,5,FALSE),"s/d") | S19: =IFERROR(VLOOKUP(INT($I$6)*100+9,METEO_SADM!$A$1:$L$505,6,FALSE),"s/d") | T19: =IFERROR(VLOOKUP(INT($I$6)*100+9,METEO_SADM!$A$1:$L$505,7,FALSE),"s/d") | U19: =IFERROR(VLOOKUP(INT($I$6)*100+9,METEO_SADM!$A$1:$L$505,8,FALSE),"s/d") | V19: =IFERROR(VLOOKUP(INT($I$6)*100+9,METEO_SADM!$A$1:$L$505,9,FALSE),"s/d")
B20: 10 a 11 | H20: =SUM(C20:G20) | R20: =IFERROR(VLOOKUP(INT($I$6)*100+10,METEO_SADM!$A$1:$L$505,5,FALSE),"s/d") | S20: =IFERROR(VLOOKUP(INT($I$6)*100+10,METEO_SADM!$A$1:$L$505,6,FALSE),"s/d") | T20: =IFERROR(VLOOKUP(INT($I$6)*100+10,METEO_SADM!$A$1:$L$505,7,FALSE),"s/d") | U20: =IFERROR(VLOOKUP(INT($I$6)*100+10,METEO_SADM!$A$1:$L$505,8,FALSE),"s/d") | V20: =IFERROR(VLOOKUP(INT($I$6)*100+10,METEO_SADM!$A$1:$L$505,9,FALSE),"s/d")
B21: 11 a 12 | E21: imc | F21: imc | G21: imc | H21: =SUM(C21:G21) | R21: =IFERROR(VLOOKUP(INT($I$6)*100+11,METEO_SADM!$A$1:$L$505,5,FALSE),"s/d") | S21: =IFERROR(VLOOKUP(INT($I$6)*100+11,METEO_SADM!$A$1:$L$505,6,FALSE),"s/d") | T21: =IFERROR(VLOOKUP(INT($I$6)*100+11,METEO_SADM!$A$1:$L$505,7,FALSE),"s/d") | U21: =IFERROR(VLOOKUP(INT($I$6)*100+11,METEO_SADM!$A$1:$L$505,8,FALSE),"s/d") | V21: =IFERROR(VLOOKUP(INT($I$6)*100+11,METEO_SADM!$A$1:$L$505,9,FALSE),"s/d")
B22: 12 a 13 | E22: imc | F22: imc | G22: imc | H22: =SUM(C22:G22) | R22: =IFERROR(VLOOKUP(INT($I$6)*100+12,METEO_SADM!$A$1:$L$505,5,FALSE),"s/d") | S22: =IFERROR(VLOOKUP(INT($I$6)*100+12,METEO_SADM!$A$1:$L$505,6,FALSE),"s/d") | T22: =IFERROR(VLOOKUP(INT($I$6)*100+12,METEO_SADM!$A$1:$L$505,7,FALSE),"s/d") | U22: =IFERROR(VLOOKUP(INT($I$6)*100+12,METEO_SADM!$A$1:$L$505,8,FALSE),"s/d") | V22: =IFERROR(VLOOKUP(INT($I$6)*100+12,METEO_SADM!$A$1:$L$505,9,FALSE),"s/d")
B23: 13 a 14 | E23: imc | F23: imc | G23: imc | H23: =SUM(C23:G23) | R23: =IFERROR(VLOOKUP(INT($I$6)*100+13,METEO_SADM!$A$1:$L$505,5,FALSE),"s/d") | S23: =IFERROR(VLOOKUP(INT($I$6)*100+13,METEO_SADM!$A$1:$L$505,6,FALSE),"s/d") | T23: =IFERROR(VLOOKUP(INT($I$6)*100+13,METEO_SADM!$A$1:$L$505,7,FALSE),"s/d") | U23: =IFERROR(VLOOKUP(INT($I$6)*100+13,METEO_SADM!$A$1:$L$505,8,FALSE),"s/d") | V23: =IFERROR(VLOOKUP(INT($I$6)*100+13,METEO_SADM!$A$1:$L$505,9,FALSE),"s/d")
B24: 14 a 15 | E24: imc | F24: imc | G24: imc | H24: =SUM(C24:G24) | R24: =IFERROR(VLOOKUP(INT($I$6)*100+14,METEO_SADM!$A$1:$L$505,5,FALSE),"s/d") | S24: =IFERROR(VLOOKUP(INT($I$6)*100+14,METEO_SADM!$A$1:$L$505,6,FALSE),"s/d") | T24: =IFERROR(VLOOKUP(INT($I$6)*100+14,METEO_SADM!$A$1:$L$505,7,FALSE),"s/d") | U24: =IFERROR(VLOOKUP(INT($I$6)*100+14,METEO_SADM!$A$1:$L$505,8,FALSE),"s/d") | V24: =IFERROR(VLOOKUP(INT($I$6)*100+14,METEO_SADM!$A$1:$L$505,9,FALSE),"s/d")
B25: 15 a 16 | E25: imc | F25: imc | G25: imc | H25: =SUM(C25:G25) | R25: =IFERROR(VLOOKUP(INT($I$6)*100+15,METEO_SADM!$A$1:$L$505,5,FALSE),"s/d") | S25: =IFERROR(VLOOKUP(INT($I$6)*100+15,METEO_SADM!$A$1:$L$505,6,FALSE),"s/d") | T25: =IFERROR(VLOOKUP(INT($I$6)*100+15,METEO_SADM!$A$1:$L$505,7,FALSE),"s/d") | U25: =IFERROR(VLOOKUP(INT($I$6)*100+15,METEO_SADM!$A$1:$L$505,8,FALSE),"s/d") | V25: =IFERROR(VLOOKUP(INT($I$6)*100+15,METEO_SADM!$A$1:$L$505,9,FALSE),"s/d")
B26: 16 a 17 | E26: 14 | F26: 16 | H26: =SUM(C26:G26) | J26: 1 | R26: =IFERROR(VLOOKUP(INT($I$6)*100+16,METEO_SADM!$A$1:$L$505,5,FALSE),"s/d") | S26: =IFERROR(VLOOKUP(INT($I$6)*100+16,METEO_SADM!$A$1:$L$505,6,FALSE),"s/d") | T26: =IFERROR(VLOOKUP(INT($I$6)*100+16,METEO_SADM!$A$1:$L$505,7,FALSE),"s/d") | U26: =IFERROR(VLOOKUP(INT($I$6)*100+16,METEO_SADM!$A$1:$L$505,8,FALSE),"s/d") | V26: =IFERROR(VLOOKUP(INT($I$6)*100+16,METEO_SADM!$A$1:$L$505,9,FALSE),"s/d")
B27: 17 a 18 | E27: imc | F27: imc | G27: imc | H27: =SUM(C27:G27) | R27: =IFERROR(VLOOKUP(INT($I$6)*100+17,METEO_SADM!$A$1:$L$505,5,FALSE),"s/d") | S27: =IFERROR(VLOOKUP(INT($I$6)*100+17,METEO_SADM!$A$1:$L$505,6,FALSE),"s/d") | T27: =IFERROR(VLOOKUP(INT($I$6)*100+17,METEO_SADM!$A$1:$L$505,7,FALSE),"s/d") | U27: =IFERROR(VLOOKUP(INT($I$6)*100+17,METEO_SADM!$A$1:$L$505,8,FALSE),"s/d") | V27: =IFERROR(VLOOKUP(INT($I$6)*100+17,METEO_SADM!$A$1:$L$505,9,FALSE),"s/d")
B28: 18 a 19 | E28: 9 | F28: 4 | H28: =SUM(C28:G28) | J28: 1 | R28: =IFERROR(VLOOKUP(INT($I$6)*100+18,METEO_SADM!$A$1:$L$505,5,FALSE),"s/d") | S28: =IFERROR(VLOOKUP(INT($I$6)*100+18,METEO_SADM!$A$1:$L$505,6,FALSE),"s/d") | T28: =IFERROR(VLOOKUP(INT($I$6)*100+18,METEO_SADM!$A$1:$L$505,7,FALSE),"s/d") | U28: =IFERROR(VLOOKUP(INT($I$6)*100+18,METEO_SADM!$A$1:$L$505,8,FALSE),"s/d") | V28: =IFERROR(VLOOKUP(INT($I$6)*100+18,METEO_SADM!$A$1:$L$505,9,FALSE),"s/d")
B29: 19 a 20 | E29: 14 | F29: 18 | H29: =SUM(C29:G29) | J29: 1 | R29: =IFERROR(VLOOKUP(INT($I$6)*100+19,METEO_SADM!$A$1:$L$505,5,FALSE),"s/d") | S29: =IFERROR(VLOOKUP(INT($I$6)*100+19,METEO_SADM!$A$1:$L$505,6,FALSE),"s/d") | T29: =IFERROR(VLOOKUP(INT($I$6)*100+19,METEO_SADM!$A$1:$L$505,7,FALSE),"s/d") | U29: =IFERROR(VLOOKUP(INT($I$6)*100+19,METEO_SADM!$A$1:$L$505,8,FALSE),"s/d") | V29: =IFERROR(VLOOKUP(INT($I$6)*100+19,METEO_SADM!$A$1:$L$505,9,FALSE),"s/d")
B30: 20 a 21 | E30: 9 | H30: =SUM(C30:G30) | J30: 1 | R30: =IFERROR(VLOOKUP(INT($I$6)*100+20,METEO_SADM!$A$1:$L$505,5,FALSE),"s/d") | S30: =IFERROR(VLOOKUP(INT($I$6)*100+20,METEO_SADM!$A$1:$L$505,6,FALSE),"s/d") | T30: =IFERROR(VLOOKUP(INT($I$6)*100+20,METEO_SADM!$A$1:$L$505,7,FALSE),"s/d") | U30: =IFERROR(VLOOKUP(INT($I$6)*100+20,METEO_SADM!$A$1:$L$505,8,FALSE),"s/d") | V30: =IFERROR(VLOOKUP(INT($I$6)*100+20,METEO_SADM!$A$1:$L$505,9,FALSE),"s/d")
B31: 21 a 22 | E31: 4 | H31: =SUM(C31:G31) | J31: 1 | R31: =IFERROR(VLOOKUP(INT($I$6)*100+21,METEO_SADM!$A$1:$L$505,5,FALSE),"s/d") | S31: =IFERROR(VLOOKUP(INT($I$6)*100+21,METEO_SADM!$A$1:$L$505,6,FALSE),"s/d") | T31: =IFERROR(VLOOKUP(INT($I$6)*100+21,METEO_SADM!$A$1:$L$505,7,FALSE),"s/d") | U31: =IFERROR(VLOOKUP(INT($I$6)*100+21,METEO_SADM!$A$1:$L$505,8,FALSE),"s/d") | V31: =IFERROR(VLOOKUP(INT($I$6)*100+21,METEO_SADM!$A$1:$L$505,9,FALSE),"s/d")
B32: 22 a 23 | H32: =SUM(C32:G32) | R32: =IFERROR(VLOOKUP(INT($I$6)*100+22,METEO_SADM!$A$1:$L$505,5,FALSE),"s/d") | S32: =IFERROR(VLOOKUP(INT($I$6)*100+22,METEO_SADM!$A$1:$L$505,6,FALSE),"s/d") | T32: =IFERROR(VLOOKUP(INT($I$6)*100+22,METEO_SADM!$A$1:$L$505,7,FALSE),"s/d") | U32: =IFERROR(VLOOKUP(INT($I$6)*100+22,METEO_SADM!$A$1:$L$505,8,FALSE),"s/d") | V32: =IFERROR(VLOOKUP(INT($I$6)*100+22,METEO_SADM!$A$1:$L$505,9,FALSE),"s/d")
B33: 23 a 00 | H33: =SUM(C33:G33) | P33: pista | R33: =IFERROR(VLOOKUP(INT($I$6)*100+23,METEO_SADM!$A$1:$L$505,5,FALSE),"s/d") | S33: =IFERROR(VLOOKUP(INT($I$6)*100+23,METEO_SADM!$A$1:$L$505,6,FALSE),"s/d") | T33: =IFERROR(VLOOKUP(INT($I$6)*100+23,METEO_SADM!$A$1:$L$505,7,FALSE),"s/d") | U33: =IFERROR(VLOOKUP(INT($I$6)*100+23,METEO_SADM!$A$1:$L$505,8,FALSE),"s/d") | V33: =IFERROR(VLOOKUP(INT($I$6)*100+23,METEO_SADM!$A$1:$L$505,9,FALSE),"s/d")
B34: TOTAL DIARIO | C34: COMERCIAL | D34: OFICIAL | E34: OTROS | F34: LOCAL | G34: SOBREVUELO | H34: TOTAL MOVIMIENTOS | I34: IFR | J34: PISTA | P34: suma total
J35: =J9 | K35: =K9 | L35: =L9 | M35: =M9 | P35: =SUM(J36:M36)
C36: =SUM(C10:C33) | D36: =SUM(D10:D33) | E36: =SUM(E10:E33) | F36: =SUM(F10:F33) | G36: =SUM(G10:G33) | H36: =SUM(H10:H33) | I36: =SUM(I10:I33) | J36: =SUM(J10:J33) | ... M36: =SUM(M10:M33)
C37: =((C36*100)/$H$36)/100 | D37: =((D36*100)/$H$36)/100 | E37: =((E36*100)/$H$36)/100 | F37: =((F36*100)/$H$36)/100 | G37: =((G36*100)/$H$36)/100 | H37: =((H36*100)/$H$36)/100 | I37: =((I36*100)/$H$36)/100 | J37: =((J36*100)/$P$35)/100 | K37: =((K36*100)/$P$35)/100 | L37: =((L36*100)/$P$35)/100 | M37: =((M36*100)/$P$35)/100
F44: Firma y aclaración del responsable

Sheet 3
B3: MOVIMIENTO DE AERONAVES
B4: ESTADISTICA DIARIA
C6: DEPENDENCIA: | D6: TORRE MORON | H6: FECHA: | I6: 46237
B8: FRANJA HORARIA UTC | C8: COMERCIAL | D8: OFICIAL | E8: OTROS | F8: LOCAL | G8: SOBREVUELO | H8: TOTAL MOVIMIENTOS | I8: IFR | J8: PISTA | R8: CONDICION METEOROLOGICA DEL AERODROMO (SADM)
J9: 2 | K9: 20 | R9: CONDICION | S9: VIS (m) | T9: TECHO (ft) | U9: SPECI | V9: METAR OBSERVADO
B10: 00 a 01 | H10: =SUM(C10:G10) | R10: =IFERROR(VLOOKUP(INT($I$6)*100+0,METEO_SADM!$A$1:$L$505,5,FALSE),"s/d") | S10: =IFERROR(VLOOKUP(INT($I$6)*100+0,METEO_SADM!$A$1:$L$505,6,FALSE),"s/d") | T10: =IFERROR(VLOOKUP(INT($I$6)*100+0,METEO_SADM!$A$1:$L$505,7,FALSE),"s/d") | U10: =IFERROR(VLOOKUP(INT($I$6)*100+0,METEO_SADM!$A$1:$L$505,8,FALSE),"s/d") | V10: =IFERROR(VLOOKUP(INT($I$6)*100+0,METEO_SADM!$A$1:$L$505,9,FALSE),"s/d")
B11: 01 a 02 | H11: =SUM(C11:G11) | R11: =IFERROR(VLOOKUP(INT($I$6)*100+1,METEO_SADM!$A$1:$L$505,5,FALSE),"s/d") | S11: =IFERROR(VLOOKUP(INT($I$6)*100+1,METEO_SADM!$A$1:$L$505,6,FALSE),"s/d") | T11: =IFERROR(VLOOKUP(INT($I$6)*100+1,METEO_SADM!$A$1:$L$505,7,FALSE),"s/d") | U11: =IFERROR(VLOOKUP(INT($I$6)*100+1,METEO_SADM!$A$1:$L$505,8,FALSE),"s/d") | V11: =IFERROR(VLOOKUP(INT($I$6)*100+1,METEO_SADM!$A$1:$L$505,9,FALSE),"s/d")
B12: 02 a 03 | H12: =SUM(C12:G12) | R12: =IFERROR(VLOOKUP(INT($I$6)*100+2,METEO_SADM!$A$1:$L$505,5,FALSE),"s/d") | S12: =IFERROR(VLOOKUP(INT($I$6)*100+2,METEO_SADM!$A$1:$L$505,6,FALSE),"s/d") | T12: =IFERROR(VLOOKUP(INT($I$6)*100+2,METEO_SADM!$A$1:$L$505,7,FALSE),"s/d") | U12: =IFERROR(VLOOKUP(INT($I$6)*100+2,METEO_SADM!$A$1:$L$505,8,FALSE),"s/d") | V12: =IFERROR(VLOOKUP(INT($I$6)*100+2,METEO_SADM!$A$1:$L$505,9,FALSE),"s/d")
B13: 03 a 04 | H13: =SUM(C13:G13) | R13: =IFERROR(VLOOKUP(INT($I$6)*100+3,METEO_SADM!$A$1:$L$505,5,FALSE),"s/d") | S13: =IFERROR(VLOOKUP(INT($I$6)*100+3,METEO_SADM!$A$1:$L$505,6,FALSE),"s/d") | T13: =IFERROR(VLOOKUP(INT($I$6)*100+3,METEO_SADM!$A$1:$L$505,7,FALSE),"s/d") | U13: =IFERROR(VLOOKUP(INT($I$6)*100+3,METEO_SADM!$A$1:$L$505,8,FALSE),"s/d") | V13: =IFERROR(VLOOKUP(INT($I$6)*100+3,METEO_SADM!$A$1:$L$505,9,FALSE),"s/d")
B14: 04 a 05 | H14: =SUM(C14:G14) | R14: =IFERROR(VLOOKUP(INT($I$6)*100+4,METEO_SADM!$A$1:$L$505,5,FALSE),"s/d") | S14: =IFERROR(VLOOKUP(INT($I$6)*100+4,METEO_SADM!$A$1:$L$505,6,FALSE),"s/d") | T14: =IFERROR(VLOOKUP(INT($I$6)*100+4,METEO_SADM!$A$1:$L$505,7,FALSE),"s/d") | U14: =IFERROR(VLOOKUP(INT($I$6)*100+4,METEO_SADM!$A$1:$L$505,8,FALSE),"s/d") | V14: =IFERROR(VLOOKUP(INT($I$6)*100+4,METEO_SADM!$A$1:$L$505,9,FALSE),"s/d")
B15: 05 a 06 | H15: =SUM(C15:G15) | R15: =IFERROR(VLOOKUP(INT($I$6)*100+5,METEO_SADM!$A$1:$L$505,5,FALSE),"s/d") | S15: =IFERROR(VLOOKUP(INT($I$6)*100+5,METEO_SADM!$A$1:$L$505,6,FALSE),"s/d") | T15: =IFERROR(VLOOKUP(INT($I$6)*100+5,METEO_SADM!$A$1:$L$505,7,FALSE),"s/d") | U15: =IFERROR(VLOOKUP(INT($I$6)*100+5,METEO_SADM!$A$1:$L$505,8,FALSE),"s/d") | V15: =IFERROR(VLOOKUP(INT($I$6)*100+5,METEO_SADM!$A$1:$L$505,9,FALSE),"s/d")
B16: 06 a 07 | H16: =SUM(C16:G16) | R16: =IFERROR(VLOOKUP(INT($I$6)*100+6,METEO_SADM!$A$1:$L$505,5,FALSE),"s/d") | S16: =IFERROR(VLOOKUP(INT($I$6)*100+6,METEO_SADM!$A$1:$L$505,6,FALSE),"s/d") | T16: =IFERROR(VLOOKUP(INT($I$6)*100+6,METEO_SADM!$A$1:$L$505,7,FALSE),"s/d") | U16: =IFERROR(VLOOKUP(INT($I$6)*100+6,METEO_SADM!$A$1:$L$505,8,FALSE),"s/d") | V16: =IFERROR(VLOOKUP(INT($I$6)*100+6,METEO_SADM!$A$1:$L$505,9,FALSE),"s/d")
B17: 07 a 08 | H17: =SUM(C17:G17) | R17: =IFERROR(VLOOKUP(INT($I$6)*100+7,METEO_SADM!$A$1:$L$505,5,FALSE),"s/d") | S17: =IFERROR(VLOOKUP(INT($I$6)*100+7,METEO_SADM!$A$1:$L$505,6,FALSE),"s/d") | T17: =IFERROR(VLOOKUP(INT($I$6)*100+7,METEO_SADM!$A$1:$L$505,7,FALSE),"s/d") | U17: =IFERROR(VLOOKUP(INT($I$6)*100+7,METEO_SADM!$A$1:$L$505,8,FALSE),"s/d") | V17: =IFERROR(VLOOKUP(INT($I$6)*100+7,METEO_SADM!$A$1:$L$505,9,FALSE),"s/d")
B18: 08 a 09 | H18: =SUM(C18:G18) | R18: =IFERROR(VLOOKUP(INT($I$6)*100+8,METEO_SADM!$A$1:$L$505,5,FALSE),"s/d") | S18: =IFERROR(VLOOKUP(INT($I$6)*100+8,METEO_SADM!$A$1:$L$505,6,FALSE),"s/d") | T18: =IFERROR(VLOOKUP(INT($I$6)*100+8,METEO_SADM!$A$1:$L$505,7,FALSE),"s/d") | U18: =IFERROR(VLOOKUP(INT($I$6)*100+8,METEO_SADM!$A$1:$L$505,8,FALSE),"s/d") | V18: =IFERROR(VLOOKUP(INT($I$6)*100+8,METEO_SADM!$A$1:$L$505,9,FALSE),"s/d")
B19: 09 a 10 | H19: =SUM(C19:G19) | R19: =IFERROR(VLOOKUP(INT($I$6)*100+9,METEO_SADM!$A$1:$L$505,5,FALSE),"s/d") | S19: =IFERROR(VLOOKUP(INT($I$6)*100+9,METEO_SADM!$A$1:$L$505,6,FALSE),"s/d") | T19: =IFERROR(VLOOKUP(INT($I$6)*100+9,METEO_SADM!$A$1:$L$505,7,FALSE),"s/d") | U19: =IFERROR(VLOOKUP(INT($I$6)*100+9,METEO_SADM!$A$1:$L$505,8,FALSE),"s/d") | V19: =IFERROR(VLOOKUP(INT($I$6)*100+9,METEO_SADM!$A$1:$L$505,9,FALSE),"s/d")
B20: 10 a 11 | H20: =SUM(C20:G20) | R20: =IFERROR(VLOOKUP(INT($I$6)*100+10,METEO_SADM!$A$1:$L$505,5,FALSE),"s/d") | S20: =IFERROR(VLOOKUP(INT($I$6)*100+10,METEO_SADM!$A$1:$L$505,6,FALSE),"s/d") | T20: =IFERROR(VLOOKUP(INT($I$6)*100+10,METEO_SADM!$A$1:$L$505,7,FALSE),"s/d") | U20: =IFERROR(VLOOKUP(INT($I$6)*100+10,METEO_SADM!$A$1:$L$505,8,FALSE),"s/d") | V20: =IFERROR(VLOOKUP(INT($I$6)*100+10,METEO_SADM!$A$1:$L$505,9,FALSE),"s/d")
B21: 11 a 12 | E21: IMC | H21: =SUM(C21:G21) | R21: =IFERROR(VLOOKUP(INT($I$6)*100+11,METEO_SADM!$A$1:$L$505,5,FALSE),"s/d") | S21: =IFERROR(VLOOKUP(INT($I$6)*100+11,METEO_SADM!$A$1:$L$505,6,FALSE),"s/d") | T21: =IFERROR(VLOOKUP(INT($I$6)*100+11,METEO_SADM!$A$1:$L$505,7,FALSE),"s/d") | U21: =IFERROR(VLOOKUP(INT($I$6)*100+11,METEO_SADM!$A$1:$L$505,8,FALSE),"s/d") | V21: =IFERROR(VLOOKUP(INT($I$6)*100+11,METEO_SADM!$A$1:$L$505,9,FALSE),"s/d")
B22: 12 a 13 | E22: IMC | H22: =SUM(C22:G22) | R22: =IFERROR(VLOOKUP(INT($I$6)*100+12,METEO_SADM!$A$1:$L$505,5,FALSE),"s/d") | S22: =IFERROR(VLOOKUP(INT($I$6)*100+12,METEO_SADM!$A$1:$L$505,6,FALSE),"s/d") | T22: =IFERROR(VLOOKUP(INT($I$6)*100+12,METEO_SADM!$A$1:$L$505,7,FALSE),"s/d") | U22: =IFERROR(VLOOKUP(INT($I$6)*100+12,METEO_SADM!$A$1:$L$505,8,FALSE),"s/d") | V22: =IFERROR(VLOOKUP(INT($I$6)*100+12,METEO_SADM!$A$1:$L$505,9,FALSE),"s/d")
B23: 13 a 14 | E23: IMC | H23: =SUM(C23:G23) | R23: =IFERROR(VLOOKUP(INT($I$6)*100+13,METEO_SADM!$A$1:$L$505,5,FALSE),"s/d") | S23: =IFERROR(VLOOKUP(INT($I$6)*100+13,METEO_SADM!$A$1:$L$505,6,FALSE),"s/d") | T23: =IFERROR(VLOOKUP(INT($I$6)*100+13,METEO_SADM!$A$1:$L$505,7,FALSE),"s/d") | U23: =IFERROR(VLOOKUP(INT($I$6)*100+13,METEO_SADM!$A$1:$L$505,8,FALSE),"s/d") | V23: =IFERROR(VLOOKUP(INT($I$6)*100+13,METEO_SADM!$A$1:$L$505,9,FALSE),"s/d")
B24: 14 a 15 | E24: IMC | H24: =SUM(C24:G24) | R24: =IFERROR(VLOOKUP(INT($I$6)*100+14,METEO_SADM!$A$1:$L$505,5,FALSE),"s/d") | S24: =IFERROR(VLOOKUP(INT($I$6)*100+14,METEO_SADM!$A$1:$L$505,6,FALSE),"s/d") | T24: =IFERROR(VLOOKUP(INT($I$6)*100+14,METEO_SADM!$A$1:$L$505,7,FALSE),"s/d") | U24: =IFERROR(VLOOKUP(INT($I$6)*100+14,METEO_SADM!$A$1:$L$505,8,FALSE),"s/d") | V24: =IFERROR(VLOOKUP(INT($I$6)*100+14,METEO_SADM!$A$1:$L$505,9,FALSE),"s/d")
B25: 15 a 16 | E25: IMC | H25: =SUM(C25:G25) | R25: =IFERROR(VLOOKUP(INT($I$6)*100+15,METEO_SADM!$A$1:$L$505,5,FALSE),"s/d") | S25: =IFERROR(VLOOKUP(INT($I$6)*100+15,METEO_SADM!$A$1:$L$505,6,FALSE),"s/d") | T25: =IFERROR(VLOOKUP(INT($I$6)*100+15,METEO_SADM!$A$1:$L$505,7,FALSE),"s/d") | U25: =IFERROR(VLOOKUP(INT($I$6)*100+15,METEO_SADM!$A$1:$L$505,8,FALSE),"s/d") | V25: =IFERROR(VLOOKUP(INT($I$6)*100+15,METEO_SADM!$A$1:$L$505,9,FALSE),"s/d")
B26: 16 a 17 | E26: IMC | H26: =SUM(C26:G26) | R26: =IFERROR(VLOOKUP(INT($I$6)*100+16,METEO_SADM!$A$1:$L$505,5,FALSE),"s/d") | S26: =IFERROR(VLOOKUP(INT($I$6)*100+16,METEO_SADM!$A$1:$L$505,6,FALSE),"s/d") | T26: =IFERROR(VLOOKUP(INT($I$6)*100+16,METEO_SADM!$A$1:$L$505,7,FALSE),"s/d") | U26: =IFERROR(VLOOKUP(INT($I$6)*100+16,METEO_SADM!$A$1:$L$505,8,FALSE),"s/d") | V26: =IFERROR(VLOOKUP(INT($I$6)*100+16,METEO_SADM!$A$1:$L$505,9,FALSE),"s/d")
B27: 17 a 18 | E27: 2 | H27: =SUM(C27:G27) | K27: 1 | R27: =IFERROR(VLOOKUP(INT($I$6)*100+17,METEO_SADM!$A$1:$L$505,5,FALSE),"s/d") | S27: =IFERROR(VLOOKUP(INT($I$6)*100+17,METEO_SADM!$A$1:$L$505,6,FALSE),"s/d") | T27: =IFERROR(VLOOKUP(INT($I$6)*100+17,METEO_SADM!$A$1:$L$505,7,FALSE),"s/d") | U27: =IFERROR(VLOOKUP(INT($I$6)*100+17,METEO_SADM!$A$1:$L$505,8,FALSE),"s/d") | V27: =IFERROR(VLOOKUP(INT($I$6)*100+17,METEO_SADM!$A$1:$L$505,9,FALSE),"s/d")
B28: 18 a 19 | E28: 6 | F28: 18 | H28: =SUM(C28:G28) | K28: 1 | R28: =IFERROR(VLOOKUP(INT($I$6)*100+18,METEO_SADM!$A$1:$L$505,5,FALSE),"s/d") | S28: =IFERROR(VLOOKUP(INT($I$6)*100+18,METEO_SADM!$A$1:$L$505,6,FALSE),"s/d") | T28: =IFERROR(VLOOKUP(INT($I$6)*100+18,METEO_SADM!$A$1:$L$505,7,FALSE),"s/d") | U28: =IFERROR(VLOOKUP(INT($I$6)*100+18,METEO_SADM!$A$1:$L$505,8,FALSE),"s/d") | V28: =IFERROR(VLOOKUP(INT($I$6)*100+18,METEO_SADM!$A$1:$L$505,9,FALSE),"s/d")
B29: 19 a 20 | E29: 6 | F29: 40 | H29: =SUM(C29:G29) | K29: 1 | R29: =IFERROR(VLOOKUP(INT($I$6)*100+19,METEO_SADM!$A$1:$L$505,5,FALSE),"s/d") | S29: =IFERROR(VLOOKUP(INT($I$6)*100+19,METEO_SADM!$A$1:$L$505,6,FALSE),"s/d") | T29: =IFERROR(VLOOKUP(INT($I$6)*100+19,METEO_SADM!$A$1:$L$505,7,FALSE),"s/d") | U29: =IFERROR(VLOOKUP(INT($I$6)*100+19,METEO_SADM!$A$1:$L$505,8,FALSE),"s/d") | V29: =IFERROR(VLOOKUP(INT($I$6)*100+19,METEO_SADM!$A$1:$L$505,9,FALSE),"s/d")
B30: 20 a 21 | E30: 3 | F30: 18 | H30: =SUM(C30:G30) | K30: 1 | R30: =IFERROR(VLOOKUP(INT($I$6)*100+20,METEO_SADM!$A$1:$L$505,5,FALSE),"s/d") | S30: =IFERROR(VLOOKUP(INT($I$6)*100+20,METEO_SADM!$A$1:$L$505,6,FALSE),"s/d") | T30: =IFERROR(VLOOKUP(INT($I$6)*100+20,METEO_SADM!$A$1:$L$505,7,FALSE),"s/d") | U30: =IFERROR(VLOOKUP(INT($I$6)*100+20,METEO_SADM!$A$1:$L$505,8,FALSE),"s/d") | V30: =IFERROR(VLOOKUP(INT($I$6)*100+20,METEO_SADM!$A$1:$L$505,9,FALSE),"s/d")
B31: 21 a 22 | H31: =SUM(C31:G31) | K31: 1 | R31: =IFERROR(VLOOKUP(INT($I$6)*100+21,METEO_SADM!$A$1:$L$505,5,FALSE),"s/d") | S31: =IFERROR(VLOOKUP(INT($I$6)*100+21,METEO_SADM!$A$1:$L$505,6,FALSE),"s/d") | T31: =IFERROR(VLOOKUP(INT($I$6)*100+21,METEO_SADM!$A$1:$L$505,7,FALSE),"s/d") | U31: =IFERROR(VLOOKUP(INT($I$6)*100+21,METEO_SADM!$A$1:$L$505,8,FALSE),"s/d") | V31: =IFERROR(VLOOKUP(INT($I$6)*100+21,METEO_SADM!$A$1:$L$505,9,FALSE),"s/d")
B32: 22 a 23 | H32: =SUM(C32:G32) | R32: =IFERROR(VLOOKUP(INT($I$6)*100+22,METEO_SADM!$A$1:$L$505,5,FALSE),"s/d") | S32: =IFERROR(VLOOKUP(INT($I$6)*100+22,METEO_SADM!$A$1:$L$505,6,FALSE),"s/d") | T32: =IFERROR(VLOOKUP(INT($I$6)*100+22,METEO_SADM!$A$1:$L$505,7,FALSE),"s/d") | U32: =IFERROR(VLOOKUP(INT($I$6)*100+22,METEO_SADM!$A$1:$L$505,8,FALSE),"s/d") | V32: =IFERROR(VLOOKUP(INT($I$6)*100+22,METEO_SADM!$A$1:$L$505,9,FALSE),"s/d")
B33: 23 a 00 | H33: =SUM(C33:G33) | P33: pista | R33: =IFERROR(VLOOKUP(INT($I$6)*100+23,METEO_SADM!$A$1:$L$505,5,FALSE),"s/d") | S33: =IFERROR(VLOOKUP(INT($I$6)*100+23,METEO_SADM!$A$1:$L$505,6,FALSE),"s/d") | T33: =IFERROR(VLOOKUP(INT($I$6)*100+23,METEO_SADM!$A$1:$L$505,7,FALSE),"s/d") | U33: =IFERROR(VLOOKUP(INT($I$6)*100+23,METEO_SADM!$A$1:$L$505,8,FALSE),"s/d") | V33: =IFERROR(VLOOKUP(INT($I$6)*100+23,METEO_SADM!$A$1:$L$505,9,FALSE),"s/d")
B34: TOTAL DIARIO | C34: COMERCIAL | D34: OFICIAL | E34: OTROS | F34: LOCAL | G34: SOBREVUELO | H34: TOTAL MOVIMIENTOS | I34: IFR | J34: PISTA | P34: suma total
J35: =J9 | K35: =K9 | L35: =L9 | M35: =M9 | P35: =SUM(J36:M36)
C36: =SUM(C10:C33) | D36: =SUM(D10:D33) | E36: =SUM(E10:E33) | F36: =SUM(F10:F33) | G36: =SUM(G10:G33) | H36: =SUM(H10:H33) | I36: =SUM(I10:I33) | J36: =SUM(J10:J33) | ... M36: =SUM(M10:M33)
C37: =((C36*100)/$H$36)/100 | D37: =((D36*100)/$H$36)/100 | E37: =((E36*100)/$H$36)/100 | F37: =((F36*100)/$H$36)/100 | G37: =((G36*100)/$H$36)/100 | H37: =((H36*100)/$H$36)/100 | I37: =((I36*100)/$H$36)/100 | J37: =((J36*100)/$P$35)/100 | K37: =((K36*100)/$P$35)/100 | L37: =((L36*100)/$P$35)/100 | M37: =((M36*100)/$P$35)/100
F44: Firma y aclaración del responsable

Sheet 4
B3: MOVIMIENTO DE AERONAVES
B4: ESTADISTICA DIARIA
C6: DEPENDENCIA: | D6: TORRE MORON | H6: FECHA: | I6: 46238
B8: FRANJA HORARIA UTC | C8: COMERCIAL | D8: OFICIAL | E8: OTROS | F8: LOCAL | G8: SOBREVUELO | H8: TOTAL MOVIMIENTOS | I8: IFR | J8: PISTA | R8: CONDICION METEOROLOGICA DEL AERODROMO (SADM)
J9: 2 | K9: 20 | R9: CONDICION | S9: VIS (m) | T9: TECHO (ft) | U9: SPECI | V9: METAR OBSERVADO
B10: 00 a 01 | H10: =SUM(C10:G10) | R10: =IFERROR(VLOOKUP(INT($I$6)*100+0,METEO_SADM!$A$1:$L$505,5,FALSE),"s/d") | S10: =IFERROR(VLOOKUP(INT($I$6)*100+0,METEO_SADM!$A$1:$L$505,6,FALSE),"s/d") | T10: =IFERROR(VLOOKUP(INT($I$6)*100+0,METEO_SADM!$A$1:$L$505,7,FALSE),"s/d") | U10: =IFERROR(VLOOKUP(INT($I$6)*100+0,METEO_SADM!$A$1:$L$505,8,FALSE),"s/d") | V10: =IFERROR(VLOOKUP(INT($I$6)*100+0,METEO_SADM!$A$1:$L$505,9,FALSE),"s/d")
B11: 01 a 02 | H11: =SUM(C11:G11) | R11: =IFERROR(VLOOKUP(INT($I$6)*100+1,METEO_SADM!$A$1:$L$505,5,FALSE),"s/d") | S11: =IFERROR(VLOOKUP(INT($I$6)*100+1,METEO_SADM!$A$1:$L$505,6,FALSE),"s/d") | T11: =IFERROR(VLOOKUP(INT($I$6)*100+1,METEO_SADM!$A$1:$L$505,7,FALSE),"s/d") | U11: =IFERROR(VLOOKUP(INT($I$6)*100+1,METEO_SADM!$A$1:$L$505,8,FALSE),"s/d") | V11: =IFERROR(VLOOKUP(INT($I$6)*100+1,METEO_SADM!$A$1:$L$505,9,FALSE),"s/d")
B12: 02 a 03 | H12: =SUM(C12:G12) | R12: =IFERROR(VLOOKUP(INT($I$6)*100+2,METEO_SADM!$A$1:$L$505,5,FALSE),"s/d") | S12: =IFERROR(VLOOKUP(INT($I$6)*100+2,METEO_SADM!$A$1:$L$505,6,FALSE),"s/d") | T12: =IFERROR(VLOOKUP(INT($I$6)*100+2,METEO_SADM!$A$1:$L$505,7,FALSE),"s/d") | U12: =IFERROR(VLOOKUP(INT($I$6)*100+2,METEO_SADM!$A$1:$L$505,8,FALSE),"s/d") | V12: =IFERROR(VLOOKUP(INT($I$6)*100+2,METEO_SADM!$A$1:$L$505,9,FALSE),"s/d")
B13: 03 a 04 | H13: =SUM(C13:G13) | R13: =IFERROR(VLOOKUP(INT($I$6)*100+3,METEO_SADM!$A$1:$L$505,5,FALSE),"s/d") | S13: =IFERROR(VLOOKUP(INT($I$6)*100+3,METEO_SADM!$A$1:$L$505,6,FALSE),"s/d") | T13: =IFERROR(VLOOKUP(INT($I$6)*100+3,METEO_SADM!$A$1:$L$505,7,FALSE),"s/d") | U13: =IFERROR(VLOOKUP(INT($I$6)*100+3,METEO_SADM!$A$1:$L$505,8,FALSE),"s/d") | V13: =IFERROR(VLOOKUP(INT($I$6)*100+3,METEO_SADM!$A$1:$L$505,9,FALSE),"s/d")
B14: 04 a 05 | H14: =SUM(C14:G14) | R14: =IFERROR(VLOOKUP(INT($I$6)*100+4,METEO_SADM!$A$1:$L$505,5,FALSE),"s/d") | S14: =IFERROR(VLOOKUP(INT($I$6)*100+4,METEO_SADM!$A$1:$L$505,6,FALSE),"s/d") | T14: =IFERROR(VLOOKUP(INT($I$6)*100+4,METEO_SADM!$A$1:$L$505,7,FALSE),"s/d") | U14: =IFERROR(VLOOKUP(INT($I$6)*100+4,METEO_SADM!$A$1:$L$505,8,FALSE),"s/d") | V14: =IFERROR(VLOOKUP(INT($I$6)*100+4,METEO_SADM!$A$1:$L$505,9,FALSE),"s/d")
B15: 05 a 06 | H15: =SUM(C15:G15) | R15: =IFERROR(VLOOKUP(INT($I$6)*100+5,METEO_SADM!$A$1:$L$505,5,FALSE),"s/d") | S15: =IFERROR(VLOOKUP(INT($I$6)*100+5,METEO_SADM!$A$1:$L$505,6,FALSE),"s/d") | T15: =IFERROR(VLOOKUP(INT($I$6)*100+5,METEO_SADM!$A$1:$L$505,7,FALSE),"s/d") | U15: =IFERROR(VLOOKUP(INT($I$6)*100+5,METEO_SADM!$A$1:$L$505,8,FALSE),"s/d") | V15: =IFERROR(VLOOKUP(INT($I$6)*100+5,METEO_SADM!$A$1:$L$505,9,FALSE),"s/d")
B16: 06 a 07 | H16: =SUM(C16:G16) | R16: =IFERROR(VLOOKUP(INT($I$6)*100+6,METEO_SADM!$A$1:$L$505,5,FALSE),"s/d") | S16: =IFERROR(VLOOKUP(INT($I$6)*100+6,METEO_SADM!$A$1:$L$505,6,FALSE),"s/d") | T16: =IFERROR(VLOOKUP(INT($I$6)*100+6,METEO_SADM!$A$1:$L$505,7,FALSE),"s/d") | U16: =IFERROR(VLOOKUP(INT($I$6)*100+6,METEO_SADM!$A$1:$L$505,8,FALSE),"s/d") | V16: =IFERROR(VLOOKUP(INT($I$6)*100+6,METEO_SADM!$A$1:$L$505,9,FALSE),"s/d")
B17: 07 a 08 | H17: =SUM(C17:G17) | R17: =IFERROR(VLOOKUP(INT($I$6)*100+7,METEO_SADM!$A$1:$L$505,5,FALSE),"s/d") | S17: =IFERROR(VLOOKUP(INT($I$6)*100+7,METEO_SADM!$A$1:$L$505,6,FALSE),"s/d") | T17: =IFERROR(VLOOKUP(INT($I$6)*100+7,METEO_SADM!$A$1:$L$505,7,FALSE),"s/d") | U17: =IFERROR(VLOOKUP(INT($I$6)*100+7,METEO_SADM!$A$1:$L$505,8,FALSE),"s/d") | V17: =IFERROR(VLOOKUP(INT($I$6)*100+7,METEO_SADM!$A$1:$L$505,9,FALSE),"s/d")
B18: 08 a 09 | H18: =SUM(C18:G18) | R18: =IFERROR(VLOOKUP(INT($I$6)*100+8,METEO_SADM!$A$1:$L$505,5,FALSE),"s/d") | S18: =IFERROR(VLOOKUP(INT($I$6)*100+8,METEO_SADM!$A$1:$L$505,6,FALSE),"s/d") | T18: =IFERROR(VLOOKUP(INT($I$6)*100+8,METEO_SADM!$A$1:$L$505,7,FALSE),"s/d") | U18: =IFERROR(VLOOKUP(INT($I$6)*100+8,METEO_SADM!$A$1:$L$505,8,FALSE),"s/d") | V18: =IFERROR(VLOOKUP(INT($I$6)*100+8,METEO_SADM!$A$1:$L$505,9,FALSE),"s/d")
B19: 09 a 10 | H19: =SUM(C19:G19) | R19: =IFERROR(VLOOKUP(INT($I$6)*100+9,METEO_SADM!$A$1:$L$505,5,FALSE),"s/d") | S19: =IFERROR(VLOOKUP(INT($I$6)*100+9,METEO_SADM!$A$1:$L$505,6,FALSE),"s/d") | T19: =IFERROR(VLOOKUP(INT($I$6)*100+9,METEO_SADM!$A$1:$L$505,7,FALSE),"s/d") | U19: =IFERROR(VLOOKUP(INT($I$6)*100+9,METEO_SADM!$A$1:$L$505,8,FALSE),"s/d") | V19: =IFERROR(VLOOKUP(INT($I$6)*100+9,METEO_SADM!$A$1:$L$505,9,FALSE),"s/d")
B20: 10 a 11 | H20: =SUM(C20:G20) | R20: =IFERROR(VLOOKUP(INT($I$6)*100+10,METEO_SADM!$A$1:$L$505,5,FALSE),"s/d") | S20: =IFERROR(VLOOKUP(INT($I$6)*100+10,METEO_SADM!$A$1:$L$505,6,FALSE),"s/d") | T20: =IFERROR(VLOOKUP(INT($I$6)*100+10,METEO_SADM!$A$1:$L$505,7,FALSE),"s/d") | U20: =IFERROR(VLOOKUP(INT($I$6)*100+10,METEO_SADM!$A$1:$L$505,8,FALSE),"s/d") | V20: =IFERROR(VLOOKUP(INT($I$6)*100+10,METEO_SADM!$A$1:$L$505,9,FALSE),"s/d")
B21: 11 a 12 | E21: imc | H21: =SUM(C21:G21) | R21: =IFERROR(VLOOKUP(INT($I$6)*100+11,METEO_SADM!$A$1:$L$505,5,FALSE),"s/d") | S21: =IFERROR(VLOOKUP(INT($I$6)*100+11,METEO_SADM!$A$1:$L$505,6,FALSE),"s/d") | T21: =IFERROR(VLOOKUP(INT($I$6)*100+11,METEO_SADM!$A$1:$L$505,7,FALSE),"s/d") | U21: =IFERROR(VLOOKUP(INT($I$6)*100+11,METEO_SADM!$A$1:$L$505,8,FALSE),"s/d") | V21: =IFERROR(VLOOKUP(INT($I$6)*100+11,METEO_SADM!$A$1:$L$505,9,FALSE),"s/d")
B22: 12 a 13 | E22: imc | H22: =SUM(C22:G22) | R22: =IFERROR(VLOOKUP(INT($I$6)*100+12,METEO_SADM!$A$1:$L$505,5,FALSE),"s/d") | S22: =IFERROR(VLOOKUP(INT($I$6)*100+12,METEO_SADM!$A$1:$L$505,6,FALSE),"s/d") | T22: =IFERROR(VLOOKUP(INT($I$6)*100+12,METEO_SADM!$A$1:$L$505,7,FALSE),"s/d") | U22: =IFERROR(VLOOKUP(INT($I$6)*100+12,METEO_SADM!$A$1:$L$505,8,FALSE),"s/d") | V22: =IFERROR(VLOOKUP(INT($I$6)*100+12,METEO_SADM!$A$1:$L$505,9,FALSE),"s/d")
B23: 13 a 14 | E23: imc | H23: =SUM(C23:G23) | R23: =IFERROR(VLOOKUP(INT($I$6)*100+13,METEO_SADM!$A$1:$L$505,5,FALSE),"s/d") | S23: =IFERROR(VLOOKUP(INT($I$6)*100+13,METEO_SADM!$A$1:$L$505,6,FALSE),"s/d") | T23: =IFERROR(VLOOKUP(INT($I$6)*100+13,METEO_SADM!$A$1:$L$505,7,FALSE),"s/d") | U23: =IFERROR(VLOOKUP(INT($I$6)*100+13,METEO_SADM!$A$1:$L$505,8,FALSE),"s/d") | V23: =IFERROR(VLOOKUP(INT($I$6)*100+13,METEO_SADM!$A$1:$L$505,9,FALSE),"s/d")
B24: 14 a 15 | E24: imc | H24: =SUM(C24:G24) | R24: =IFERROR(VLOOKUP(INT($I$6)*100+14,METEO_SADM!$A$1:$L$505,5,FALSE),"s/d") | S24: =IFERROR(VLOOKUP(INT($I$6)*100+14,METEO_SADM!$A$1:$L$505,6,FALSE),"s/d") | T24: =IFERROR(VLOOKUP(INT($I$6)*100+14,METEO_SADM!$A$1:$L$505,7,FALSE),"s/d") | U24: =IFERROR(VLOOKUP(INT($I$6)*100+14,METEO_SADM!$A$1:$L$505,8,FALSE),"s/d") | V24: =IFERROR(VLOOKUP(INT($I$6)*100+14,METEO_SADM!$A$1:$L$505,9,FALSE),"s/d")
B25: 15 a 16 | E25: imc | H25: =SUM(C25:G25) | R25: =IFERROR(VLOOKUP(INT($I$6)*100+15,METEO_SADM!$A$1:$L$505,5,FALSE),"s/d") | S25: =IFERROR(VLOOKUP(INT($I$6)*100+15,METEO_SADM!$A$1:$L$505,6,FALSE),"s/d") | T25: =IFERROR(VLOOKUP(INT($I$6)*100+15,METEO_SADM!$A$1:$L$505,7,FALSE),"s/d") | U25: =IFERROR(VLOOKUP(INT($I$6)*100+15,METEO_SADM!$A$1:$L$505,8,FALSE),"s/d") | V25: =IFERROR(VLOOKUP(INT($I$6)*100+15,METEO_SADM!$A$1:$L$505,9,FALSE),"s/d")
B26: 16 a 17 | E26: imc | H26: =SUM(C26:G26) | R26: =IFERROR(VLOOKUP(INT($I$6)*100+16,METEO_SADM!$A$1:$L$505,5,FALSE),"s/d") | S26: =IFERROR(VLOOKUP(INT($I$6)*100+16,METEO_SADM!$A$1:$L$505,6,FALSE),"s/d") | T26: =IFERROR(VLOOKUP(INT($I$6)*100+16,METEO_SADM!$A$1:$L$505,7,FALSE),"s/d") | U26: =IFERROR(VLOOKUP(INT($I$6)*100+16,METEO_SADM!$A$1:$L$505,8,FALSE),"s/d") | V26: =IFERROR(VLOOKUP(INT($I$6)*100+16,METEO_SADM!$A$1:$L$505,9,FALSE),"s/d")
B27: 17 a 18 | E27: imc | H27: =SUM(C27:G27) | R27: =IFERROR(VLOOKUP(INT($I$6)*100+17,METEO_SADM!$A$1:$L$505,5,FALSE),"s/d") | S27: =IFERROR(VLOOKUP(INT($I$6)*100+17,METEO_SADM!$A$1:$L$505,6,FALSE),"s/d") | T27: =IFERROR(VLOOKUP(INT($I$6)*100+17,METEO_SADM!$A$1:$L$505,7,FALSE),"s/d") | U27: =IFERROR(VLOOKUP(INT($I$6)*100+17,METEO_SADM!$A$1:$L$505,8,FALSE),"s/d") | V27: =IFERROR(VLOOKUP(INT($I$6)*100+17,METEO_SADM!$A$1:$L$505,9,FALSE),"s/d")
B28: 18 a 19 | E28: 9 | F28: 4 | H28: =SUM(C28:G28) | K28: 1 | R28: =IFERROR(VLOOKUP(INT($I$6)*100+18,METEO_SADM!$A$1:$L$505,5,FALSE),"s/d") | S28: =IFERROR(VLOOKUP(INT($I$6)*100+18,METEO_SADM!$A$1:$L$505,6,FALSE),"s/d") | T28: =IFERROR(VLOOKUP(INT($I$6)*100+18,METEO_SADM!$A$1:$L$505,7,FALSE),"s/d") | U28: =IFERROR(VLOOKUP(INT($I$6)*100+18,METEO_SADM!$A$1:$L$505,8,FALSE),"s/d") | V28: =IFERROR(VLOOKUP(INT($I$6)*100+18,METEO_SADM!$A$1:$L$505,9,FALSE),"s/d")
B29: 19 a 20 | E29: 11 | F29: 22 | G29: 1 | H29: =SUM(C29:G29) | K29: 1 | R29: =IFERROR(VLOOKUP(INT($I$6)*100+19,METEO_SADM!$A$1:$L$505,5,FALSE),"s/d") | S29: =IFERROR(VLOOKUP(INT($I$6)*100+19,METEO_SADM!$A$1:$L$505,6,FALSE),"s/d") | T29: =IFERROR(VLOOKUP(INT($I$6)*100+19,METEO_SADM!$A$1:$L$505,7,FALSE),"s/d") | U29: =IFERROR(VLOOKUP(INT($I$6)*100+19,METEO_SADM!$A$1:$L$505,8,FALSE),"s/d") | V29: =IFERROR(VLOOKUP(INT($I$6)*100+19,METEO_SADM!$A$1:$L$505,9,FALSE),"s/d")
B30: 20 a 21 | E30: 8 | F30: 10 | H30: =SUM(C30:G30) | J30: 1 | R30: =IFERROR(VLOOKUP(INT($I$6)*100+20,METEO_SADM!$A$1:$L$505,5,FALSE),"s/d") | S30: =IFERROR(VLOOKUP(INT($I$6)*100+20,METEO_SADM!$A$1:$L$505,6,FALSE),"s/d") | T30: =IFERROR(VLOOKUP(INT($I$6)*100+20,METEO_SADM!$A$1:$L$505,7,FALSE),"s/d") | U30: =IFERROR(VLOOKUP(INT($I$6)*100+20,METEO_SADM!$A$1:$L$505,8,FALSE),"s/d") | V30: =IFERROR(VLOOKUP(INT($I$6)*100+20,METEO_SADM!$A$1:$L$505,9,FALSE),"s/d")
B31: 21 a 22 | H31: =SUM(C31:G31) | R31: =IFERROR(VLOOKUP(INT($I$6)*100+21,METEO_SADM!$A$1:$L$505,5,FALSE),"s/d") | S31: =IFERROR(VLOOKUP(INT($I$6)*100+21,METEO_SADM!$A$1:$L$505,6,FALSE),"s/d") | T31: =IFERROR(VLOOKUP(INT($I$6)*100+21,METEO_SADM!$A$1:$L$505,7,FALSE),"s/d") | U31: =IFERROR(VLOOKUP(INT($I$6)*100+21,METEO_SADM!$A$1:$L$505,8,FALSE),"s/d") | V31: =IFERROR(VLOOKUP(INT($I$6)*100+21,METEO_SADM!$A$1:$L$505,9,FALSE),"s/d")
B32: 22 a 23 | H32: =SUM(C32:G32) | R32: =IFERROR(VLOOKUP(INT($I$6)*100+22,METEO_SADM!$A$1:$L$505,5,FALSE),"s/d") | S32: =IFERROR(VLOOKUP(INT($I$6)*100+22,METEO_SADM!$A$1:$L$505,6,FALSE),"s/d") | T32: =IFERROR(VLOOKUP(INT($I$6)*100+22,METEO_SADM!$A$1:$L$505,7,FALSE),"s/d") | U32: =IFERROR(VLOOKUP(INT($I$6)*100+22,METEO_SADM!$A$1:$L$505,8,FALSE),"s/d") | V32: =IFERROR(VLOOKUP(INT($I$6)*100+22,METEO_SADM!$A$1:$L$505,9,FALSE),"s/d")
B33: 23 a 00 | H33: =SUM(C33:G33) | P33: pista | R33: =IFERROR(VLOOKUP(INT($I$6)*100+23,METEO_SADM!$A$1:$L$505,5,FALSE),"s/d") | S33: =IFERROR(VLOOKUP(INT($I$6)*100+23,METEO_SADM!$A$1:$L$505,6,FALSE),"s/d") | T33: =IFERROR(VLOOKUP(INT($I$6)*100+23,METEO_SADM!$A$1:$L$505,7,FALSE),"s/d") | U33: =IFERROR(VLOOKUP(INT($I$6)*100+23,METEO_SADM!$A$1:$L$505,8,FALSE),"s/d") | V33: =IFERROR(VLOOKUP(INT($I$6)*100+23,METEO_SADM!$A$1:$L$505,9,FALSE),"s/d")
B34: TOTAL DIARIO | C34: COMERCIAL | D34: OFICIAL | E34: OTROS | F34: LOCAL | G34: SOBREVUELO | H34: TOTAL MOVIMIENTOS | I34: IFR | J34: PISTA | P34: suma total
J35: =J9 | K35: =K9 | L35: =L9 | M35: =M9 | P35: =SUM(J36:M36)
C36: =SUM(C10:C33) | D36: =SUM(D10:D33) | E36: =SUM(E10:E33) | F36: =SUM(F10:F33) | G36: =SUM(G10:G33) | H36: =SUM(H10:H33) | I36: =SUM(I10:I33) | J36: =SUM(J10:J33) | ... M36: =SUM(M10:M33)
C37: =((C36*100)/$H$36)/100 | D37: =((D36*100)/$H$36)/100 | E37: =((E36*100)/$H$36)/100 | F37: =((F36*100)/$H$36)/100 | G37: =((G36*100)/$H$36)/100 | H37: =((H36*100)/$H$36)/100 | I37: =((I36*100)/$H$36)/100 | J37: =((J36*100)/$P$35)/100 | K37: =((K36*100)/$P$35)/100 | L37: =((L36*100)/$P$35)/100 | M37: =((M36*100)/$P$35)/100
F44: Firma y aclaración del responsable

Sheet 5
B3: MOVIMIENTO DE AERONAVES
B4: ESTADISTICA DIARIA
C6: DEPENDENCIA: | D6: TORRE MORON | H6: FECHA: | I6: 46239
B8: FRANJA HORARIA UTC | C8: COMERCIAL | D8: OFICIAL | E8: OTROS | F8: LOCAL | G8: SOBREVUELO | H8: TOTAL MOVIMIENTOS | I8: IFR | J8: PISTA | R8: CONDICION METEOROLOGICA DEL AERODROMO (SADM)
J9: 2 | K9: 20 | R9: CONDICION | S9: VIS (m) | T9: TECHO (ft) | U9: SPECI | V9: METAR OBSERVADO
B10: 00 a 01 | H10: =SUM(C10:G10) | R10: =IFERROR(VLOOKUP(INT($I$6)*100+0,METEO_SADM!$A$1:$L$505,5,FALSE),"s/d") | S10: =IFERROR(VLOOKUP(INT($I$6)*100+0,METEO_SADM!$A$1:$L$505,6,FALSE),"s/d") | T10: =IFERROR(VLOOKUP(INT($I$6)*100+0,METEO_SADM!$A$1:$L$505,7,FALSE),"s/d") | U10: =IFERROR(VLOOKUP(INT($I$6)*100+0,METEO_SADM!$A$1:$L$505,8,FALSE),"s/d") | V10: =IFERROR(VLOOKUP(INT($I$6)*100+0,METEO_SADM!$A$1:$L$505,9,FALSE),"s/d")
B11: 01 a 02 | H11: =SUM(C11:G11) | R11: =IFERROR(VLOOKUP(INT($I$6)*100+1,METEO_SADM!$A$1:$L$505,5,FALSE),"s/d") | S11: =IFERROR(VLOOKUP(INT($I$6)*100+1,METEO_SADM!$A$1:$L$505,6,FALSE),"s/d") | T11: =IFERROR(VLOOKUP(INT($I$6)*100+1,METEO_SADM!$A$1:$L$505,7,FALSE),"s/d") | U11: =IFERROR(VLOOKUP(INT($I$6)*100+1,METEO_SADM!$A$1:$L$505,8,FALSE),"s/d") | V11: =IFERROR(VLOOKUP(INT($I$6)*100+1,METEO_SADM!$A$1:$L$505,9,FALSE),"s/d")
B12: 02 a 03 | H12: =SUM(C12:G12) | R12: =IFERROR(VLOOKUP(INT($I$6)*100+2,METEO_SADM!$A$1:$L$505,5,FALSE),"s/d") | S12: =IFERROR(VLOOKUP(INT($I$6)*100+2,METEO_SADM!$A$1:$L$505,6,FALSE),"s/d") | T12: =IFERROR(VLOOKUP(INT($I$6)*100+2,METEO_SADM!$A$1:$L$505,7,FALSE),"s/d") | U12: =IFERROR(VLOOKUP(INT($I$6)*100+2,METEO_SADM!$A$1:$L$505,8,FALSE),"s/d") | V12: =IFERROR(VLOOKUP(INT($I$6)*100+2,METEO_SADM!$A$1:$L$505,9,FALSE),"s/d")
B13: 03 a 04 | H13: =SUM(C13:G13) | R13: =IFERROR(VLOOKUP(INT($I$6)*100+3,METEO_SADM!$A$1:$L$505,5,FALSE),"s/d") | S13: =IFERROR(VLOOKUP(INT($I$6)*100+3,METEO_SADM!$A$1:$L$505,6,FALSE),"s/d") | T13: =IFERROR(VLOOKUP(INT($I$6)*100+3,METEO_SADM!$A$1:$L$505,7,FALSE),"s/d") | U13: =IFERROR(VLOOKUP(INT($I$6)*100+3,METEO_SADM!$A$1:$L$505,8,FALSE),"s/d") | V13: =IFERROR(VLOOKUP(INT($I$6)*100+3,METEO_SADM!$A$1:$L$505,9,FALSE),"s/d")
B14: 04 a 05 | H14: =SUM(C14:G14) | R14: =IFERROR(VLOOKUP(INT($I$6)*100+4,METEO_SADM!$A$1:$L$505,5,FALSE),"s/d") | S14: =IFERROR(VLOOKUP(INT($I$6)*100+4,METEO_SADM!$A$1:$L$505,6,FALSE),"s/d") | T14: =IFERROR(VLOOKUP(INT($I$6)*100+4,METEO_SADM!$A$1:$L$505,7,FALSE),"s/d") | U14: =IFERROR(VLOOKUP(INT($I$6)*100+4,METEO_SADM!$A$1:$L$505,8,FALSE),"s/d") | V14: =IFERROR(VLOOKUP(INT($I$6)*100+4,METEO_SADM!$A$1:$L$505,9,FALSE),"s/d")
B15: 05 a 06 | H15: =SUM(C15:G15) | R15: =IFERROR(VLOOKUP(INT($I$6)*100+5,METEO_SADM!$A$1:$L$505,5,FALSE),"s/d") | S15: =IFERROR(VLOOKUP(INT($I$6)*100+5,METEO_SADM!$A$1:$L$505,6,FALSE),"s/d") | T15: =IFERROR(VLOOKUP(INT($I$6)*100+5,METEO_SADM!$A$1:$L$505,7,FALSE),"s/d") | U15: =IFERROR(VLOOKUP(INT($I$6)*100+5,METEO_SADM!$A$1:$L$505,8,FALSE),"s/d") | V15: =IFERROR(VLOOKUP(INT($I$6)*100+5,METEO_SADM!$A$1:$L$505,9,FALSE),"s/d")
B16: 06 a 07 | H16: =SUM(C16:G16) | R16: =IFERROR(VLOOKUP(INT($I$6)*100+6,METEO_SADM!$A$1:$L$505,5,FALSE),"s/d") | S16: =IFERROR(VLOOKUP(INT($I$6)*100+6,METEO_SADM!$A$1:$L$505,6,FALSE),"s/d") | T16: =IFERROR(VLOOKUP(INT($I$6)*100+6,METEO_SADM!$A$1:$L$505,7,FALSE),"s/d") | U16: =IFERROR(VLOOKUP(INT($I$6)*100+6,METEO_SADM!$A$1:$L$505,8,FALSE),"s/d") | V16: =IFERROR(VLOOKUP(INT($I$6)*100+6,METEO_SADM!$A$1:$L$505,9,FALSE),"s/d")
B17: 07 a 08 | H17: =SUM(C17:G17) | R17: =IFERROR(VLOOKUP(INT($I$6)*100+7,METEO_SADM!$A$1:$L$505,5,FALSE),"s/d") | S17: =IFERROR(VLOOKUP(INT($I$6)*100+7,METEO_SADM!$A$1:$L$505,6,FALSE),"s/d") | T17: =IFERROR(VLOOKUP(INT($I$6)*100+7,METEO_SADM!$A$1:$L$505,7,FALSE),"s/d") | U17: =IFERROR(VLOOKUP(INT($I$6)*100+7,METEO_SADM!$A$1:$L$505,8,FALSE),"s/d") | V17: =IFERROR(VLOOKUP(INT($I$6)*100+7,METEO_SADM!$A$1:$L$505,9,FALSE),"s/d")
B18: 08 a 09 | H18: =SUM(C18:G18) | R18: =IFERROR(VLOOKUP(INT($I$6)*100+8,METEO_SADM!$A$1:$L$505,5,FALSE),"s/d") | S18: =IFERROR(VLOOKUP(INT($I$6)*100+8,METEO_SADM!$A$1:$L$505,6,FALSE),"s/d") | T18: =IFERROR(VLOOKUP(INT($I$6)*100+8,METEO_SADM!$A$1:$L$505,7,FALSE),"s/d") | U18: =IFERROR(VLOOKUP(INT($I$6)*100+8,METEO_SADM!$A$1:$L$505,8,FALSE),"s/d") | V18: =IFERROR(VLOOKUP(INT($I$6)*100+8,METEO_SADM!$A$1:$L$505,9,FALSE),"s/d")
B19: 09 a 10 | H19: =SUM(C19:G19) | R19: =IFERROR(VLOOKUP(INT($I$6)*100+9,METEO_SADM!$A$1:$L$505,5,FALSE),"s/d") | S19: =IFERROR(VLOOKUP(INT($I$6)*100+9,METEO_SADM!$A$1:$L$505,6,FALSE),"s/d") | T19: =IFERROR(VLOOKUP(INT($I$6)*100+9,METEO_SADM!$A$1:$L$505,7,FALSE),"s/d") | U19: =IFERROR(VLOOKUP(INT($I$6)*100+9,METEO_SADM!$A$1:$L$505,8,FALSE),"s/d") | V19: =IFERROR(VLOOKUP(INT($I$6)*100+9,METEO_SADM!$A$1:$L$505,9,FALSE),"s/d")
B20: 10 a 11 | H20: =SUM(C20:G20) | R20: =IFERROR(VLOOKUP(INT($I$6)*100+10,METEO_SADM!$A$1:$L$505,5,FALSE),"s/d") | S20: =IFERROR(VLOOKUP(INT($I$6)*100+10,METEO_SADM!$A$1:$L$505,6,FALSE),"s/d") | T20: =IFERROR(VLOOKUP(INT($I$6)*100+10,METEO_SADM!$A$1:$L$505,7,FALSE),"s/d") | U20: =IFERROR(VLOOKUP(INT($I$6)*100+10,METEO_SADM!$A$1:$L$505,8,FALSE),"s/d") | V20: =IFERROR(VLOOKUP(INT($I$6)*100+10,METEO_SADM!$A$1:$L$505,9,FALSE),"s/d")
B21: 11 a 12 | H21: =SUM(C21:G21) | R21: =IFERROR(VLOOKUP(INT($I$6)*100+11,METEO_SADM!$A$1:$L$505,5,FALSE),"s/d") | S21: =IFERROR(VLOOKUP(INT($I$6)*100+11,METEO_SADM!$A$1:$L$505,6,FALSE),"s/d") | T21: =IFERROR(VLOOKUP(INT($I$6)*100+11,METEO_SADM!$A$1:$L$505,7,FALSE),"s/d") | U21: =IFERROR(VLOOKUP(INT($I$6)*100+11,METEO_SADM!$A$1:$L$505,8,FALSE),"s/d") | V21: =IFERROR(VLOOKUP(INT($I$6)*100+11,METEO_SADM!$A$1:$L$505,9,FALSE),"s/d")
B22: 12 a 13 | H22: =SUM(C22:G22) | R22: =IFERROR(VLOOKUP(INT($I$6)*100+12,METEO_SADM!$A$1:$L$505,5,FALSE),"s/d") | S22: =IFERROR(VLOOKUP(INT($I$6)*100+12,METEO_SADM!$A$1:$L$505,6,FALSE),"s/d") | T22: =IFERROR(VLOOKUP(INT($I$6)*100+12,METEO_SADM!$A$1:$L$505,7,FALSE),"s/d") | U22: =IFERROR(VLOOKUP(INT($I$6)*100+12,METEO_SADM!$A$1:$L$505,8,FALSE),"s/d") | V22: =IFERROR(VLOOKUP(INT($I$6)*100+12,METEO_SADM!$A$1:$L$505,9,FALSE),"s/d")
B23: 13 a 14 | H23: =SUM(C23:G23) | R23: =IFERROR(VLOOKUP(INT($I$6)*100+13,METEO_SADM!$A$1:$L$505,5,FALSE),"s/d") | S23: =IFERROR(VLOOKUP(INT($I$6)*100+13,METEO_SADM!$A$1:$L$505,6,FALSE),"s/d") | T23: =IFERROR(VLOOKUP(INT($I$6)*100+13,METEO_SADM!$A$1:$L$505,7,FALSE),"s/d") | U23: =IFERROR(VLOOKUP(INT($I$6)*100+13,METEO_SADM!$A$1:$L$505,8,FALSE),"s/d") | V23: =IFERROR(VLOOKUP(INT($I$6)*100+13,METEO_SADM!$A$1:$L$505,9,FALSE),"s/d")
B24: 14 a 15 | H24: =SUM(C24:G24) | R24: =IFERROR(VLOOKUP(INT($I$6)*100+14,METEO_SADM!$A$1:$L$505,5,FALSE),"s/d") | S24: =IFERROR(VLOOKUP(INT($I$6)*100+14,METEO_SADM!$A$1:$L$505,6,FALSE),"s/d") | T24: =IFERROR(VLOOKUP(INT($I$6)*100+14,METEO_SADM!$A$1:$L$505,7,FALSE),"s/d") | U24: =IFERROR(VLOOKUP(INT($I$6)*100+14,METEO_SADM!$A$1:$L$505,8,FALSE),"s/d") | V24: =IFERROR(VLOOKUP(INT($I$6)*100+14,METEO_SADM!$A$1:$L$505,9,FALSE),"s/d")
B25: 15 a 16 | H25: =SUM(C25:G25) | R25: =IFERROR(VLOOKUP(INT($I$6)*100+15,METEO_SADM!$A$1:$L$505,5,FALSE),"s/d") | S25: =IFERROR(VLOOKUP(INT($I$6)*100+15,METEO_SADM!$A$1:$L$505,6,FALSE),"s/d") | T25: =IFERROR(VLOOKUP(INT($I$6)*100+15,METEO_SADM!$A$1:$L$505,7,FALSE),"s/d") | U25: =IFERROR(VLOOKUP(INT($I$6)*100+15,METEO_SADM!$A$1:$L$505,8,FALSE),"s/d") | V25: =IFERROR(VLOOKUP(INT($I$6)*100+15,METEO_SADM!$A$1:$L$505,9,FALSE),"s/d")
B26: 16 a 17 | E26: 2 | H26: =SUM(C26:G26) | K26: 1 | R26: =IFERROR(VLOOKUP(INT($I$6)*100+16,METEO_SADM!$A$1:$L$505,5,FALSE),"s/d") | S26: =IFERROR(VLOOKUP(INT($I$6)*100+16,METEO_SADM!$A$1:$L$505,6,FALSE),"s/d") | T26: =IFERROR(VLOOKUP(INT($I$6)*100+16,METEO_SADM!$A$1:$L$505,7,FALSE),"s/d") | U26: =IFERROR(VLOOKUP(INT($I$6)*100+16,METEO_SADM!$A$1:$L$505,8,FALSE),"s/d") | V26: =IFERROR(VLOOKUP(INT($I$6)*100+16,METEO_SADM!$A$1:$L$505,9,FALSE),"s/d")
B27: 17 a 18 | E27: 2 | F27: 8 | H27: =SUM(C27:G27) | K27: 1 | R27: =IFERROR(VLOOKUP(INT($I$6)*100+17,METEO_SADM!$A$1:$L$505,5,FALSE),"s/d") | S27: =IFERROR(VLOOKUP(INT($I$6)*100+17,METEO_SADM!$A$1:$L$505,6,FALSE),"s/d") | T27: =IFERROR(VLOOKUP(INT($I$6)*100+17,METEO_SADM!$A$1:$L$505,7,FALSE),"s/d") | U27: =IFERROR(VLOOKUP(INT($I$6)*100+17,METEO_SADM!$A$1:$L$505,8,FALSE),"s/d") | V27: =IFERROR(VLOOKUP(INT($I$6)*100+17,METEO_SADM!$A$1:$L$505,9,FALSE),"s/d")
B28: 18 a 19 | E28: 12 | F28: 16 | H28: =SUM(C28:G28) | K28: 1 | R28: =IFERROR(VLOOKUP(INT($I$6)*100+18,METEO_SADM!$A$1:$L$505,5,FALSE),"s/d") | S28: =IFERROR(VLOOKUP(INT($I$6)*100+18,METEO_SADM!$A$1:$L$505,6,FALSE),"s/d") | T28: =IFERROR(VLOOKUP(INT($I$6)*100+18,METEO_SADM!$A$1:$L$505,7,FALSE),"s/d") | U28: =IFERROR(VLOOKUP(INT($I$6)*100+18,METEO_SADM!$A$1:$L$505,8,FALSE),"s/d") | V28: =IFERROR(VLOOKUP(INT($I$6)*100+18,METEO_SADM!$A$1:$L$505,9,FALSE),"s/d")
B29: 19 a 20 | E29: 17 | F29: 44 | H29: =SUM(C29:G29) | K29: 1 | R29: =IFERROR(VLOOKUP(INT($I$6)*100+19,METEO_SADM!$A$1:$L$505,5,FALSE),"s/d") | S29: =IFERROR(VLOOKUP(INT($I$6)*100+19,METEO_SADM!$A$1:$L$505,6,FALSE),"s/d") | T29: =IFERROR(VLOOKUP(INT($I$6)*100+19,METEO_SADM!$A$1:$L$505,7,FALSE),"s/d") | U29: =IFERROR(VLOOKUP(INT($I$6)*100+19,METEO_SADM!$A$1:$L$505,8,FALSE),"s/d") | V29: =IFERROR(VLOOKUP(INT($I$6)*100+19,METEO_SADM!$A$1:$L$505,9,FALSE),"s/d")
B30: 20 a 21 | E30: 16 | F30: 16 | H30: =SUM(C30:G30) | K30: 1 | R30: =IFERROR(VLOOKUP(INT($I$6)*100+20,METEO_SADM!$A$1:$L$505,5,FALSE),"s/d") | S30: =IFERROR(VLOOKUP(INT($I$6)*100+20,METEO_SADM!$A$1:$L$505,6,FALSE),"s/d") | T30: =IFERROR(VLOOKUP(INT($I$6)*100+20,METEO_SADM!$A$1:$L$505,7,FALSE),"s/d") | U30: =IFERROR(VLOOKUP(INT($I$6)*100+20,METEO_SADM!$A$1:$L$505,8,FALSE),"s/d") | V30: =IFERROR(VLOOKUP(INT($I$6)*100+20,METEO_SADM!$A$1:$L$505,9,FALSE),"s/d")
B31: 21 a 22 | E31: 1 | H31: =SUM(C31:G31) | K31: 1 | R31: =IFERROR(VLOOKUP(INT($I$6)*100+21,METEO_SADM!$A$1:$L$505,5,FALSE),"s/d") | S31: =IFERROR(VLOOKUP(INT($I$6)*100+21,METEO_SADM!$A$1:$L$505,6,FALSE),"s/d") | T31: =IFERROR(VLOOKUP(INT($I$6)*100+21,METEO_SADM!$A$1:$L$505,7,FALSE),"s/d") | U31: =IFERROR(VLOOKUP(INT($I$6)*100+21,METEO_SADM!$A$1:$L$505,8,FALSE),"s/d") | V31: =IFERROR(VLOOKUP(INT($I$6)*100+21,METEO_SADM!$A$1:$L$505,9,FALSE),"s/d")
B32: 22 a 23 | H32: =SUM(C32:G32) | R32: =IFERROR(VLOOKUP(INT($I$6)*100+22,METEO_SADM!$A$1:$L$505,5,FALSE),"s/d") | S32: =IFERROR(VLOOKUP(INT($I$6)*100+22,METEO_SADM!$A$1:$L$505,6,FALSE),"s/d") | T32: =IFERROR(VLOOKUP(INT($I$6)*100+22,METEO_SADM!$A$1:$L$505,7,FALSE),"s/d") | U32: =IFERROR(VLOOKUP(INT($I$6)*100+22,METEO_SADM!$A$1:$L$505,8,FALSE),"s/d") | V32: =IFERROR(VLOOKUP(INT($I$6)*100+22,METEO_SADM!$A$1:$L$505,9,FALSE),"s/d")
B33: 23 a 00 | H33: =SUM(C33:G33) | P33: pista | R33: =IFERROR(VLOOKUP(INT($I$6)*100+23,METEO_SADM!$A$1:$L$505,5,FALSE),"s/d") | S33: =IFERROR(VLOOKUP(INT($I$6)*100+23,METEO_SADM!$A$1:$L$505,6,FALSE),"s/d") | T33: =IFERROR(VLOOKUP(INT($I$6)*100+23,METEO_SADM!$A$1:$L$505,7,FALSE),"s/d") | U33: =IFERROR(VLOOKUP(INT($I$6)*100+23,METEO_SADM!$A$1:$L$505,8,FALSE),"s/d") | V33: =IFERROR(VLOOKUP(INT($I$6)*100+23,METEO_SADM!$A$1:$L$505,9,FALSE),"s/d")
B34: TOTAL DIARIO | C34: COMERCIAL | D34: OFICIAL | E34: OTROS | F34: LOCAL | G34: SOBREVUELO | H34: TOTAL MOVIMIENTOS | I34: IFR | J34: PISTA | P34: suma total
J35: =J9 | K35: =K9 | L35: =L9 | M35: =M9 | P35: =SUM(J36:M36)
C36: =SUM(C10:C33) | D36: =SUM(D10:D33) | E36: =SUM(E10:E33) | F36: =SUM(F10:F33) | G36: =SUM(G10:G33) | H36: =SUM(H10:H33) | I36: =SUM(I10:I33) | J36: =SUM(J10:J33) | ... M36: =SUM(M10:M33)
C37: =((C36*100)/$H$36)/100 | D37: =((D36*100)/$H$36)/100 | E37: =((E36*100)/$H$36)/100 | F37: =((F36*100)/$H$36)/100 | G37: =((G36*100)/$H$36)/100 | H37: =((H36*100)/$H$36)/100 | I37: =((I36*100)/$H$36)/100 | J37: =((J36*100)/$P$35)/100 | K37: =((K36*100)/$P$35)/100 | L37: =((L36*100)/$P$35)/100 | M37: =((M36*100)/$P$35)/100
F44: Firma y aclaración del responsable

Sheet 6
B3: MOVIMIENTO DE AERONAVES
B4: ESTADISTICA DIARIA
C6: DEPENDENCIA: | D6: TORRE MORON | H6: FECHA: | I6: 46240
B8: FRANJA HORARIA UTC | C8: COMERCIAL | D8: OFICIAL | E8: OTROS | F8: LOCAL | G8: SOBREVUELO | H8: TOTAL MOVIMIENTOS | I8: IFR | J8: PISTA | R8: CONDICION METEOROLOGICA DEL AERODROMO (SADM)
J9: 2 | K9: 20 | R9: CONDICION | S9: VIS (m) | T9: TECHO (ft) | U9: SPECI | V9: METAR OBSERVADO
B10: 00 a 01 | H10: =SUM(C10:G10) | R10: =IFERROR(VLOOKUP(INT($I$6)*100+0,METEO_SADM!$A$1:$L$505,5,FALSE),"s/d") | S10: =IFERROR(VLOOKUP(INT($I$6)*100+0,METEO_SADM!$A$1:$L$505,6,FALSE),"s/d") | T10: =IFERROR(VLOOKUP(INT($I$6)*100+0,METEO_SADM!$A$1:$L$505,7,FALSE),"s/d") | U10: =IFERROR(VLOOKUP(INT($I$6)*100+0,METEO_SADM!$A$1:$L$505,8,FALSE),"s/d") | V10: =IFERROR(VLOOKUP(INT($I$6)*100+0,METEO_SADM!$A$1:$L$505,9,FALSE),"s/d")
