Workbook

Sheet 1
B3: MOVIMIENTO DE AERONAVES
B4: ESTADISTICA DIARIA
C6: DEPENDENCIA: | D6: TORRE MORON | H6: FECHA: | I6: 46235
B8: FRANJA HORARIA UTC | C8: COMERCIAL | D8: OFICIAL | E8: OTROS | F8: LOCAL | G8: SOBREVUELO | H8: TOTAL MOVIMIENTOS | I8: IFR | J8: PISTA
J9: 2 | K9: 20
B10: 00 a 01 | H10: =SUM(C10:G10) -> 0
B11: 01 a 02 | H11: =SUM(C11:G11) -> 0
B12: 02 a 03 | H12: =SUM(C12:G12) -> 0
B13: 03 a 04 | H13: =SUM(C13:G13) -> 0
B14: 04 a 05 | H14: =SUM(C14:G14) -> 0
B15: 05 a 06 | H15: =SUM(C15:G15) -> 0
B16: 06 a 07 | H16: =SUM(C16:G16) -> 0
B17: 07 a 08 | H17: =SUM(C17:G17) -> 0
B18: 08 a 09 | H18: =SUM(C18:G18) -> 0
B19: 09 a 10 | H19: =SUM(C19:G19) -> 0
B20: 10 a 11 | H20: =SUM(C20:G20) -> 0
B21: 11 a 12 | E21: 2 | H21: =SUM(C21:G21) -> 2 | I21: 1 | K21: 1
B22: 12 a 13 | E22: 7 | H22: =SUM(C22:G22) -> 7 | I22: 1 | K22: 1
B23: 13 a 14 | E23: 15 | F23: 14 | H23: =SUM(C23:G23) -> 29 | K23: 1
B24: 14 a 15 | E24: 2 | G24: 1 | H24: =SUM(C24:G24) -> 3 | K24: 1
B25: 15 a 16 | E25: 20 | F25: 8 | H25: =SUM(C25:G25) -> 28 | K25: 1
B26: 16 a 17 | E26: 19 | F26: 16 | H26: =SUM(C26:G26) -> 35 | K26: 1
B27: 17 a 18 | E27: 26 | F27: 12 | H27: =SUM(C27:G27) -> 38 | K27: 1
B28: 18 a 19 | E28: 27 | F28: 8 | H28: =SUM(C28:G28) -> 35 | K28: 1
B29: 19 a 20 | E29: 25 | H29: =SUM(C29:G29) -> 25 | K29: 1
B30: 20 a 21 | E30: 24 | F30: 10 | H30: =SUM(C30:G30) -> 34 | K30: 1
B31: 21 a 22 | E31: 5 | F31: 6 | H31: =SUM(C31:G31) -> 11 | K31: 1
B32: 22 a 23 | H32: =SUM(C32:G32) -> 0
B33: 23 a 00 | H33: =SUM(C33:G33) -> 0 | P33: pista
B34: TOTAL DIARIO | C34: COMERCIAL | D34: OFICIAL | E34: OTROS | F34: LOCAL | G34: SOBREVUELO | H34: TOTAL MOVIMIENTOS | I34: IFR | J34: PISTA | P34: suma total
J35: =J9 -> 2 | K35: =K9 -> 20 | L35: =L9 -> 0 | M35: =M9 -> 0 | P35: =SUM(J36:M36) -> 11
C36: =SUM(C10:C33) -> 0 | D36: =SUM(D10:D33) -> 0 | E36: =SUM(E10:E33) -> 172 | F36: =SUM(F10:F33) -> 74 | G36: =SUM(G10:G33) -> 1 | H36: =SUM(H10:H33) -> 247 | I36: =SUM(I10:I33) -> 2 | J36: =SUM(J10:J33) -> 0 | ... M36: =SUM(M10:M33) -> 0
C37: =((C36*100)/$H$36)/100 -> 0 | D37: =((D36*100)/$H$36)/100 -> 0 | E37: =((E36*100)/$H$36)/100 -> 0.69635628 | F37: =((F36*100)/$H$36)/100 -> 0.29959514 | G37: =((G36*100)/$H$36)/100 -> 0.004048583 | H37: =((H36*100)/$H$36)/100 -> 1 | I37: =((I36*100)/$H$36)/100 -> 0.008097166 | J37: =((J36*100)/$P$35)/100 -> 0 | K37: =((K36*100)/$P$35)/100 -> 1 | L37: =((L36*100)/$P$35)/100 -> 0 | M37: =((M36*100)/$P$35)/100 -> 0
F44: Firma y aclaración del responsable

Sheet 2
B3: MOVIMIENTO DE AERONAVES
B4: ESTADISTICA DIARIA
C6: DEPENDENCIA: | D6: TORRE MORON | H6: FECHA: | I6: 46236
B8: FRANJA HORARIA UTC | C8: COMERCIAL | D8: OFICIAL | E8: OTROS | F8: LOCAL | G8: SOBREVUELO | H8: TOTAL MOVIMIENTOS | I8: IFR | J8: PISTA
J9: 2 | K9: 20
B10: 00 a 01 | H10: =SUM(C10:G10) -> 0
B11: 01 a 02 | H11: =SUM(C11:G11) -> 0
B12: 02 a 03 | H12: =SUM(C12:G12) -> 0
B13: 03 a 04 | H13: =SUM(C13:G13) -> 0
B14: 04 a 05 | H14: =SUM(C14:G14) -> 0
B15: 05 a 06 | H15: =SUM(C15:G15) -> 0
B16: 06 a 07 | H16: =SUM(C16:G16) -> 0
B17: 07 a 08 | H17: =SUM(C17:G17) -> 0
B18: 08 a 09 | H18: =SUM(C18:G18) -> 0
B19: 09 a 10 | H19: =SUM(C19:G19) -> 0
B20: 10 a 11 | H20: =SUM(C20:G20) -> 0
B21: 11 a 12 | E21: imc | F21: imc | G21: imc | H21: =SUM(C21:G21) -> 0
B22: 12 a 13 | E22: imc | F22: imc | G22: imc | H22: =SUM(C22:G22) -> 0
B23: 13 a 14 | E23: imc | F23: imc | G23: imc | H23: =SUM(C23:G23) -> 0
B24: 14 a 15 | E24: imc | F24: imc | G24: imc | H24: =SUM(C24:G24) -> 0
B25: 15 a 16 | E25: imc | F25: imc | G25: imc | H25: =SUM(C25:G25) -> 0
B26: 16 a 17 | E26: 14 | F26: 16 | H26: =SUM(C26:G26) -> 30 | J26: 1
B27: 17 a 18 | E27: imc | F27: imc | G27: imc | H27: =SUM(C27:G27) -> 0
B28: 18 a 19 | E28: 9 | F28: 4 | H28: =SUM(C28:G28) -> 13 | J28: 1
B29: 19 a 20 | E29: 14 | F29: 18 | H29: =SUM(C29:G29) -> 32 | J29: 1
B30: 20 a 21 | E30: 9 | H30: =SUM(C30:G30) -> 9 | J30: 1
B31: 21 a 22 | E31: 4 | H31: =SUM(C31:G31) -> 4 | J31: 1
B32: 22 a 23 | H32: =SUM(C32:G32) -> 0
B33: 23 a 00 | H33: =SUM(C33:G33) -> 0 | P33: pista
B34: TOTAL DIARIO | C34: COMERCIAL | D34: OFICIAL | E34: OTROS | F34: LOCAL | G34: SOBREVUELO | H34: TOTAL MOVIMIENTOS | I34: IFR | J34: PISTA | P34: suma total
J35: =J9 -> 2 | K35: =K9 -> 20 | L35: =L9 -> 0 | M35: =M9 -> 0 | P35: =SUM(J36:M36) -> 5
C36: =SUM(C10:C33) -> 0 | D36: =SUM(D10:D33) -> 0 | E36: =SUM(E10:E33) -> 50 | F36: =SUM(F10:F33) -> 38 | G36: =SUM(G10:G33) -> 0 | H36: =SUM(H10:H33) -> 88 | I36: =SUM(I10:I33) -> 0 | J36: =SUM(J10:J33) -> 5 | ... M36: =SUM(M10:M33) -> 0
C37: =((C36*100)/$H$36)/100 -> 0 | D37: =((D36*100)/$H$36)/100 -> 0 | E37: =((E36*100)/$H$36)/100 -> 0.56818182 | F37: =((F36*100)/$H$36)/100 -> 0.43181818 | G37: =((G36*100)/$H$36)/100 -> 0 | H37: =((H36*100)/$H$36)/100 -> 1 | I37: =((I36*100)/$H$36)/100 -> 0 | J37: =((J36*100)/$P$35)/100 -> 1 | K37: =((K36*100)/$P$35)/100 -> 0 | L37: =((L36*100)/$P$35)/100 -> 0 | M37: =((M36*100)/$P$35)/100 -> 0
F44: Firma y aclaración del responsable

Sheet 3
B3: MOVIMIENTO DE AERONAVES
B4: ESTADISTICA DIARIA
C6: DEPENDENCIA: | D6: TORRE MORON | H6: FECHA: | I6: 46237
B8: FRANJA HORARIA UTC | C8: COMERCIAL | D8: OFICIAL | E8: OTROS | F8: LOCAL | G8: SOBREVUELO | H8: TOTAL MOVIMIENTOS | I8: IFR | J8: PISTA
J9: 2 | K9: 20
B10: 00 a 01 | H10: =SUM(C10:G10) -> 0
B11: 01 a 02 | H11: =SUM(C11:G11) -> 0
B12: 02 a 03 | H12: =SUM(C12:G12) -> 0
B13: 03 a 04 | H13: =SUM(C13:G13) -> 0
B14: 04 a 05 | H14: =SUM(C14:G14) -> 0
B15: 05 a 06 | H15: =SUM(C15:G15) -> 0
B16: 06 a 07 | H16: =SUM(C16:G16) -> 0
B17: 07 a 08 | H17: =SUM(C17:G17) -> 0
B18: 08 a 09 | H18: =SUM(C18:G18) -> 0
B19: 09 a 10 | H19: =SUM(C19:G19) -> 0
B20: 10 a 11 | H20: =SUM(C20:G20) -> 0
B21: 11 a 12 | E21: IMC | H21: =SUM(C21:G21) -> 0
B22: 12 a 13 | E22: IMC | H22: =SUM(C22:G22) -> 0
B23: 13 a 14 | E23: IMC | H23: =SUM(C23:G23) -> 0
B24: 14 a 15 | E24: IMC | H24: =SUM(C24:G24) -> 0
B25: 15 a 16 | E25: IMC | H25: =SUM(C25:G25) -> 0
B26: 16 a 17 | E26: IMC | H26: =SUM(C26:G26) -> 0
B27: 17 a 18 | E27: 2 | H27: =SUM(C27:G27) -> 2 | K27: 1
B28: 18 a 19 | E28: 6 | F28: 18 | H28: =SUM(C28:G28) -> 24 | K28: 1
B29: 19 a 20 | E29: 6 | F29: 40 | H29: =SUM(C29:G29) -> 46 | K29: 1
B30: 20 a 21 | E30: 3 | F30: 18 | H30: =SUM(C30:G30) -> 21 | K30: 1
B31: 21 a 22 | H31: =SUM(C31:G31) -> 0 | K31: 1
B32: 22 a 23 | H32: =SUM(C32:G32) -> 0
B33: 23 a 00 | H33: =SUM(C33:G33) -> 0 | P33: pista
B34: TOTAL DIARIO | C34: COMERCIAL | D34: OFICIAL | E34: OTROS | F34: LOCAL | G34: SOBREVUELO | H34: TOTAL MOVIMIENTOS | I34: IFR | J34: PISTA | P34: suma total
J35: =J9 -> 2 | K35: =K9 -> 20 | L35: =L9 -> 0 | M35: =M9 -> 0 | P35: =SUM(J36:M36) -> 5
C36: =SUM(C10:C33) -> 0 | D36: =SUM(D10:D33) -> 0 | E36: =SUM(E10:E33) -> 17 | F36: =SUM(F10:F33) -> 76 | G36: =SUM(G10:G33) -> 0 | H36: =SUM(H10:H33) -> 93 | I36: =SUM(I10:I33) -> 0 | J36: =SUM(J10:J33) -> 0 | ... M36: =SUM(M10:M33) -> 0
C37: =((C36*100)/$H$36)/100 -> 0 | D37: =((D36*100)/$H$36)/100 -> 0 | E37: =((E36*100)/$H$36)/100 -> 0.1827957 | F37: =((F36*100)/$H$36)/100 -> 0.8172043 | G37: =((G36*100)/$H$36)/100 -> 0 | H37: =((H36*100)/$H$36)/100 -> 1 | I37: =((I36*100)/$H$36)/100 -> 0 | J37: =((J36*100)/$P$35)/100 -> 0 | K37: =((K36*100)/$P$35)/100 -> 1 | L37: =((L36*100)/$P$35)/100 -> 0 | M37: =((M36*100)/$P$35)/100 -> 0
F44: Firma y aclaración del responsable

Sheet 4
B3: MOVIMIENTO DE AERONAVES
B4: ESTADISTICA DIARIA
C6: DEPENDENCIA: | D6: TORRE MORON | H6: FECHA: | I6: 46238
B8: FRANJA HORARIA UTC | C8: COMERCIAL | D8: OFICIAL | E8: OTROS | F8: LOCAL | G8: SOBREVUELO | H8: TOTAL MOVIMIENTOS | I8: IFR | J8: PISTA
J9: 2 | K9: 20
B10: 00 a 01 | H10: =SUM(C10:G10) -> 0
B11: 01 a 02 | H11: =SUM(C11:G11) -> 0
B12: 02 a 03 | H12: =SUM(C12:G12) -> 0
B13: 03 a 04 | H13: =SUM(C13:G13) -> 0
B14: 04 a 05 | H14: =SUM(C14:G14) -> 0
B15: 05 a 06 | H15: =SUM(C15:G15) -> 0
B16: 06 a 07 | H16: =SUM(C16:G16) -> 0
B17: 07 a 08 | H17: =SUM(C17:G17) -> 0
B18: 08 a 09 | H18: =SUM(C18:G18) -> 0
B19: 09 a 10 | H19: =SUM(C19:G19) -> 0
B20: 10 a 11 | H20: =SUM(C20:G20) -> 0
B21: 11 a 12 | E21: imc | H21: =SUM(C21:G21) -> 0
B22: 12 a 13 | E22: imc | H22: =SUM(C22:G22) -> 0
B23: 13 a 14 | E23: imc | H23: =SUM(C23:G23) -> 0
B24: 14 a 15 | E24: imc | H24: =SUM(C24:G24) -> 0
B25: 15 a 16 | E25: imc | H25: =SUM(C25:G25) -> 0
B26: 16 a 17 | E26: imc | H26: =SUM(C26:G26) -> 0
B27: 17 a 18 | E27: imc | H27: =SUM(C27:G27) -> 0
B28: 18 a 19 | E28: 9 | F28: 4 | H28: =SUM(C28:G28) -> 13 | K28: 1
B29: 19 a 20 | E29: 11 | F29: 22 | G29: 1 | H29: =SUM(C29:G29) -> 34 | K29: 1
B30: 20 a 21 | E30: 8 | F30: 10 | H30: =SUM(C30:G30) -> 18 | J30: 1
B31: 21 a 22 | H31: =SUM(C31:G31) -> 0
B32: 22 a 23 | H32: =SUM(C32:G32) -> 0
B33: 23 a 00 | H33: =SUM(C33:G33) -> 0 | P33: pista
B34: TOTAL DIARIO | C34: COMERCIAL | D34: OFICIAL | E34: OTROS | F34: LOCAL | G34: SOBREVUELO | H34: TOTAL MOVIMIENTOS | I34: IFR | J34: PISTA | P34: suma total
J35: =J9 -> 2 | K35: =K9 -> 20 | L35: =L9 -> 0 | M35: =M9 -> 0 | P35: =SUM(J36:M36) -> 3
C36: =SUM(C10:C33) -> 0 | D36: =SUM(D10:D33) -> 0 | E36: =SUM(E10:E33) -> 28 | F36: =SUM(F10:F33) -> 36 | G36: =SUM(G10:G33) -> 1 | H36: =SUM(H10:H33) -> 65 | I36: =SUM(I10:I33) -> 0 | J36: =SUM(J10:J33) -> 1 | ... M36: =SUM(M10:M33) -> 0
C37: =((C36*100)/$H$36)/100 -> 0 | D37: =((D36*100)/$H$36)/100 -> 0 | E37: =((E36*100)/$H$36)/100 -> 0.43076923 | F37: =((F36*100)/$H$36)/100 -> 0.55384615 | G37: =((G36*100)/$H$36)/100 -> 0.015384615 | H37: =((H36*100)/$H$36)/100 -> 1 | I37: =((I36*100)/$H$36)/100 -> 0 | J37: =((J36*100)/$P$35)/100 -> 0.33333333 | K37: =((K36*100)/$P$35)/100 -> 0.66666667 | L37: =((L36*100)/$P$35)/100 -> 0 | M37: =((M36*100)/$P$35)/100 -> 0
F44: Firma y aclaración del responsable

Sheet 5
B3: MOVIMIENTO DE AERONAVES
B4: ESTADISTICA DIARIA
C6: DEPENDENCIA: | D6: TORRE MORON | H6: FECHA: | I6: 46239
B8: FRANJA HORARIA UTC | C8: COMERCIAL | D8: OFICIAL | E8: OTROS | F8: LOCAL | G8: SOBREVUELO | H8: TOTAL MOVIMIENTOS | I8: IFR | J8: PISTA
J9: 2 | K9: 20
B10: 00 a 01 | H10: =SUM(C10:G10) -> 0
B11: 01 a 02 | H11: =SUM(C11:G11) -> 0
B12: 02 a 03 | H12: =SUM(C12:G12) -> 0
B13: 03 a 04 | H13: =SUM(C13:G13) -> 0
B14: 04 a 05 | H14: =SUM(C14:G14) -> 0
B15: 05 a 06 | H15: =SUM(C15:G15) -> 0
B16: 06 a 07 | H16: =SUM(C16:G16) -> 0
B17: 07 a 08 | H17: =SUM(C17:G17) -> 0
B18: 08 a 09 | H18: =SUM(C18:G18) -> 0
B19: 09 a 10 | H19: =SUM(C19:G19) -> 0
B20: 10 a 11 | H20: =SUM(C20:G20) -> 0
B21: 11 a 12 | H21: =SUM(C21:G21) -> 0
... B25: 15 a 16 | H25: =SUM(C25:G25) -> 0
B26: 16 a 17 | E26: 2 | H26: =SUM(C26:G26) -> 2 | K26: 1
B27: 17 a 18 | E27: 2 | F27: 8 | H27: =SUM(C27:G27) -> 10 | K27: 1
B28: 18 a 19 | E28: 12 | F28: 16 | H28: =SUM(C28:G28) -> 28 | K28: 1
B29: 19 a 20 | E29: 17 | F29: 44 | H29: =SUM(C29:G29) -> 61 | K29: 1
B30: 20 a 21 | E30: 16 | F30: 16 | H30: =SUM(C30:G30) -> 32 | K30: 1
B31: 21 a 22 | E31: 1 | H31: =SUM(C31:G31) -> 1 | K31: 1
B32: 22 a 23 | H32: =SUM(C32:G32) -> 0
B33: 23 a 00 | H33: =SUM(C33:G33) -> 0 | P33: pista
B34: TOTAL DIARIO | C34: COMERCIAL | D34: OFICIAL | E34: OTROS | F34: LOCAL | G34: SOBREVUELO | H34: TOTAL MOVIMIENTOS | I34: IFR | J34: PISTA | P34: suma total
J35: =J9 -> 2 | K35: =K9 -> 20 | L35: =L9 -> 0 | M35: =M9 -> 0 | P35: =SUM(J36:M36) -> 6
C36: =SUM(C10:C33) -> 0 | D36: =SUM(D10:D33) -> 0 | E36: =SUM(E10:E33) -> 50 | F36: =SUM(F10:F33) -> 84 | G36: =SUM(G10:G33) -> 0 | H36: =SUM(H10:H33) -> 134 | I36: =SUM(I10:I33) -> 0 | J36: =SUM(J10:J33) -> 0 | ... M36: =SUM(M10:M33) -> 0
C37: =((C36*100)/$H$36)/100 -> 0 | D37: =((D36*100)/$H$36)/100 -> 0 | E37: =((E36*100)/$H$36)/100 -> 0.37313433 | F37: =((F36*100)/$H$36)/100 -> 0.62686567 | G37: =((G36*100)/$H$36)/100 -> 0 | H37: =((H36*100)/$H$36)/100 -> 1 | I37: =((I36*100)/$H$36)/100 -> 0 | J37: =((J36*100)/$P$35)/100 -> 0 | K37: =((K36*100)/$P$35)/100 -> 1 | L37: =((L36*100)/$P$35)/100 -> 0 | M37: =((M36*100)/$P$35)/100 -> 0
F44: Firma y aclaración del responsable

Sheet 6
B3: MOVIMIENTO DE AERONAVES
B4: ESTADISTICA DIARIA
C6: DEPENDENCIA: | D6: TORRE MORON | H6: FECHA: | I6: 46240
B8: FRANJA HORARIA UTC | C8: COMERCIAL | D8: OFICIAL | E8: OTROS | F8: LOCAL | G8: SOBREVUELO | H8: TOTAL MOVIMIENTOS | I8: IFR | J8: PISTA
J9: 2 | K9: 20
B10: 00 a 01 | H10: =SUM(C10:G10) -> 0
B11: 01 a 02 | H11: =SUM(C11:G11) -> 0
B12: 02 a 03 | H12: =SUM(C12:G12) -> 0
B13: 03 a 04 | H13: =SUM(C13:G13) -> 0
B14: 04 a 05 | H14: =SUM(C14:G14) -> 0
B15: 05 a 06 | H15: =SUM(C15:G15) -> 0
B16: 06 a 07 | H16: =SUM(C16:G16) -> 0
B17: 07 a 08 | H17: =SUM(C17:G17) -> 0
B18: 08 a 09 | H18: =SUM(C18:G18) -> 0
B19: 09 a 10 | H19: =SUM(C19:G19) -> 0
B20: 10 a 11 | H20: =SUM(C20:G20) -> 0
B21: 11 a 12 | E21: IMC | H21: =SUM(C21:G21) -> 0
B22: 12 a 13 | E22: IMC | H22: =SUM(C22:G22) -> 0
B23: 13 a 14 | E23: IMC | H23: =SUM(C23:G23) -> 0
B24: 14 a 15 | E24: IMC | H24: =SUM(C24:G24) -> 0
B25: 15 a 16 | E25: IMC | H25: =SUM(C25:G25) -> 0
B26: 16 a 17 | E26: IMC | H26: =SUM(C26:G26) -> 0
B27: 17 a 18 | E27: IMC | H27: =SUM(C27:G27) -> 0
B28: 18 a 19 | E28: IMC | H28: =SUM(C28:G28) -> 0
B29: 19 a 20 | E29: 1 | H29: =SUM(C29:G29) -> 1 | K29: 1
B30: 20 a 21 | E30: 1 | H30: =SUM(C30:G30) -> 1 | K30: 1
B31: 21 a 22 | E31: IMC | H31: =SUM(C31:G31) -> 0
B32: 22 a 23 | H32: =SUM(C32:G32) -> 0
B33: 23 a 00 | H33: =SUM(C33:G33) -> 0 | P33: pista
B34: TOTAL DIARIO | C34: COMERCIAL | D34: OFICIAL | E34: OTROS | F34: LOCAL | G34: SOBREVUELO | H34: TOTAL MOVIMIENTOS | I34: IFR | J34: PISTA | P34: suma total
J35: =J9 -> 2 | K35: =K9 -> 20 | L35: =L9 -> 0 | M35: =M9 -> 0 | P35: =SUM(J36:M36) -> 2
C36: =SUM(C10:C33) -> 0 | D36: =SUM(D10:D33) -> 0 | E36: =SUM(E10:E33) -> 2 | F36: =SUM(F10:F33) -> 0 | G36: =SUM(G10:G33) -> 0 | H36: =SUM(H10:H33) -> 2 | I36: =SUM(I10:I33) -> 0 | J36: =SUM(J10:J33) -> 0 | ... M36: =SUM(M10:M33) -> 0
C37: =((C36*100)/$H$36)/100 -> 0 | D37: =((D36*100)/$H$36)/100 -> 0 | E37: =((E36*100)/$H$36)/100 -> 1 | F37: =((F36*100)/$H$36)/100 -> 0 | G37: =((G36*100)/$H$36)/100 -> 0 | H37: =((H36*100)/$H$36)/100 -> 1 | I37: =((I36*100)/$H$36)/100 -> 0 | J37: =((J36*100)/$P$35)/100 -> 0 | K37: =((K36*100)/$P$35)/100 -> 1 | L37: =((L36*100)/$P$35)/100 -> 0 | M37: =((M36*100)/$P$35)/100 -> 0
F44: Firma y aclaración del responsable

Sheet 7
B3: MOVIMIENTO DE AERONAVES
B4: ESTADISTICA DIARIA
C6: DEPENDENCIA: | D6: TORRE MORON | H6: FECHA: | I6: 46241
B8: FRANJA HORARIA UTC | C8: COMERCIAL | D8: OFICIAL | E8: OTROS | F8: LOCAL | G8: SOBREVUELO | H8: TOTAL MOVIMIENTOS | I8: IFR | J8: PISTA
J9: 2 | K9: 20
B10: 00 a 01 | H10: =SUM(C10:G10) -> 0
B11: 01 a 02 | H11: =SUM(C11:G11) -> 0
B12: 02 a 03 | H12: =SUM(C12:G12) -> 0
B13: 03 a 04 | H13: =SUM(C13:G13) -> 0
B14: 04 a 05 | H14: =SUM(C14:G14) -> 0
B15: 05 a 06 | H15: =SUM(C15:G15) -> 0
B16: 06 a 07 | H16: =SUM(C16:G16) -> 0
B17: 07 a 08 | H17: =SUM(C17:G17) -> 0
B18: 08 a 09 | H18: =SUM(C18:G18) -> 0
B19: 09 a 10 | H19: =SUM(C19:G19) -> 0
B20: 10 a 11 | H20: =SUM(C20:G20) -> 0
B21: 11 a 12 | H21: =SUM(C21:G21) -> 0 | K21: 1
B22: 12 a 13 | E22: 9 | H22: =SUM(C22:G22) -> 9 | K22: 1
B23: 13 a 14 | E23: 10 | H23: =SUM(C23:G23) -> 10 | I23: 1 | K23: 1
B24: 14 a 15 | E24: 9 | F24: 6 | G24: 1 | H24: =SUM(C24:G24) -> 16 | K24: 1
B25: 15 a 16 | E25: 10 | H25: =SUM(C25:G25) -> 10 | K25: 1
B26: 16 a 17 | E26: 15 | G26: 1 | H26: =SUM(C26:G26) -> 16 | K26: 1
B27: 17 a 18 | E27: 5 | F27: 4 | G27: 1 | H27: =SUM(C27:G27) -> 10
B28: 18 a 19 | E28: 2 | H28: =SUM(C28:G28) -> 2 | J28: 1
B29: 19 a 20 | E29: 1 | H29: =SUM(C29:G29) -> 1 | J29: 1
B30: 20 a 21 | E30: 16 | F30: 4 | H30: =SUM(C30:G30) -> 20 | J30: 1
B31: 21 a 22 | E31: 8 | H31: =SUM(C31:G31) -> 8 | J31: 1
B32: 22 a 23 | H32: =SUM(C32:G32) -> 0
B33: 23 a 00 | H33: =SUM(C33:G33) -> 0 | P33: pista
B34: TOTAL DIARIO | C34: COMERCIAL | D34: OFICIAL | E34: OTROS | F34: LOCAL | G34: SOBREVUELO | H34: TOTAL MOVIMIENTOS | I34: IFR | J34: PISTA | P34: suma total
J35: =J9 -> 2 | K35: =K9 -> 20 | L35: =L9 -> 0 | M35: =M9 -> 0 | P35: =SUM(J36:M36) -> 10
C36: =SUM(C10:C33) -> 0 | D36: =SUM(D10:D33) -> 0 | E36: =SUM(E10:E33) -> 85 | F36: =SUM(F10:F33) -> 14 | G36: =SUM(G10:G33) -> 3 | H36: =SUM(H10:H33) -> 102 | I36: =SUM(I10:I33) -> 1 | J36: =SUM(J10:J33) -> 4 | ... M36: =SUM(M10:M33) -> 0
C37: =((C36*100)/$H$36)/100 -> 0 | D37: =((D36*100)/$H$36)/100 -> 0 | E37: =((E36*100)/$H$36)/100 -> 0.83333333 | F37: =((F36*100)/$H$36)/100 -> 0.1372549 | G37: =((G36*100)/$H$36)/100 -> 0.029411765 | H37: =((H36*100)/$H$36)/100 -> 1 | I37: =((I36*100)/$H$36)/100 -> 0.0098039216 | J37: =((J36*100)/$P$35)/100 -> 0.4 | K37: =((K36*100)/$P$35)/100 -> 0.6 | L37: =((L36*100)/$P$35)/100 -> 0 | M37: =((M36*100)/$P$35)/100 -> 0
F44: Firma y aclaración del responsable

Sheet 8
B3: MOVIMIENTO DE AERONAVES
B4: ESTADISTICA DIARIA
C6: DEPENDENCIA: | D6: TORRE MORON | H6: FECHA: | I6: 46242
B8: FRANJA HORARIA UTC | C8: COMERCIAL | D8: OFICIAL | E8: OTROS | F8: LOCAL | G8: SOBREVUELO | H8: TOTAL MOVIMIENTOS | I8: IFR | J8: PISTA
J9: 2 | K9: 20
B10: 00 a 01 | H10: =SUM(C10:G10) -> 0
B11: 01 a 02 | H11: =SUM(C11:G11) -> 0
B12: 02 a 03 | H12: =SUM(C12:G12) -> 0
B13: 03 a 04 | H13: =SUM(C13:G13) -> 0
B14: 04 a 05 | H14: =SUM(C14:G14) -> 0
B15: 05 a 06 | H15: =SUM(C15:G15) -> 0
B16: 06 a 07 | H16: =SUM(C16:G16) -> 0
B17: 07 a 08 | H17: =SUM(C17:G17) -> 0
B18: 08 a 09 | H18: =SUM(C18:G18) -> 0
B19: 09 a 10 | H19: =SUM(C19:G19) -> 0
B20: 10 a 11 | H20: =SUM(C20:G20) -> 0
B21: 11 a 12 | H21: =SUM(C21:G21) -> 0
B22: 12 a 13 | H22: =SUM(C22:G22) -> 0 | J22: 1
B23: 13 a 14 | E23: 1 | G23: 9 | H23: =SUM(C23:G23) -> 10 | J23: 1
B24: 14 a 15 | E24: 1 | H24: =SUM(C24:G24) -> 1 | J24: 1
B25: 15 a 16 | E25: 4 | H25: =SUM(C25:G25) -> 4 | J25: 1
B26: 16 a 17 | E26: 7 | H26: =SUM(C26:G26) -> 7 | J26: 1
B27: 17 a 18 | E27: 4 | H27: =SUM(C27:G27) -> 4 | J27: 1
B28: 18 a 19 | E28: 8 | F28: 8 | H28: =SUM(C28:G28) -> 16 | J28: 1
B29: 19 a 20 | E29: 15 | H29: =SUM(C29:G29) -> 15 | J29: 1
B30: 20 a 21 | E30: 11 | F30: 4 | H30: =SUM(C30:G30) -> 15 | J30: 1
B31: 21 a 22 | E31: 5 | H31: =SUM(C31:G31) -> 5 | J31: 1
B32: 22 a 23 | H32: =SUM(C32:G32) -> 0
B33: 23 a 00 | H33: =SUM(C33:G33) -> 0 | P33: pista
B34: TOTAL DIARIO | C34: COMERCIAL | D34: OFICIAL | E34: OTROS | F34: LOCAL | G34: SOBREVUELO | H34: TOTAL MOVIMIENTOS | I34: IFR | J34: PISTA | P34: suma total
J35: =J9 -> 2 | K35: =K9 -> 20 | L35: =L9 -> 0 | M35: =M9 -> 0 | P35: =SUM(J36:M36) -> 10
C36: =SUM(C10:C33) -> 0 | D36: =SUM(D10:D33) -> 0 | E36: =SUM(E10:E33) -> 56 | F36: =SUM(F10:F33) -> 12 | G36: =SUM(G10:G33) -> 9 | H36: =SUM(H10:H33) -> 77 | I36: =SUM(I10:I33) -> 0 | J36: =SUM(J10:J33) -> 10 | ... M36: =SUM(M10:M33) -> 0
C37: =((C36*100)/$H$36)/100 -> 0 | D37: =((D36*100)/$H$36)/100 -> 0 | E37: =((E36*100)/$H$36)/100 -> 0.72727273 | F37: =((F36*100)/$H$36)/100 -> 0.15584416 | G37: =((G36*100)/$H$36)/100 -> 0.11688312 | H37: =((H36*100)/$H$36)/100 -> 1 | I37: =((I36*100)/$H$36)/100 -> 0 | J37: =((J36*100)/$P$35)/100 -> 1 | K37: =((K36*100)/$P$35)/100 -> 0 | L37: =((L36*100)/$P$35)/100 -> 0 | M37: =((M36*100)/$P$35)/100 -> 0
F44: Firma y aclaración del responsable

Sheet 9
B3: MOVIMIENTO DE AERONAVES
B4: ESTADISTICA DIARIA
C6: DEPENDENCIA: | D6: TORRE MORON | H6: FECHA: | I6: 46243
B8: FRANJA HORARIA UTC | C8: COMERCIAL | D8: OFICIAL | E8: OTROS | F8: LOCAL | G8: SOBREVUELO | H8: TOTAL MOVIMIENTOS | I8: IFR | J8: PISTA
J9: 2 | K9: 20
B10: 00 a 01 | H10: =SUM(C10:G10) -> 0
B11: 01 a 02 | H11: =SUM(C11:G11) -> 0
B12: 02 a 03 | H12: =SUM(C12:G12) -> 0
B13: 03 a 04 | H13: =SUM(C13:G13) -> 0
B14: 04 a 05 | H14: =SUM(C14:G14) -> 0
B15: 05 a 06 | H15: =SUM(C15:G15) -> 0
B16: 06 a 07 | H16: =SUM(C16:G16) -> 0
B17: 07 a 08 | H17: =SUM(C17:G17) -> 0
B18: 08 a 09 | H18: =SUM(C18:G18) -> 0
B19: 09 a 10 | H19: =SUM(C19:G19) -> 0
B20: 10 a 11 | H20: =SUM(C20:G20) -> 0
B21: 11 a 12 | E21: 7 | H21: =SUM(C21:G21) -> 7 | I21: 1 | K21: 1
B22: 12 a 13 | E22: 6 | H22: =SUM(C22:G22) -> 6 | I22: 1 | K22: 1
B23: 13 a 14 | E23: 9 | H23: =SUM(C23:G23) -> 9 | I23: 1 | K23: 1
B24: 14 a 15 | E24: 5 | F24: 2 | H24: =SUM(C24:G24) -> 7 | K24: 1
B25: 15 a 16 | E25: 9 | F25: 10 | G25: 1 | H25: =SUM(C25:G25) -> 20 | K25: 1
B26: 16 a 17 | E26: 10 | F26: 10 | H26: =SUM(C26:G26) -> 20 | K26: 1
B27: 17 a 18 | E27: 8 | F27: 16 | H27: =SUM(C27:G27) -> 24 | K27: 1
B28: 18 a 19 | E28: 14 | H28: =SUM(C28:G28) -> 14 | K28: 1
B29: 19 a 20 | E29: 16 | F29: 2 | H29: =SUM(C29:G29) -> 18 | K29: 1
B30: 20 a 21 | E30: 15 | F30: 14 | H30: =SUM(C30:G30) -> 29 | K30: 1
B31: 21 a 22 | E31: 5 | H31: =SUM(C31:G31) -> 5
B32: 22 a 23 | H32: =SUM(C32:G32) -> 0
B33: 23 a 00 | H33: =SUM(C33:G33) -> 0 | P33: pista
B34: TOTAL DIARIO | C34: COMERCIAL | D34: OFICIAL | E34: OTROS | F34: LOCAL | G34: SOBREVUELO | H34: TOTAL MOVIMIENTOS | I34: IFR | J34: PISTA | P34: suma total
J35: =J9 -> 2 | K35: =K9 -> 20 | L35: =L9 -> 0 | M35: =M9 -> 0 | P35: =SUM(J36:M36) -> 10
C36: =SUM(C10:C33) -> 0 | D36: =SUM(D10:D33) -> 0 | E36: =SUM(E10:E33) -> 104 | F36: =SUM(F10:F33) -> 54 | G36: =SUM(G10:G33) -> 1 | H36: =SUM(H10:H33) -> 159 | I36: =SUM(I10:I33) -> 3 | J36: =SUM(J10:J33) -> 0 | ... M36: =SUM(M10:M33) -> 0
C37: =((C36*100)/$H$36)/100 -> 0 | D37: =((D36*100)/$H$36)/100 -> 0 | E37: =((E36*100)/$H$36)/100 -> 0.65408805 | F37: =((F36*100)/$H$36)/100 -> 0.33962264 | G37: =((G36*100)/$H$36)/100 -> 0.0062893082 | H37: =((H36*100)/$H$36)/100 -> 1 | I37: =((I36*100)/$H$36)/100 -> 0.018867925 | J37: =((J36*100)/$P$35)/100 -> 0 | K37: =((K36*100)/$P$35)/100 -> 1 | L37: =((L36*100)/$P$35)/100 -> 0 | M37: =((M36*100)/$P$35)/100 -> 0
F44: Firma y aclaración del responsable

Sheet 10
B3: MOVIMIENTO DE AERONAVES
B4: ESTADISTICA DIARIA
C6: DEPENDENCIA: | D6: TORRE MORON | H6: FECHA: | I6: 46244
B8: FRANJA HORARIA UTC | C8: COMERCIAL | D8: OFICIAL | E8: OTROS | F8: LOCAL | G8: SOBREVUELO | H8: TOTAL MOVIMIENTOS | I8: IFR | J8: PISTA
J9: 2 | K9: 20
B10: 00 a 01 | H10: =SUM(C10:G10) -> 0
B11: 01 a 02 | H11: =SUM(C11:G11) -> 0
B12: 02 a 03 | H12: =SUM(C12:G12) -> 0
B13: 03 a 04 | H13: =SUM(C13:G13) -> 0
B14: 04 a 05 | H14: =SUM(C14:G14) -> 0
B15: 05 a 06 | H15: =SUM(C15:G15) -> 0
B16: 06 a 07 | H16: =SUM(C16:G16) -> 0
B17: 07 a 08 | H17: =SUM(C17:G17) -> 0
B18: 08 a 09 | H18: =SUM(C18:G18) -> 0
B19: 09 a 10 | H19: =SUM(C19:G19) -> 0
B20: 10 a 11 | H20: =SUM(C20:G20) -> 0
B21: 11 a 12 | E21: 0 | H21: =SUM(C21:G21) -> 0 | K21: 1
B22: 12 a 13 | E22: 0 | H22: =SUM(C22:G22) -> 0 | K22: 1
B23: 13 a 14 | E23: 1 | H23: =SUM(C23:G23) -> 1 | K23: 1
B24: 14 a 15 | E24: 1 | H24: =SUM(C24:G24) -> 1 | K24: 1
B25: 15 a 16 | E25: 2 | H25: =SUM(C25:G25) -> 2 | I25: 1 | K25: 1
B26: 16 a 17 | E26: 3 | F26: 8 | H26: =SUM(C26:G26) -> 11 | K26: 1
B27: 17 a 18 | E27: 13 | H27: =SUM(C27:G27) -> 13 | K27: 1
B28: 18 a 19 | E28: 21 | F28: 6 | H28: =SUM(C28:G28) -> 27 | K28: 1
B29: 19 a 20 | E29: 30 | F29: 22 | H29: =SUM(C29:G29) -> 52 | K29: 1
B30: 20 a 21 | E30: 26 | F30: 6 | H30: =SUM(C30:G30) -> 32 | K30: 1
B31: 21 a 22 | E31: 9 | H31: =SUM(C31:G31) -> 9 | K31: 1
B32: 22 a 23 | H32: =SUM(C32:G32) -> 0
B33: 23 a 00 | H33: =SUM(C33:G33) -> 0 | P33: pista
B34: TOTAL DIARIO | C34: COMERCIAL | D34: OFICIAL | E34: OTROS | F34: LOCAL | G34: SOBREVUELO | H34: TOTAL MOVIMIENTOS | I34: IFR | J34: PISTA | P34: suma total
J35: =J9 -> 2 | K35: =K9 -> 20 | L35: =L9 -> 0 | M35: =M9 -> 0 | P35: =SUM(J36:M36) -> 11
C36: =SUM(C10:C33) -> 0 | D36: =SUM(D10:D33) -> 0 | E36: =SUM(E10:E33) -> 106 | F36: =SUM(F10:F33) -> 42 | G36: =SUM(G10:G33) -> 0 | H36: =SUM(H10:H33) -> 148 | I36: =SUM(I10:I33) -> 1 | J36: =SUM(J10:J33) -> 0 | ... M36: =SUM(M10:M33) -> 0
C37: =((C36*100)/$H$36)/100 -> 0 | D37: =((D36*100)/$H$36)/100 -> 0 | E37: =((E36*100)/$H$36)/100 -> 0.71621622 | F37: =((F36*100)/$H$36)/100 -> 0.28378378 | G37: =((G36*100)/$H$36)/100 -> 0 | H37: =((H36*100)/$H$36)/100 -> 1 | I37: =((I36*100)/$H$36)/100 -> 0.0067567568 | J37: =((J36*100)/$P$35)/100 -> 0 | K37: =((K36*100)/$P$35)/100 -> 1 | L37: =((L36*100)/$P$35)/100 -> 0 | M37: =((M36*100)/$P$35)/100 -> 0
F44: Firma y aclaración del responsable

Sheet 11
B3: MOVIMIENTO DE AERONAVES
B4: ESTADISTICA DIARIA
C6: DEPENDENCIA: | D6: TORRE MORON | H6: FECHA: | I6: 46245
B8: FRANJA HORARIA UTC | C8: COMERCIAL | D8: OFICIAL | E8: OTROS | F8: LOCAL | G8: SOBREVUELO | H8: TOTAL MOVIMIENTOS | I8: IFR | J8: PISTA
J9: 2 | K9: 20
B10: 00 a 01 | H10: =SUM(C10:G10) -> 0
B11: 01 a 02 | H11: =SUM(C11:G11) -> 0
B12: 02 a 03 | H12: =SUM(C12:G12) -> 0
B13: 03 a 04 | H13: =SUM(C13:G13) -> 0
B14: 04 a 05 | H14: =SUM(C14:G14) -> 0
B15: 05 a 06 | H15: =SUM(C15:G15) -> 0
B16: 06 a 07 | H16: =SUM(C16:G16) -> 0
B17: 07 a 08 | H17: =SUM(C17:G17) -> 0
B18: 08 a 09 | H18: =SUM(C18:G18) -> 0
B19: 09 a 10 | H19: =SUM(C19:G19) -> 0
B20: 10 a 11 | H20: =SUM(C20:G20) -> 0
B21: 11 a 12 | E21: 6 | H21: =SUM(C21:G21) -> 6 | K21: 1
B22: 12 a 13 | E22: 20 | H22: =SUM(C22:G22) -> 20 | K22: 1
B23: 13 a 14 | E23: 24 | F23: 14 | H23: =SUM(C23:G23) -> 38 | K23: 1
B24: 14 a 15 | E24: 32 | F24: 4 | G24: 1 | H24: =SUM(C24:G24) -> 37 | K24: 1
B25: 15 a 16 | E25: 24 | F25: 6 | H25: =SUM(C25:G25) -> 30 | I25: 1 | K25: 1
B26: 16 a 17 | E26: 26 | F26: 4 | H26: =SUM(C26:G26) -> 30 | K26: 1
B27: 17 a 18 | E27: 29 | F27: 10 | H27: =SUM(C27:G27) -> 39 | J27: 1 | K27: 1
B28: 18 a 19 | E28: 29 | F28: 14 | H28: =SUM(C28:G28) -> 43 | J28: 1
B29: 19 a 20 | E29: 25 | F29: 2 | H29: =SUM(C29:G29) -> 27 | J29: 1
B30: 20 a 21 | E30: 35 | F30: 4 | H30: =SUM(C30:G30) -> 39 | J30: 1
B31: 21 a 22 | E31: 12 | F31: 2 | H31: =SUM(C31:G31) -> 14 | J31: 1
B32: 22 a 23 | H32: =SUM(C32:G32) -> 0
B33: 23 a 00 | H33: =SUM(C33:G33) -> 0 | P33: pista
B34: TOTAL DIARIO | C34: COMERCIAL | D34: OFICIAL | E34: OTROS | F34: LOCAL | G34: SOBREVUELO | H34: TOTAL MOVIMIENTOS | I34: IFR | J34: PISTA | P34: suma total
J35: =J9 -> 2 | K35: =K9 -> 20 | L35: =L9 -> 0 | M35: =M9 -> 0 | P35: =SUM(J36:M36) -> 12
C36: =SUM(C10:C33) -> 0 | D36: =SUM(D10:D33) -> 0 | E36: =SUM(E10:E33) -> 262 | F36: =SUM(F10:F33) -> 60 | G36: =SUM(G10:G33) -> 1 | H36: =SUM(H10:H33) -> 323 | I36: =SUM(I10:I33) -> 1 | J36: =SUM(J10:J33) -> 5 | ... M36: =SUM(M10:M33) -> 0
C37: =((C36*100)/$H$36)/100 -> 0 | D37: =((D36*100)/$H$36)/100 -> 0 | E37: =((E36*100)/$H$36)/100 -> 0.81114551 | F37: =((F36*100)/$H$36)/100 -> 0.18575851 | G37: =((G36*100)/$H$36)/100 -> 0.0030959752 | H37: =((H36*100)/$H$36)/100 -> 1 | I37: =((I36*100)/$H$36)/100 -> 0.0030959752 | J37: =((J36*100)/$P$35)/100 -> 0.41666667 | K37: =((K36*100)/$P$35)/100 -> 0.58333333 | L37: =((L36*100)/$P$35)/100 -> 0 | M37: =((M36*100)/$P$35)/100 -> 0
F44: Firma y aclaración del responsable

Sheet 12
B3: MOVIMIENTO DE AERONAVES
B4: ESTADISTICA DIARIA
C6: DEPENDENCIA: | D6: TORRE MORON | H6: FECHA: | I6: 46246
B8: FRANJA HORARIA UTC | C8: COMERCIAL | D8: OFICIAL | E8: OTROS | F8: LOCAL | G8: SOBREVUELO | H8: TOTAL MOVIMIENTOS | I8: IFR | J8: PISTA
J9: 2 | K9: 20
B10: 00 a 01 | H10: =SUM(C10:G10) -> 0
B11: 01 a 02 | H11: =SUM(C11:G11) -> 0
B12: 02 a 03 | H12: =SUM(C12:G12) -> 0
B13: 03 a 04 | H13: =SUM(C13:G13) -> 0
B14: 04 a 05 | H14: =SUM(C14:G14) -> 0
B15: 05 a 06 | H15: =SUM(C15:G15) -> 0
B16: 06 a 07 | H16: =SUM(C16:G16) -> 0
B17: 07 a 08 | H17: =SUM(C17:G17) -> 0
B18: 08 a 09 | H18: =SUM(C18:G18) -> 0
B19: 09 a 10 | H19: =SUM(C19:G19) -> 0
B20: 10 a 11 | H20: =SUM(C20:G20) -> 0
B21: 11 a 12 | E21: 4 | H21: =SUM(C21:G21) -> 4 | K21: 1
B22: 12 a 13 | E22: 12 | F22: 18 | G22: 1 | H22: =SUM(C22:G22) -> 31 | K22: 1
B23: 13 a 14 | E23: 15 | H23: =SUM(C23:G23) -> 15 | K23: 1
B24: 14 a 15 | E24: 18 | F24: 18 | G24: 1 | H24: =SUM(C24:G24) -> 37 | K24: 1
B25: 15 a 16 | E25: 21 | F25: 2 | H25: =SUM(C25:G25) -> 23 | K25: 1
B26: 16 a 17 | E26: 19 | F26: 16 | H26: =SUM(C26:G26) -> 35 | K26: 1
B27: 17 a 18 | E27: 18 | F27: 28 | H27: =SUM(C27:G27) -> 46 | K27: 1
B28: 18 a 19 | E28: 18 | F28: 14 | H28: =SUM(C28:G28) -> 32 | K28: 1
B29: 19 a 20 | E29: 25 | F29: 26 | H29: =SUM(C29:G29) -> 51 | K29: 1
B30: 20 a 21 | E30: 13 | F30: 18 | H30: =SUM(C30:G30) -> 31 | K30: 1
B31: 21 a 22 | E31: 7 | F31: 16 | H31: =SUM(C31:G31) -> 23 | K31: 1
B32: 22 a 23 | H32: =SUM(C32:G32) -> 0
B33: 23 a 00 | H33: =SUM(C33:G33) -> 0 | P33: pista
B34: TOTAL DIARIO | C34: COMERCIAL | D34: OFICIAL | E34: OTROS | F34: LOCAL | G34: SOBREVUELO | H34: TOTAL MOVIMIENTOS | I34: IFR | J34: PISTA | P34: suma total
J35: =J9 -> 2 | K35: =K9 -> 20 | L35: =L9 -> 0 | M35: =M9 -> 0 | P35: =SUM(J36:M36) -> 11
C36: =SUM(C10:C33) -> 0 | D36: =SUM(D10:D33) -> 0 | E36: =SUM(E10:E33) -> 170 | F36: =SUM(F10:F33) -> 156 | G36: =SUM(G10:G33) -> 2 | H36: =SUM(H10:H33) -> 328 | I36: =SUM(I10:I33) -> 0 | J36: =SUM(J10:J33) -> 0 | ... M36: =SUM(M10:M33) -> 0
C37: =((C36*100)/$H$36)/100 -> 0 | D37: =((D36*100)/$H$36)/100 -> 0 | E37: =((E36*100)/$H$36)/100 -> 0.51829268 | F37: =((F36*100)/$H$36)/100 -> 0.47560976 | G37: =((G36*100)/$H$36)/100 -> 0.006097561 | H37: =((H36*100)/$H$36)/100 -> 1 | I37: =((I36*100)/$H$36)/100 -> 0 | J37: =((J36*100)/$P$35)/100 -> 0 | K37: =((K36*100)/$P$35)/100 -> 1 | L37: =((L36*100)/$P$35)/100 -> 0 | M37: =((M36*100)/$P$35)/100 -> 0
F44: Firma y aclaración del responsable

Sheet 13
B3: MOVIMIENTO DE AERONAVES
B4: ESTADISTICA DIARIA
C6: DEPENDENCIA: | D6: TORRE MORON | H6: FECHA: | I6: 46247
B8: FRANJA HORARIA UTC | C8: COMERCIAL | D8: OFICIAL | E8: OTROS | F8: LOCAL | G8: SOBREVUELO | H8: TOTAL MOVIMIENTOS | I8: IFR | J8: PISTA
J9: 2 | K9: 20
B10: 00 a 01 | H10: =SUM(C10:G10) -> 0
B11: 01 a 02 | H11: =SUM(C11:G11) -> 0
B12: 02 a 03 | H12: =SUM(C12:G12) -> 0
B13: 03 a 04 | H13: =SUM(C13:G13) -> 0
B14: 04 a 05 | H14: =SUM(C14:G14) -> 0
B15: 05 a 06 | H15: =SUM(C15:G15) -> 0
B16: 06 a 07 | H16: =SUM(C16:G16) -> 0
B17: 07 a 08 | H17: =SUM(C17:G17) -> 0
B18: 08 a 09 | H18: =SUM(C18:G18) -> 0
B19: 09 a 10 | H19: =SUM(C19:G19) -> 0
B20: 10 a 11 | H20: =SUM(C20:G20) -> 0
B21: 11 a 12 | E21: 4 | H21: =SUM(C21:G21) -> 4 | K21: 1
B22: 12 a 13 | E22: 8 | F22: 4 | H22: =SUM(C22:G22) -> 12 | K22: 1
B23: 13 a 14 | E23: 12 | F23: 1 | H23: =SUM(C23:G23) -> 13 | K23: 1
B24: 14 a 15 | E24: 15 | H24: =SUM(C24:G24) -> 15 | K24: 1
B25: 15 a 16 | E25: 21 | F25: 28 | H25: =SUM(C25:G25) -> 49 | K25: 1
B26: 16 a 17 | E26: 17 | F26: 2 | H26: =SUM(C26:G26) -> 19 | K26: 1
B27: 17 a 18 | E27: 22 | F27: 4 | H27: =SUM(C27:G27) -> 26 | K27: 1
B28: 18 a 19 | E28: 20 | F28: 4 | H28: =SUM(C28:G28) -> 24 | K28: 1
B29: 19 a 20 | E29: 24 | H29: =SUM(C29:G29) -> 24 | K29: 1
B30: 20 a 21 | E30: 17 | F30: 2 | H30: =SUM(C30:G30) -> 19 | K30: 1
B31: 21 a 22 | E31: 2 | F31: 2 | H31: =SUM(C31:G31) -> 4 | K31: 1
B32: 22 a 23 | H32: =SUM(C32:G32) -> 0
B33: 23 a 00 | H33: =SUM(C33:G33) -> 0 | P33: pista
B34: TOTAL DIARIO | C34: COMERCIAL | D34: OFICIAL | E34: OTROS | F34: LOCAL | G34: SOBREVUELO | H34: TOTAL MOVIMIENTOS | I34: IFR | J34: PISTA | P34: suma total
J35: =J9 -> 2 | K35: =K9 -> 20 | L35: =L9 -> 0 | M35: =M9 -> 0 | P35: =SUM(J36:M36) -> 11
C36: =SUM(C10:C33) -> 0 | D36: =SUM(D10:D33) -> 0 | E36: =SUM(E10:E33) -> 162 | F36: =SUM(F10:F33) -> 47 | G36: =SUM(G10:G33) -> 0 | H36: =SUM(H10:H33) -> 209 | I36: =SUM(I10:I33) -> 0 | J36: =SUM(J10:J33) -> 0 | ... M36: =SUM(M10:M33) -> 0
C37: =((C36*100)/$H$36)/100 -> 0 | D37: =((D36*100)/$H$36)/100 -> 0 | E37: =((E36*100)/$H$36)/100 -> 0.77511962 | F37: =((F36*100)/$H$36)/100 -> 0.22488038 | G37: =((G36*100)/$H$36)/100 -> 0 | H37: =((H36*100)/$H$36)/100 -> 1 | I37: =((I36*100)/$H$36)/100 -> 0 | J37: =((J36*100)/$P$35)/100 -> 0 | K37: =((K36*100)/$P$35)/100 -> 1 | L37: =((L36*100)/$P$35)/100 -> 0 | M37: =((M36*100)/$P$35)/100 -> 0
F44: Firma y aclaración del responsable

Sheet 14
B3: MOVIMIENTO DE AERONAVES
B4: ESTADISTICA DIARIA
C6: DEPENDENCIA: | D6: TORRE MORON | H6: FECHA: | I6: 46248
B8: FRANJA HORARIA UTC | C8: COMERCIAL | D8: OFICIAL | E8: OTROS | F8: LOCAL | G8: SOBREVUELO | H8: TOTAL MOVIMIENTOS | I8: IFR | J8: PISTA
J9: 2 | K9: 20
B10: 00 a 01 | H10: =SUM(C10:G10) -> 0
B11: 01 a 02 | H11: =SUM(C11:G11) -> 0
B12: 02 a 03 | H12: =SUM(C12:G12) -> 0
B13: 03 a 04 | H13: =SUM(C13:G13) -> 0
B14: 04 a 05 | H14: =SUM(C14:G14) -> 0
B15: 05 a 06 | H15: =SUM(C15:G15) -> 0
B16: 06 a 07 | H16: =SUM(C16:G16) -> 0
B17: 07 a 08 | H17: =SUM(C17:G17) -> 0
B18: 08 a 09 | H18: =SUM(C18:G18) -> 0
B19: 09 a 10 | H19: =SUM(C19:G19) -> 0
B20: 10 a 11 | H20: =SUM(C20:G20) -> 0
B21: 11 a 12 | E21: AD IMC | H21: =SUM(C21:G21) -> 0
B22: 12 a 13 | E22: AD IMC | H22: =SUM(C22:G22) -> 0
B23: 13 a 14 | E23: AD IMC | H23: =SUM(C23:G23) -> 0
B24: 14 a 15 | E24: AD IMC | H24: =SUM(C24:G24) -> 0
B25: 15 a 16 | E25: AD IMC | H25: =SUM(C25:G25) -> 0
B26: 16 a 17 | E26: AD IMC | H26: =SUM(C26:G26) -> 0
B27: 17 a 18 | E27: AD IMC | H27: =SUM(C27:G27) -> 0
B28: 18 a 19 | E28: AD IMC | H28: =SUM(C28:G28) -> 0
B29: 19 a 20 | E29: AD IMC | H29: =SUM(C29:G29) -> 0
B30: 20 a 21 | E30: AD IMC | H30: =SUM(C30:G30) -> 0
B31: 21 a 22 | E31: AD IMC | H31: =SUM(C31:G31) -> 0
B32: 22 a 23 | H32: =SUM(C32:G32) -> 0
B33: 23 a 00 | H33: =SUM(C33:G33) -> 0 | P33: pista
B34: TOTAL DIARIO | C34: COMERCIAL | D34: OFICIAL | E34: OTROS | F34: LOCAL | G34: SOBREVUELO | H34: TOTAL MOVIMIENTOS | I34: IFR | J34: PISTA | P34: suma total
J35: =J9 -> 2 | K35: =K9 -> 20 | L35: =L9 -> 0 | M35: =M9 -> 0 | P35: =SUM(J36:M36) -> 0
C36: =SUM(C10:C33) -> 0 | D36: =SUM(D10:D33) -> 0 | E36: =SUM(E10:E33) -> 0 | F36: =SUM(F10:F33) -> 0 | G36: =SUM(G10:G33) -> 0 | H36: =SUM(H10:H33) -> 0 | I36: =SUM(I10:I33) -> 0 | J36: =SUM(J10:J33) -> 0 | ... M36: =SUM(M10:M33) -> 0
C37: =((C36*100)/$H$36)/100 -> #DIV/0! | D37: =((D36*100)/$H$36)/100 -> #DIV/0! | E37: =((E36*100)/$H$36)/100 -> #DIV/0! | F37: =((F36*100)/$H$36)/100 -> #DIV/0! | G37: =((G36*100)/$H$36)/100 -> #DIV/0! | H37: =((H36*100)/$H$36)/100 -> #DIV/0! | I37: =((I36*100)/$H$36)/100 -> #DIV/0! | J37: =((J36*100)/$P$35)/100 -> #DIV/0! | K37: =((K36*100)/$P$35)/100 -> #DIV/0! | L37: =((L36*100)/$P$35)/100 -> #DIV/0! | M37: =((M36*100)/$P$35)/100 -> #DIV/0!
F44: Firma y aclaración del responsable

Sheet 15
B3: MOVIMIENTO DE AERONAVES
B4: ESTADISTICA DIARIA
C6: DEPENDENCIA: | D6: TORRE MORON | H6: FECHA: | I6: 46249
B8: FRANJA HORARIA UTC | C8: COMERCIAL | D8: OFICIAL | E8: OTROS | F8: LOCAL | G8: SOBREVUELO | H8: TOTAL MOVIMIENTOS | I8: IFR | J8: PISTA
J9: 2 | K9: 20
B10: 00 a 01 | H10: =SUM(C10:G10) -> 0
B11: 01 a 02 | H11: =SUM(C11:G11) -> 0
B12: 02 a 03 | H12: =SUM(C12:G12) -> 0
B13: 03 a 04 | H13: =SUM(C13:G13) -> 0
B14: 04 a 05 | H14: =SUM(C14:G14) -> 0
B15: 05 a 06 | H15: =SUM(C15:G15) -> 0
B16: 06 a 07 | H16: =SUM(C16:G16) -> 0
B17: 07 a 08 | H17: =SUM(C17:G17) -> 0
B18: 08 a 09 | H18: =SUM(C18:G18) -> 0
B19: 09 a 10 | H19: =SUM(C19:G19) -> 0
B20: 10 a 11 | H20: =SUM(C20:G20) -> 0
B21: 11 a 12 | E21: 1 | H21: =SUM(C21:G21) -> 1 | J21: 1
B22: 12 a 13 | E22: IMC | H22: =SUM(C22:G22) -> 0
B23: 13 a 14 | E23: IMC | H23: =SUM(C23:G23) -> 0
B24: 14 a 15 | E24: IMC | H24: =SUM(C24:G24) -> 0
B25: 15 a 16 | E25: IMC | H25: =SUM(C25:G25) -> 0
B26: 16 a 17 | E26: 3 | H26: =SUM(C26:G26) -> 3 | J26: 1
B27: 17 a 18 | E27: 1 | H27: =SUM(C27:G27) -> 1 | J27: 1
B28: 18 a 19 | E28: IMC | H28: =SUM(C28:G28) -> 0
B29: 19 a 20 | E29: IMC | H29: =SUM(C29:G29) -> 0
B30: 20 a 21 | E30: IMC | H30: =SUM(C30:G30) -> 0
B31: 21 a 22 | E31: IMC | H31: =SUM(C31:G31) -> 0
B32: 22 a 23 | H32: =SUM(C32:G32) -> 0
B33: 23 a 00 | H33: =SUM(C33:G33) -> 0 | P33: pista
B34: TOTAL DIARIO | C34: COMERCIAL | D34: OFICIAL | E34: OTROS | F34: LOCAL | G34: SOBREVUELO | H34: TOTAL MOVIMIENTOS | I34: IFR | J34: PISTA | P34: suma total
J35: =J9 -> 2 | K35: =K9 -> 20 | L35: =L9 -> 0 | M35: =M9 -> 0 | P35: =SUM(J36:M36) -> 3
C36: =SUM(C10:C33) -> 0 | D36: =SUM(D10:D33) -> 0 | E36: =SUM(E10:E33) -> 5 | F36: =SUM(F10:F33) -> 0 | G36: =SUM(G10:G33) -> 0 | H36: =SUM(H10:H33) -> 5 | I36: =SUM(I10:I33) -> 0 | J36: =SUM(J10:J33) -> 3 | ... M36: =SUM(M10:M33) -> 0
C37: =((C36*100)/$H$36)/100 -> 0 | D37: =((D36*100)/$H$36)/100 -> 0 | E37: =((E36*100)/$H$36)/100 -> 1 | F37: =((F36*100)/$H$36)/100 -> 0 | G37: =((G36*100)/$H$36)/100 -> 0 | H37: =((H36*100)/$H$36)/100 -> 1 | I37: =((I36*100)/$H$36)/100 -> 0 | J37: =((J36*100)/$P$35)/100 -> 1 | K37: =((K36*100)/$P$35)/100 -> 0 | L37: =((L36*100)/$P$35)/100 -> 0 | M37: =((M36*100)/$P$35)/100 -> 0
F44: Firma y aclaración del responsable

Sheet 16
B3: MOVIMIENTO DE AERONAVES
B4: ESTADISTICA DIARIA
C6: DEPENDENCIA: | D6: TORRE MORON | H6: FECHA: | I6: 46250
B8: FRANJA HORARIA UTC | C8: COMERCIAL | D8: OFICIAL | E8: OTROS | F8: LOCAL | G8: SOBREVUELO | H8: TOTAL MOVIMIENTOS | I8: IFR | J8: PISTA
J9: 2 | K9: 20
B10: 00 a 01 | H10: =SUM(C10:G10) -> 0
B11: 01 a 02 | H11: =SUM(C11:G11) -> 0
B12: 02 a 03 | H12: =SUM(C12:G12) -> 0
B13: 03 a 04 | H13: =SUM(C13:G13) -> 0
B14: 04 a 05 | H14: =SUM(C14:G14) -> 0
B15: 05 a 06 | H15: =SUM(C15:G15) -> 0
B16: 06 a 07 | H16: =SUM(C16:G16) -> 0
B17: 07 a 08 | H17: =SUM(C17:G17) -> 0
B18: 08 a 09 | H18: =SUM(C18:G18) -> 0
B19: 09 a 10 | H19: =SUM(C19:G19) -> 0
B20: 10 a 11 | H20: =SUM(C20:G20) -> 0
B21: 11 a 12 | E21: IMC | H21: =SUM(C21:G21) -> 0
B22: 12 a 13 | E22: IMC | H22: =SUM(C22:G22) -> 0
B23: 13 a 14 | E23: IMC | H23: =SUM(C23:G23) -> 0
B24: 14 a 15 | E24: 1 | H24: =SUM(C24:G24) -> 1 | K24: 1
B25: 15 a 16 | E25: 9 | F25: 14 | H25: =SUM(C25:G25) -> 23 | K25: 1
B26: 16 a 17 | E26: 19 | H26: =SUM(C26:G26) -> 19 | K26: 1
B27: 17 a 18 | E27: 15 | F27: 2 | H27: =SUM(C27:G27) -> 17 | K27: 1
B28: 18 a 19 | E28: 15 | F28: 16 | H28: =SUM(C28:G28) -> 31 | K28: 1
B29: 19 a 20 | E29: 16 | F29: 6 | H29: =SUM(C29:G29) -> 22 | K29: 1
B30: 20 a 21 | E30: 12 | F30: 32 | H30: =SUM(C30:G30) -> 44 | K30: 1
B31: 21 a 22 | E31: 5 | F31: 8 | H31: =SUM(C31:G31) -> 13 | K31: 1
B32: 22 a 23 | H32: =SUM(C32:G32) -> 0
B33: 23 a 00 | H33: =SUM(C33:G33) -> 0 | P33: pista
B34: TOTAL DIARIO | C34: COMERCIAL | D34: OFICIAL | E34: OTROS | F34: LOCAL | G34: SOBREVUELO | H34: TOTAL MOVIMIENTOS | I34: IFR | J34: PISTA | P34: suma total
J35: =J9 -> 2 | K35: =K9 -> 20 | L35: =L9 -> 0 | M35: =M9 -> 0 | P35: =SUM(J36:M36) -> 8
C36: =SUM(C10:C33) -> 0 | D36: =SUM(D10:D33) -> 0 | E36: =SUM(E10:E33) -> 92 | F36: =SUM(F10:F33) -> 78 | G36: =SUM(G10:G33) -> 0 | H36: =SUM(H10:H33) -> 170 | I36: =SUM(I10:I33) -> 0 | J36: =SUM(J10:J33) -> 0 | ... M36: =SUM(M10:M33) -> 0
C37: =((C36*100)/$H$36)/100 -> 0 | D37: =((D36*100)/$H$36)/100 -> 0 | E37: =((E36*100)/$H$36)/100 -> 0.54117647 | F37: =((F36*100)/$H$36)/100 -> 0.45882353 | G37: =((G36*100)/$H$36)/100 -> 0 | H37: =((H36*100)/$H$36)/100 -> 1 | I37: =((I36*100)/$H$36)/100 -> 0 | J37: =((J36*100)/$P$35)/100 -> 0 | K37: =((K36*100)/$P$35)/100 -> 1 | L37: =((L36*100)/$P$35)/100 -> 0 | M37: =((M36*100)/$P$35)/100 -> 0
F44: Firma y aclaración del responsable

Sheet Hoja5

Sheet 17
B3: MOVIMIENTO DE AERONAVES
B4: ESTADISTICA DIARIA
C6: DEPENDENCIA: | D6: TORRE MORON | H6: FECHA: | I6: 46251
B8: FRANJA HORARIA UTC | C8: COMERCIAL | D8: OFICIAL | E8: OTROS | F8: LOCAL | G8: SOBREVUELO | H8: TOTAL MOVIMIENTOS | I8: IFR | J8: PISTA
J9: 2 | K9: 20
B10: 00 a 01 | H10: =SUM(C10:G10) -> 0
B11: 01 a 02 | H11: =SUM(C11:G11) -> 0
B12: 02 a 03 | H12: =SUM(C12:G12) -> 0
B13: 03 a 04 | H13: =SUM(C13:G13) -> 0
B14: 04 a 05 | H14: =SUM(C14:G14) -> 0
B15: 05 a 06 | H15: =SUM(C15:G15) -> 0
B16: 06 a 07 | H16: =SUM(C16:G16) -> 0
B17: 07 a 08 | H17: =SUM(C17:G17) -> 0
B18: 08 a 09 | H18: =SUM(C18:G18) -> 0
B19: 09 a 10 | H19: =SUM(C19:G19) -> 0
B20: 10 a 11 | H20: =SUM(C20:G20) -> 0
B21: 11 a 12 | E21: 6 | F21: 2 | H21: =SUM(C21:G21) -> 8 | K21: 1
B22: 12 a 13 | E22: 11 | F22: 42 | H22: =SUM(C22:G22) -> 53 | K22: 1
B23: 13 a 14 | E23: 5 | F23: 12 | H23: =SUM(C23:G23) -> 17 | K23: 1
B24: 14 a 15 | E24: 12 | F24: 22 | H24: =SUM(C24:G24) -> 34 | K24: 1
B25: 15 a 16 | E25: 17 | F25: 12 | G25: 1 | H25: =SUM(C25:G25) -> 30 | K25: 1
B26: 16 a 17 | E26: 18 | F26: 24 | G26: 1 | H26: =SUM(C26:G26) -> 43 | K26: 1
B27: 17 a 18 | E27: 17 | F27: 20 | H27: =SUM(C27:G27) -> 37 | K27: 1
B28: 18 a 19 | E28: 19 | F28: 12 | H28: =SUM(C28:G28) -> 31 | K28: 1
B29: 19 a 20 | E29: 16 | F29: 4 | H29: =SUM(C29:G29) -> 20 | K29: 1
B30: 20 a 21 | E30: 21 | F30: 34 | H30: =SUM(C30:G30) -> 55 | K30: 1
B31: 21 a 22 | E31: 3 | H31: =SUM(C31:G31) -> 3
B32: 22 a 23 | H32: =SUM(C32:G32) -> 0
B33: 23 a 00 | H33: =SUM(C33:G33) -> 0 | P33: pista
B34: TOTAL DIARIO | C34: COMERCIAL | D34: OFICIAL | E34: OTROS | F34: LOCAL | G34: SOBREVUELO | H34: TOTAL MOVIMIENTOS | I34: IFR | J34: PISTA | P34: suma total
J35: =J9 -> 2 | K35: =K9 -> 20 | L35: =L9 -> 0 | M35: =M9 -> 0 | P35: =SUM(J36:M36) -> 10
C36: =SUM(C10:C33) -> 0 | D36: =SUM(D10:D33) -> 0 | E36: =SUM(E10:E33) -> 145 | F36: =SUM(F10:F33) -> 184 | G36: =SUM(G10:G33) -> 2 | H36: =SUM(H10:H33) -> 331 | I36: =SUM(I10:I33) -> 0 | J36: =SUM(J10:J33) -> 0 | ... M36: =SUM(M10:M33) -> 0
C37: =((C36*100)/$H$36)/100 -> 0 | D37: =((D36*100)/$H$36)/100 -> 0 | E37: =((E36*100)/$H$36)/100 -> 0.43806647 | F37: =((F36*100)/$H$36)/100 -> 0.55589124 | G37: =((G36*100)/$H$36)/100 -> 0.0060422961 | H37: =((H36*100)/$H$36)/100 -> 1 | I37: =((I36*100)/$H$36)/100 -> 0 | J37: =((J36*100)/$P$35)/100 -> 0 | K37: =((K36*100)/$P$35)/100 -> 1 | L37: =((L36*100)/$P$35)/100 -> 0 | M37: =((M36*100)/$P$35)/100 -> 0
F44: Firma y aclaración del responsable

Sheet 18
B3: MOVIMIENTO DE AERONAVES
B4: ESTADISTICA DIARIA
C6: DEPENDENCIA: | D6: TORRE MORON | H6: FECHA: | I6: 46252
B8: FRANJA HORARIA UTC | C8: COMERCIAL | D8: OFICIAL | E8: OTROS | F8: LOCAL | G8: SOBREVUELO | H8: TOTAL MOVIMIENTOS | I8: IFR | J8: PISTA
J9: 2 | K9: 20
B10: 00 a 01 | H10: =SUM(C10:G10) -> 0
B11: 01 a 02 | H11: =SUM(C11:G11) -> 0
B12: 02 a 03 | H12: =SUM(C12:G12) -> 0
B13: 03 a 04 | H13: =SUM(C13:G13) -> 0
B14: 04 a 05 | H14: =SUM(C14:G14) -> 0
B15: 05 a 06 | H15: =SUM(C15:G15) -> 0
B16: 06 a 07 | H16: =SUM(C16:G16) -> 0
B17: 07 a 08 | H17: =SUM(C17:G17) -> 0
B18: 08 a 09 | H18: =SUM(C18:G18) -> 0
B19: 09 a 10 | H19: =SUM(C19:G19) -> 0
B20: 10 a 11 | H20: =SUM(C20:G20) -> 0
B21: 11 a 12 | E21: IMC | H21: =SUM(C21:G21) -> 0
B22: 12 a 13 | E22: 1 | H22: =SUM(C22:G22) -> 1 | K22: 1
B23: 13 a 14 | E23: 6 | H23: =SUM(C23:G23) -> 6 | K23: 1
B24: 14 a 15 | E24: 13 | H24: =SUM(C24:G24) -> 13 | K24: 1
B25: 15 a 16 | E25: 22 | F25: 6 | H25: =SUM(C25:G25) -> 28 | K25: 1
B26: 16 a 17 | E26: 23 | F26: 12 | H26: =SUM(C26:G26) -> 35 | I26: 1 | K26: 1
B27: 17 a 18 | E27: 30 | F27: 20 | H27: =SUM(C27:G27) -> 50 | K27: 1
B28: 18 a 19 | E28: 25 | F28: 6 | H28: =SUM(C28:G28) -> 31 | K28: 1
B29: 19 a 20 | E29: 26 | F29: 6 | H29: =SUM(C29:G29) -> 32 | K29: 1
B30: 20 a 21 | E30: 21 | F30: 10 | H30: =SUM(C30:G30) -> 31 | K30: 1
B31: 21 a 22 | E31: 4 | H31: =SUM(C31:G31) -> 4 | K31: 1
B32: 22 a 23 | H32: =SUM(C32:G32) -> 0
B33: 23 a 00 | H33: =SUM(C33:G33) -> 0 | P33: pista
B34: TOTAL DIARIO | C34: COMERCIAL | D34: OFICIAL | E34: OTROS | F34: LOCAL | G34: SOBREVUELO | H34: TOTAL MOVIMIENTOS | I34: IFR | J34: PISTA | P34: suma total
J35: =J9 -> 2 | K35: =K9 -> 20 | L35: =L9 -> 0 | M35: =M9 -> 0 | P35: =SUM(J36:M36) -> 10
C36: =SUM(C10:C33) -> 0 | D36: =SUM(D10:D33) -> 0 | E36: =SUM(E10:E33) -> 171 | F36: =SUM(F10:F33) -> 60 | G36: =SUM(G10:G33) -> 0 | H36: =SUM(H10:H33) -> 231 | I36: =SUM(I10:I33) -> 1 | J36: =SUM(J10:J33) -> 0 | ... M36: =SUM(M10:M33) -> 0
C37: =((C36*100)/$H$36)/100 -> 0 | D37: =((D36*100)/$H$36)/100 -> 0 | E37: =((E36*100)/$H$36)/100 -> 0.74025974 | F37: =((F36*100)/$H$36)/100 -> 0.25974026 | G37: =((G36*100)/$H$36)/100 -> 0 | H37: =((H36*100)/$H$36)/100 -> 1 | I37: =((I36*100)/$H$36)/100 -> 0.0043290043 | J37: =((J36*100)/$P$35)/100 -> 0 | K37: =((K36*100)/$P$35)/100 -> 1 | L37: =((L36*100)/$P$35)/100 -> 0 | M37: =((M36*100)/$P$35)/100 -> 0
F44: Firma y aclaración del responsable

Sheet 19
B3: MOVIMIENTO DE AERONAVES
B4: ESTADISTICA DIARIA
C6: DEPENDENCIA: | D6: TORRE MORON | H6: FECHA: | I6: 46253
B8: FRANJA HORARIA UTC | C8: COMERCIAL | D8: OFICIAL | E8: OTROS | F8: LOCAL | G8: SOBREVUELO | H8: TOTAL MOVIMIENTOS | I8: IFR | J8: PISTA
J9: 2 | K9: 20
B10: 00 a 01 | H10: =SUM(C10:G10) -> 0
B11: 01 a 02 | H11: =SUM(C11:G11) -> 0
B12: 02 a 03 | H12: =SUM(C12:G12) -> 0
B13: 03 a 04 | H13: =SUM(C13:G13) -> 0
B14: 04 a 05 | H14: =SUM(C14:G14) -> 0
B15: 05 a 06 | H15: =SUM(C15:G15) -> 0
B16: 06 a 07 | H16: =SUM(C16:G16) -> 0
B17: 07 a 08 | H17: =SUM(C17:G17) -> 0
B18: 08 a 09 | H18: =SUM(C18:G18) -> 0
B19: 09 a 10 | H19: =SUM(C19:G19) -> 0
B20: 10 a 11 | H20: =SUM(C20:G20) -> 0
B21: 11 a 12 | H21: =SUM(C21:G21) -> 0
B22: 12 a 13 | E22: 5 | H22: =SUM(C22:G22) -> 5 | K22: 1
B23: 13 a 14 | E23: 11 | H23: =SUM(C23:G23) -> 11 | I23: 1 | J23: 1
B24: 14 a 15 | E24: 23 | F24: 8 | H24: =SUM(C24:G24) -> 31 | I24: 1 | J24: 1
B25: 15 a 16 | E25: 29 | F25: 10 | H25: =SUM(C25:G25) -> 39 | K25: 1
B26: 16 a 17 | E26: 29 | H26: =SUM(C26:G26) -> 29 | K26: 1
B27: 17 a 18 | E27: 32 | F27: 2 | H27: =SUM(C27:G27) -> 34 | I27: 1 | K27: 1
B28: 18 a 19 | E28: 29 | F28: 8 | H28: =SUM(C28:G28) -> 37 | J28: 1
B29: 19 a 20 | E29: 29 | F29: 10 | H29: =SUM(C29:G29) -> 39 | J29: 1
B30: 20 a 21 | E30: 26 | F30: 6 | H30: =SUM(C30:G30) -> 32 | J30: 1
B31: 21 a 22 | E31: 11 | F31: 2A3394/2026 AVISOS FIR EZEIZA (-EF) Desde: 2026-08-25 12:00:00 Hasta: 2026-08-27 19:00:00 AFIL AND ABBREVIATED FLT DATA WILL NOT BE ACCEPTED IN CTA EZEIZA I, CTA EZEIZA II, TMA BAIRES AND CTR EZEIZA TO AVOID TFC CONGESTION EXC SAN, HUM AND STAA3394/2026 AVISOS FIR EZEIZA (-EF) Desde: 2026-08-25 12:00:00 Hasta: 2026-08-27 19:00:00 AFIL AND ABBREVIATED FLT DATA WILL NOT BE ACCEPTED IN CTA EZEIZA I, CTA EZEIZA II, TMA BAIRES AND CTR EZEIZA TO AVOID TFC CONGESTION EXC SAN, HUM AND STATE FLT Versión en Español: NO SE ACEPTARA FLT AFIL Y DATOS ABREVIADOS DE VUELOS EN CTA EZEIZA I, CTA EZEIZA II, TMA BAIRES Y CTR EZEIZA PARA EVITAR CONGESTION TFC EXC FLT SAN, HUM Y ESTADOA3394/2026 AVISOS FIR EZEIZA (-EF) Desde: 2026-08-25 12:00:00 Hasta: 2026-08-27 19:00:00 AFIL AND ABBREVIATED FLT DATA WILL NOT BE ACCEPTED IN CTA EZEIZA I, CTA EZEIZA II, TMA BAIRES AND CTR EZEIZA TO AVOID TFC CONGESTION EXC SAN, HUM AND STATE FLT Versión en Español: NO SE ACEPTARA FLT AFIL Y DATOS ABREVIADOS DE VUELOS EN CTA EZEIZA I, CTA EZEIZA II, TMA BAIRES Y CTR EZEIZA PARA EVITAR CONGESTION TFC EXC FLT SAN, HUM Y ESTADO AVISOS FIR EZEIZA (-EF) Desde: 2026-08-25 12:00:00 Hasta: 2026-08-27 19:00:00 AFIL AND ABBREVIATED FLT DATA WILL NOT BE ACCEPTED IN CTA EZEIZA I, CTA EZEIZA II, TMA BAIRES AND CTR EZEIZA TO AVOID TFC CONGESTION EXC SAN, HUM AND STATE FLT Versión en Español: NO SE ACEPTARA FLT AFIL Y DATOS ABREVIADOS DE VUELOS EN CTA EZEIZA I, CTA EZEIZA II, TMA BAIRES Y CTR EZEIZA PARA EVITAR CONGESTION TFC EXC FLT SAN, HUM Y ESTADO AVISOS FIR EZEIZA (-EF) Desde: 2026-08-25 12:00:00 Hasta: 2026-08-27 19:00:00 AFIL AND ABBREVIATED FLT DATA WILL NOT BE ACCEPTED IN CTA EZEIZA I, CTA EZEIZA II, TMA BAIRES AND CTR EZEIZA TO AVOID TFC CONGESTION EXC SAN, HUM AND STATE FLT Versión en Español: NO SE ACEPTARA FLT AFIL Y DATOS ABREVIADOS DE VUELOS EN CTA EZEIZA I, CTA EZEIZA II, TMA BAIRES Y CTR EZEIZA PARA EVITAR CONGESTION TFC EXC FLT SAN, HUM Y ESTADO | H31: =SUM(C31:G31) -> 11 | J31: 1
B32: 22 a 23 | H32: =SUM(C32:G32) -> 0
B33: 23 a 00 | H33: =SUM(C33:G33) -> 0 | P33: pista
B34: TOTAL DIARIO | C34: COMERCIAL | D34: OFICIAL | E34: OTROS | F34: LOCAL | G34: SOBREVUELO | H34: TOTAL MOVIMIENTOS | I34: IFR | J34: PISTA | P34: suma total
J35: =J9 -> 2 | K35: =K9 -> 20 | L35: =L9 -> 0 | M35: =M9 -> 0 | P35: =SUM(J36:M36) -> 10
C36: =SUM(C10:C33) -> 0 | D36: =SUM(D10:D33) -> 0 | E36: =SUM(E10:E33) -> 224 | F36: =SUM(F10:F33) -> 44 | G36: =SUM(G10:G33) -> 0 | H36: =SUM(H10:H33) -> 268 | I36: =SUM(I10:I33) -> 3 | J36: =SUM(J10:J33) -> 6 | ... M36: =SUM(M10:M33) -> 0
C37: =((C36*100)/$H$36)/100 -> 0 | D37: =((D36*100)/$H$36)/100 -> 0 | E37: =((E36*100)/$H$36)/100 -> 0.8358209 | F37: =((F36*100)/$H$36)/100 -> 0.1641791 | G37: =((G36*100)/$H$36)/100 -> 0 | H37: =((H36*100)/$H$36)/100 -> 1 | I37: =((I36*100)/$H$36)/100 -> 0.01119403 | J37: =((J36*100)/$P$35)/100 -> 0.6 | K37: =((K36*100)/$P$35)/100 -> 0.4 | L37: =((L36*100)/$P$35)/100 -> 0 | M37: =((M36*100)/$P$35)/100 -> 0
F44: Firma y aclaración del responsable

Sheet 20
B3: MOVIMIENTO DE AERONAVES
B4: ESTADISTICA DIARIA
C6: DEPENDENCIA: | D6: TORRE MORON | H6: FECHA: | I6: 46254
B8: FRANJA HORARIA UTC | C8: COMERCIAL | D8: OFICIAL | E8: OTROS | F8: LOCAL | G8: SOBREVUELO | H8: TOTAL MOVIMIENTOS | I8: IFR | J8: PISTA
J9: 2 | K9: 20
B10: 00 a 01 | H10: =SUM(C10:G10) -> 0
B11: 01 a 02 | H11: =SUM(C11:G11) -> 0
B12: 02 a 03 | H12: =SUM(C12:G12) -> 0
B13: 03 a 04 | H13: =SUM(C13:G13) -> 0
B14: 04 a 05 | H14: =SUM(C14:G14) -> 0
B15: 05 a 06 | H15: =SUM(C15:G15) -> 0
B16: 06 a 07 | H16: =SUM(C16:G16) -> 0
B17: 07 a 08 | H17: =SUM(C17:G17) -> 0
B18: 08 a 09 | H18: =SUM(C18:G18) -> 0
B19: 09 a 10 | H19: =SUM(C19:G19) -> 0
B20: 10 a 11 | H20: =SUM(C20:G20) -> 0
B21: 11 a 12 | E21: IMC | H21: =SUM(C21:G21) -> 0
B22: 12 a 13 | E22: IMC | H22: =SUM(C22:G22) -> 0
B23: 13 a 14 | E23: IMC | H23: =SUM(C23:G23) -> 0
B24: 14 a 15 | E24: IMC | H24: =SUM(C24:G24) -> 0
B25: 15 a 16 | C25: 1 | E25: 19 | F25: 10 | H25: =SUM(C25:G25) -> 30 | K25: 1
B26: 16 a 17 | C26: 1 | E26: 20 | F26: 20 | H26: =SUM(C26:G26) -> 41 | K26: 1
B27: 17 a 18 | C27: 1 | E27: 29 | F27: 12 | H27: =SUM(C27:G27) -> 42 | K27: 1
B28: 18 a 19 | C28: 2 | E28: 24 | F28: 18 | H28: =SUM(C28:G28) -> 44 | K28: 1
B29: 19 a 20 | C29: 1 | E29: 24 | F29: 10 | H29: =SUM(C29:G29) -> 35 | K29: 1
B30: 20 a 21 | C30: 1 | E30: 19 | F30: 4 | H30: =SUM(C30:G30) -> 24 | K30: 1
B31: 21 a 22 | E31: 7 | F31: 8 | H31: =SUM(C31:G31) -> 15 | K31: 1
B32: 22 a 23 | H32: =SUM(C32:G32) -> 0
B33: 23 a 00 | H33: =SUM(C33:G33) -> 0 | P33: pista
B34: TOTAL DIARIO | C34: COMERCIAL | D34: OFICIAL | E34: OTROS | F34: LOCAL | G34: SOBREVUELO | H34: TOTAL MOVIMIENTOS | I34: IFR | J34: PISTA | P34: suma total
J35: =J9 -> 2 | K35: =K9 -> 20 | L35: =L9 -> 0 | M35: =M9 -> 0 | P35: =SUM(J36:M36) -> 7
C36: =SUM(C10:C33) -> 7 | D36: =SUM(D10:D33) -> 0 | E36: =SUM(E10:E33) -> 142 | F36: =SUM(F10:F33) -> 82 | G36: =SUM(G10:G33) -> 0 | H36: =SUM(H10:H33) -> 231 | I36: =SUM(I10:I33) -> 0 | J36: =SUM(J10:J33) -> 0 | ... M36: =SUM(M10:M33) -> 0
C37: =((C36*100)/$H$36)/100 -> 0.03030303 | D37: =((D36*100)/$H$36)/100 -> 0 | E37: =((E36*100)/$H$36)/100 -> 0.61471861 | F37: =((F36*100)/$H$36)/100 -> 0.35497835 | G37: =((G36*100)/$H$36)/100 -> 0 | H37: =((H36*100)/$H$36)/100 -> 1 | I37: =((I36*100)/$H$36)/100 -> 0 | J37: =((J36*100)/$P$35)/100 -> 0 | K37: =((K36*100)/$P$35)/100 -> 1 | L37: =((L36*100)/$P$35)/100 -> 0 | M37: =((M36*100)/$P$35)/100 -> 0
F44: Firma y aclaración del responsable

Sheet 21
B3: MOVIMIENTO DE AERONAVES
B4: ESTADISTICA DIARIA
C6: DEPENDENCIA: | D6: TORRE MORON | H6: FECHA: | I6: 46255
B8: FRANJA HORARIA UTC | C8: COMERCIAL | D8: OFICIAL | E8: OTROS | F8: LOCAL | G8: SOBREVUELO | H8: TOTAL MOVIMIENTOS | I8: IFR | J8: PISTA
J9: 2 | K9: 20
B10: 00 a 01 | H10: =SUM(C10:G10) -> 0
B11: 01 a 02 | H11: =SUM(C11:G11) -> 0
B12: 02 a 03 | H12: =SUM(C12:G12) -> 0
B13: 03 a 04 | H13: =SUM(C13:G13) -> 0
B14: 04 a 05 | H14: =SUM(C14:G14) -> 0
B15: 05 a 06 | H15: =SUM(C15:G15) -> 0
B16: 06 a 07 | H16: =SUM(C16:G16) -> 0
B17: 07 a 08 | H17: =SUM(C17:G17) -> 0
B18: 08 a 09 | H18: =SUM(C18:G18) -> 0
B19: 09 a 10 | H19: =SUM(C19:G19) -> 0
B20: 10 a 11 | H20: =SUM(C20:G20) -> 0
B21: 11 a 12 | H21: =SUM(C21:G21) -> 0
... B32: 22 a 23 | H32: =SUM(C32:G32) -> 0
B33: 23 a 00 | H33: =SUM(C33:G33) -> 0 | P33: pista
B34: TOTAL DIARIO | C34: COMERCIAL | D34: OFICIAL | E34: OTROS | F34: LOCAL | G34: SOBREVUELO | H34: TOTAL MOVIMIENTOS | I34: IFR | J34: PISTA | P34: suma total
J35: =J9 -> 2 | K35: =K9 -> 20 | L35: =L9 -> 0 | M35: =M9 -> 0 | P35: =SUM(J36:M36) -> 0
C36: =SUM(C10:C33) -> 0 | D36: =SUM(D10:D33) -> 0 | E36: =SUM(E10:E33) -> 0 | F36: =SUM(F10:F33) -> 0 | G36: =SUM(G10:G33) -> 0 | H36: =SUM(H10:H33) -> 0 | I36: =SUM(I10:I33) -> 0 | J36: =SUM(J10:J33) -> 0 | ... M36: =SUM(M10:M33) -> 0
C37: =((C36*100)/$H$36)/100 -> #DIV/0! | D37: =((D36*100)/$H$36)/100 -> #DIV/0! | E37: =((E36*100)/$H$36)/100 -> #DIV/0! | F37: =((F36*100)/$H$36)/100 -> #DIV/0! | G37: =((G36*100)/$H$36)/100 -> #DIV/0! | H37: =((H36*100)/$H$36)/100 -> #DIV/0! | I37: =((I36*100)/$H$36)/100 -> #DIV/0! | J37: =((J36*100)/$P$35)/100 -> #DIV/0! | K37: =((K36*100)/$P$35)/100 -> #DIV/0! | L37: =((L36*100)/$P$35)/100 -> #DIV/0! | M37: =((M36*100)/$P$35)/100 -> #DIV/0!
F44: Firma y aclaración del responsable

Sheet Hoja2

Sheet Hoja3

Sheet Hoja4

Sheet 22
B3: MOVIMIENTO DE AERONAVES
B4: ESTADISTICA DIARIA
C6: DEPENDENCIA: | D6: TORRE MORON | H6: FECHA: | I6: 46256
B8: FRANJA HORARIA UTC | C8: COMERCIAL | D8: OFICIAL | E8: OTROS | F8: LOCAL | G8: SOBREVUELO | H8: TOTAL MOVIMIENTOS | I8: IFR | J8: PISTA
J9: 2 | K9: 20
B10: 00 a 01 | H10: =SUM(C10:G10) -> 0
B11: 01 a 02 | H11: =SUM(C11:G11) -> 0
B12: 02 a 03 | H12: =SUM(C12:G12) -> 0
B13: 03 a 04 | H13: =SUM(C13:G13) -> 0
B14: 04 a 05 | H14: =SUM(C14:G14) -> 0
B15: 05 a 06 | H15: =SUM(C15:G15) -> 0
B16: 06 a 07 | H16: =SUM(C16:G16) -> 0
B17: 07 a 08 | H17: =SUM(C17:G17) -> 0
B18: 08 a 09 | H18: =SUM(C18:G18) -> 0
B19: 09 a 10 | H19: =SUM(C19:G19) -> 0
B20: 10 a 11 | H20: =SUM(C20:G20) -> 0
B21: 11 a 12 | H21: =SUM(C21:G21) -> 0
... B32: 22 a 23 | H32: =SUM(C32:G32) -> 0
B33: 23 a 00 | H33: =SUM(C33:G33) -> 0 | P33: pista
B34: TOTAL DIARIO | C34: COMERCIAL | D34: OFICIAL | E34: OTROS | F34: LOCAL | G34: SOBREVUELO | H34: TOTAL MOVIMIENTOS | I34: IFR | J34: PISTA | P34: suma total
J35: =J9 -> 2 | K35: =K9 -> 20 | L35: =L9 -> 0 | M35: =M9 -> 0 | P35: =SUM(J36:M36) -> 0
C36: =SUM(C10:C33) -> 0 | D36: =SUM(D10:D33) -> 0 | E36: =SUM(E10:E33) -> 0 | F36: =SUM(F10:F33) -> 0 | G36: =SUM(G10:G33) -> 0 | H36: =SUM(H10:H33) -> 0 | I36: =SUM(I10:I33) -> 0 | J36: =SUM(J10:J33) -> 0 | ... M36: =SUM(M10:M33) -> 0
C37: =((C36*100)/$H$36)/100 -> #DIV/0! | D37: =((D36*100)/$H$36)/100 -> #DIV/0! | E37: =((E36*100)/$H$36)/100 -> #DIV/0! | F37: =((F36*100)/$H$36)/100 -> #DIV/0! | G37: =((G36*100)/$H$36)/100 -> #DIV/0! | H37: =((H36*100)/$H$36)/100 -> #DIV/0! | I37: =((I36*100)/$H$36)/100 -> #DIV/0! | J37: =((J36*100)/$P$35)/100 -> #DIV/0! | K37: =((K36*100)/$P$35)/100 -> #DIV/0! | L37: =((L36*100)/$P$35)/100 -> #DIV/0! | M37: =((M36*100)/$P$35)/100 -> #DIV/0!
F44: Firma y aclaración del responsable

Sheet 23
B3: MOVIMIENTO DE AERONAVES
B4: ESTADISTICA DIARIA
C6: DEPENDENCIA: | D6: TORRE MORON | H6: FECHA: | I6: 46196
B8: FRANJA HORARIA UTC | C8: COMERCIAL | D8: OFICIAL | E8: OTROS | F8: LOCAL | G8: SOBREVUELO | H8: TOTAL MOVIMIENTOS | I8: IFR | J8: PISTA
J9: 2 | K9: 20
B10: 00 a 01 | H10: =SUM(C10:G10) -> 0
B11: 01 a 02 | H11: =SUM(C11:G11) -> 0
B12: 02 a 03 | H12: =SUM(C12:G12) -> 0
B13: 03 a 04 | H13: =SUM(C13:G13) -> 0
B14: 04 a 05 | H14: =SUM(C14:G14) -> 0
B15: 05 a 06 | H15: =SUM(C15:G15) -> 0
B16: 06 a 07 | H16: =SUM(C16:G16) -> 0
B17: 07 a 08 | H17: =SUM(C17:G17) -> 0
B18: 08 a 09 | H18: =SUM(C18:G18) -> 0
B19: 09 a 10 | H19: =SUM(C19:G19) -> 0
B20: 10 a 11 | H20: =SUM(C20:G20) -> 0
B21: 11 a 12 | H21: =SUM(C21:G21) -> 0
... B32: 22 a 23 | H32: =SUM(C32:G32) -> 0
B33: 23 a 00 | H33: =SUM(C33:G33) -> 0 | P33: pista
B34: TOTAL DIARIO | C34: COMERCIAL | D34: OFICIAL | E34: OTROS | F34: LOCAL | G34: SOBREVUELO | H34: TOTAL MOVIMIENTOS | I34: IFR | J34: PISTA | P34: suma total
J35: =J9 -> 2 | K35: =K9 -> 20 | L35: =L9 -> 0 | M35: =M9 -> 0 | P35: =SUM(J36:M36) -> 0
C36: =SUM(C10:C33) -> 0 | D36: =SUM(D10:D33) -> 0 | E36: =SUM(E10:E33) -> 0 | F36: =SUM(F10:F33) -> 0 | G36: =SUM(G10:G33) -> 0 | H36: =SUM(H10:H33) -> 0 | I36: =SUM(I10:I33) -> 0 | J36: =SUM(J10:J33) -> 0 | ... M36: =SUM(M10:M33) -> 0
C37: =((C36*100)/$H$36)/100 -> #DIV/0! | D37: =((D36*100)/$H$36)/100 -> #DIV/0! | E37: =((E36*100)/$H$36)/100 -> #DIV/0! | F37: =((F36*100)/$H$36)/100 -> #DIV/0! | G37: =((G36*100)/$H$36)/100 -> #DIV/0! | H37: =((H36*100)/$H$36)/100 -> #DIV/0! | I37: =((I36*100)/$H$36)/100 -> #DIV/0! | J37: =((J36*100)/$P$35)/100 -> #DIV/0! | K37: =((K36*100)/$P$35)/100 -> #DIV/0! | L37: =((L36*100)/$P$35)/100 -> #DIV/0! | M37: =((M36*100)/$P$35)/100 -> #DIV/0!
F44: Firma y aclaración del responsable

Sheet Hoja6

Sheet Hoja7

Sheet Hoja8

Sheet 24
B3: MOVIMIENTO DE AERONAVES
B4: ESTADISTICA DIARIA
C6: DEPENDENCIA: | D6: TORRE MORON | H6: FECHA: | I6: 46258
B8: FRANJA HORARIA UTC | C8: COMERCIAL | D8: OFICIAL | E8: OTROS | F8: LOCAL | G8: SOBREVUELO | H8: TOTAL MOVIMIENTOS | I8: IFR | J8: PISTA
J9: 2 | K9: 20
B10: 00 a 01 | H10: =SUM(C10:G10) -> 0
B11: 01 a 02 | H11: =SUM(C11:G11) -> 0
B12: 02 a 03 | H12: =SUM(C12:G12) -> 0
B13: 03 a 04 | H13: =SUM(C13:G13) -> 0
B14: 04 a 05 | H14: =SUM(C14:G14) -> 0
B15: 05 a 06 | H15: =SUM(C15:G15) -> 0
B16: 06 a 07 | H16: =SUM(C16:G16) -> 0
B17: 07 a 08 | H17: =SUM(C17:G17) -> 0
B18: 08 a 09 | H18: =SUM(C18:G18) -> 0
B19: 09 a 10 | H19: =SUM(C19:G19) -> 0
B20: 10 a 11 | H20: =SUM(C20:G20) -> 0
B21: 11 a 12 | H21: =SUM(C21:G21) -> 0
... B32: 22 a 23 | H32: =SUM(C32:G32) -> 0
B33: 23 a 00 | H33: =SUM(C33:G33) -> 0 | P33: pista
B34: TOTAL DIARIO | C34: COMERCIAL | D34: OFICIAL | E34: OTROS | F34: LOCAL | G34: SOBREVUELO | H34: TOTAL MOVIMIENTOS | I34: IFR | J34: PISTA | P34: suma total
J35: =J9 -> 2 | K35: =K9 -> 20 | L35: =L9 -> 0 | M35: =M9 -> 0 | P35: =SUM(J36:M36) -> 0
C36: =SUM(C10:C33) -> 0 | D36: =SUM(D10:D33) -> 0 | E36: =SUM(E10:E33) -> 0 | F36: =SUM(F10:F33) -> 0 | G36: =SUM(G10:G33) -> 0 | H36: =SUM(H10:H33) -> 0 | I36: =SUM(I10:I33) -> 0 | J36: =SUM(J10:J33) -> 0 | ... M36: =SUM(M10:M33) -> 0
C37: =((C36*100)/$H$36)/100 -> #DIV/0! | D37: =((D36*100)/$H$36)/100 -> #DIV/0! | E37: =((E36*100)/$H$36)/100 -> #DIV/0! | F37: =((F36*100)/$H$36)/100 -> #DIV/0! | G37: =((G36*100)/$H$36)/100 -> #DIV/0! | H37: =((H36*100)/$H$36)/100 -> #DIV/0! | I37: =((I36*100)/$H$36)/100 -> #DIV/0! | J37: =((J36*100)/$P$35)/100 -> #DIV/0! | K37: =((K36*100)/$P$35)/100 -> #DIV/0! | L37: =((L36*100)/$P$35)/100 -> #DIV/0! | M37: =((M36*100)/$P$35)/100 -> #DIV/0!
F44: Firma y aclaración del responsable

Sheet 25
B3: MOVIMIENTO DE AERONAVES
B4: ESTADISTICA DIARIA
C6: DEPENDENCIA: | D6: TORRE MORON | H6: FECHA: | I6: 46259
B8: FRANJA HORARIA UTC | C8: COMERCIAL | D8: OFICIAL | E8: OTROS | F8: LOCAL | G8: SOBREVUELO | H8: TOTAL MOVIMIENTOS | I8: IFR | J8: PISTA
J9: 2 | K9: 20
B10: 00 a 01 | H10: =SUM(C10:G10) -> 0
B11: 01 a 02 | H11: =SUM(C11:G11) -> 0
B12: 02 a 03 | H12: =SUM(C12:G12) -> 0
B13: 03 a 04 | H13: =SUM(C13:G13) -> 0
B14: 04 a 05 | H14: =SUM(C14:G14) -> 0
B15: 05 a 06 | H15: =SUM(C15:G15) -> 0
B16: 06 a 07 | H16: =SUM(C16:G16) -> 0
B17: 07 a 08 | H17: =SUM(C17:G17) -> 0
B18: 08 a 09 | H18: =SUM(C18:G18) -> 0
B19: 09 a 10 | H19: =SUM(C19:G19) -> 0
B20: 10 a 11 | H20: =SUM(C20:G20) -> 0
B21: 11 a 12 | H21: =SUM(C21:G21) -> 0
... B32: 22 a 23 | H32: =SUM(C32:G32) -> 0
B33: 23 a 00 | H33: =SUM(C33:G33) -> 0 | P33: pista
B34: TOTAL DIARIO | C34: COMERCIAL | D34: OFICIAL | E34: OTROS | F34: LOCAL | G34: SOBREVUELO | H34: TOTAL MOVIMIENTOS | I34: IFR | J34: PISTA | P34: suma total
J35: =J9 -> 2 | K35: =K9 -> 20 | L35: =L9 -> 0 | M35: =M9 -> 0 | P35: =SUM(J36:M36) -> 0
C36: =SUM(C10:C33) -> 0 | D36: =SUM(D10:D33) -> 0 | E36: =SUM(E10:E33) -> 0 | F36: =SUM(F10:F33) -> 0 | G36: =SUM(G10:G33) -> 0 | H36: =SUM(H10:H33) -> 0 | I36: =SUM(I10:I33) -> 0 | J36: =SUM(J10:J33) -> 0 | ... M36: =SUM(M10:M33) -> 0
C37: =((C36*100)/$H$36)/100 -> #DIV/0! | D37: =((D36*100)/$H$36)/100 -> #DIV/0! | E37: =((E36*100)/$H$36)/100 -> #DIV/0! | F37: =((F36*100)/$H$36)/100 -> #DIV/0! | G37: =((G36*100)/$H$36)/100 -> #DIV/0! | H37: =((H36*100)/$H$36)/100 -> #DIV/0! | I37: =((I36*100)/$H$36)/100 -> #DIV/0! | J37: =((J36*100)/$P$35)/100 -> #DIV/0! | K37: =((K36*100)/$P$35)/100 -> #DIV/0! | L37: =((L36*100)/$P$35)/100 -> #DIV/0! | M37: =((M36*100)/$P$35)/100 -> #DIV/0!
F44: Firma y aclaración del responsable

Sheet 26
B3: MOVIMIENTO DE AERONAVES
B4: ESTADISTICA DIARIA
C6: DEPENDENCIA: | D6: TORRE MORON | H6: FECHA: | I6: 46260
B8: FRANJA HORARIA UTC | C8: COMERCIAL | D8: OFICIAL | E8: OTROS | F8: LOCAL | G8: SOBREVUELO | H8: TOTAL MOVIMIENTOS | I8: IFR | J8: PISTA
J9: 2 | K9: 20
B10: 00 a 01 | H10: =SUM(C10:G10) -> 0
B11: 01 a 02 | H11: =SUM(C11:G11) -> 0
B12: 02 a 03 | H12: =SUM(C12:G12) -> 0
B13: 03 a 04 | H13: =SUM(C13:G13) -> 0
B14: 04 a 05 | H14: =SUM(C14:G14) -> 0
B15: 05 a 06 | H15: =SUM(C15:G15) -> 0
B16: 06 a 07 | H16: =SUM(C16:G16) -> 0
B17: 07 a 08 | H17: =SUM(C17:G17) -> 0
B18: 08 a 09 | H18: =SUM(C18:G18) -> 0
B19: 09 a 10 | H19: =SUM(C19:G19) -> 0
B20: 10 a 11 | H20: =SUM(C20:G20) -> 0
